Workbook

Sheet Read Me
A1: Azure CIS Control Register
A3: Purpose: master list of CIS-recommended controls by Azure service, taken from the four CIS Microsoft Azure benchmarks supplied.
A5: Source benchmarks
A6: • CIS Microsoft Azure Foundations Benchmark v6.0.0 (published 2026-04-19): 127 recommendations
A7: • CIS Microsoft Azure Compute Services Benchmark v2.0.0 (published 2025-06-27): 99 recommendations
A8: • CIS Microsoft Azure Database Services Benchmark v2.0.0 (published 2025-12-31): 49 recommendations
A9: • CIS Microsoft Azure Storage Services Benchmark v2.0.0 (published 2026-06-30): 64 recommendations
A10: Total: 339 recommendations
A12: Sheets
A13: • All Controls: every recommendation, sorted by Service Category > Azure Service > Benchmark > CIS ID. Filter-ready table.
A14: • Service Summary: control counts per service (live COUNTIFS formulas over All Controls).
A15: • Foundations / Compute / Database / Storage: one sheet per benchmark, in CIS order.
... A34: • Recommendation titles are reproduced as written. See the source PDFs for audit and remediation steps.

Sheet All Controls
A1: # | B1: Service Category | C1: Azure Service | D1: Section / Sub-service | E1: CIS ID | F1: Control (CIS Recommendation) | G1: Profile | H1: Assessment | I1: CIS Benchmark (Version) | J1: Overlap Flag | K1: Overlap Reference
A2: 1 | B2: Analytics | C2: Azure Databricks | D2: Analytics Services > Azure Databricks | E2: 2.1.1 | F2: Ensure that Azure Databricks is deployed in a customer-managed virtual network (VNet) | G2: Level 1 | H2: Automated | I2: CIS Microsoft Azure Foundations Benchmark v6.0.0 | J2: None
A3: 2 | B3: Analytics | C3: Azure Databricks | D3: Analytics Services > Azure Databricks | E3: 2.1.2 | F3: Ensure that Network Security Groups are Configured for Databricks Subnets | G3: Level 1 | H3: Automated | I3: CIS Microsoft Azure Foundations Benchmark v6.0.0 | J3: None
A4: 3 | B4: Analytics | C4: Azure Databricks | D4: Analytics Services > Azure Databricks | E4: 2.1.3 | F4: Ensure that Traffic is Encrypted Between Cluster Worker Nodes | G4: Level 2 | H4: Manual | I4: CIS Microsoft Azure Foundations Benchmark v6.0.0 | J4: None
A5: 4 | B5: Analytics | C5: Azure Databricks | D5: Analytics Services > Azure Databricks | E5: 2.1.4 | F5: Ensure that Users and Groups are Synced from Microsoft Entra ID to Azure Databricks | G5: Level 1 | H5: Manual | I5: CIS Microsoft Azure Foundations Benchmark v6.0.0 | J5: None
A6: 5 | B6: Analytics | C6: Azure Databricks | D6: Analytics Services > Azure Databricks | E6: 2.1.5 | F6: Ensure that Unity Catalog is Configured for Azure Databricks | G6: Level 1 | H6: Manual | I6: CIS Microsoft Azure Foundations Benchmark v6.0.0 | J6: None
A7: 6 | B7: Analytics | C7: Azure Databricks | D7: Analytics Services > Azure Databricks | E7: 2.1.6 | F7: Ensure that Usage is Restricted and Expiry is Enforced for Databricks Personal Access Tokens | G7: Level 1 | H7: Manual | I7: CIS Microsoft Azure Foundations Benchmark v6.0.0 | J7: None
A8: 7 | B8: Analytics | C8: Azure Databricks | D8: Analytics Services > Azure Databricks | E8: 2.1.7 | F8: Ensure that Diagnostic Log Delivery is Configured for Azure Databricks | G8: Level 1 | H8: Automated | I8: CIS Microsoft Azure Foundations Benchmark v6.0.0 | J8: None
A9: 8 | B9: Analytics | C9: Azure Databricks | D9: Analytics Services > Azure Databricks | E9: 2.1.8 | F9: Ensure Critical Data in Azure Databricks is Encrypted with Customer-managed Keys (CMK) | G9: Level 2 | H9: Manual | I9: CIS Microsoft Azure Foundations Benchmark v6.0.0 | J9: None
A10: 9 | B10: Analytics | C10: Azure Databricks | D10: Analytics Services > Azure Databricks | E10: 2.1.9 | F10: Ensure 'No Public IP' is Set to 'Enabled' | G10: Level 1 | H10: Automated | I10: CIS Microsoft Azure Foundations Benchmark v6.0.0 | J10: None
A11: 10 | B11: Analytics | C11: Azure Databricks | D11: Analytics Services > Azure Databricks | E11: 2.1.10 | F11: Ensure 'Allow Public Network Access' is set to 'Disabled' | G11: Level 1 | H11: Automated | I11: CIS Microsoft Azure Foundations Benchmark v6.0.0 | J11: None
A12: 11 | B12: Analytics | C12: Azure Databricks | D12: Analytics Services > Azure Databricks | E12: 2.1.11 | F12: Ensure Private Endpoints are used to access Azure Databricks workspaces | G12: Level 2 | H12: Automated | I12: CIS Microsoft Azure Foundations Benchmark v6.0.0 | J12: None
A13: 12 | B13: Analytics | C13: Azure Databricks | D13: Analytics Services > Azure Databricks | E13: 2.1.12 | F13: Ensure Azure Databricks groups are reviewed periodically | G13: Level 1 | H13: Manual | I13: CIS Microsoft Azure Foundations Benchmark v6.0.0 | J13: None
... A101: 100 | B101: Compute | C101: Azure Functions | D101: App Service > Functions Deployment Slots | E101: 2.4.16 | F101: Ensure cross-origin resource sharing does not allow all origins | G101: Level 2 | H101: Automated | I101: CIS Microsoft Azure Compute Services Benchmark v2.0.0 | J101: None
A102: 101 | B102: Compute | C102: Azure Virtual Machines | D102: Compute Services > Virtual Machines | E102: 3.1.1 | F102: Ensure only MFA Enabled Identities can Access Privileged Virtual Machine | G102: Level 2 | H102: Manual | I102: CIS Microsoft Azure Foundations Benchmark v6.0.0 | J102: Duplicate | K102: Compute v2.0.0 20.9
A103: 102 | B103: Compute | C103: Azure Virtual Machines | D103: Virtual Machines | E103: 20.1 | F103: Ensure Virtual Machines are utilizing Managed Disks | G103: Level 1 | H103: Automated | I103: CIS Microsoft Azure Compute Services Benchmark v2.0.0 | J103: None
A104: 103 | B104: Compute | C104: Azure Virtual Machines | D104: Virtual Machines | E104: 20.2 | F104: Ensure that 'OS and Data' disks are encrypted with Customer Managed Key (CMK) | G104: Level 2 | H104: Automated | I104: CIS Microsoft Azure Compute Services Benchmark v2.0.0 | J104: None
A105: 104 | B105: Compute | C105: Azure Virtual Machines | D105: Virtual Machines | E105: 20.3 | F105: Ensure that 'Unattached disks' are encrypted with 'Customer Managed Key' (CMK) | G105: Level 2 | H105: Automated | I105: CIS Microsoft Azure Compute Services Benchmark v2.0.0 | J105: None
A106: 105 | B106: Compute | C106: Azure Virtual Machines | D106: Virtual Machines | E106: 20.4 | F106: Ensure that 'Disk Network Access' is NOT set to 'Enable public access from all networks' | G106: Level 1 | H106: Automated | I106: CIS Microsoft Azure Compute Services Benchmark v2.0.0 | J106: None
A107: 106 | B107: Compute | C107: Azure Virtual Machines | D107: Virtual Machines | E107: 20.5 | F107: Ensure that 'Enable Data Access Authentication Mode' is 'Checked' | G107: Level 1 | H107: Automated | I107: CIS Microsoft Azure Compute Services Benchmark v2.0.0 | J107: None
A108: 107 | B108: Compute | C108: Azure Virtual Machines | D108: Virtual Machines | E108: 20.6 | F108: Ensure that Only Approved Extensions Are Installed | G108: Level 1 | H108: Manual | I108: CIS Microsoft Azure Compute Services Benchmark v2.0.0 | J108: None
A109: 108 | B109: Compute | C109: Azure Virtual Machines | D109: Virtual Machines | E109: 20.7 | F109: Ensure that Endpoint Protection for all Virtual Machines is installed | G109: Level 2 | H109: Manual | I109: CIS Microsoft Azure Compute Services Benchmark v2.0.0 | J109: Related | K109: Foundations v6.0.0 8.1.3.3
A110: 109 | B110: Compute | C110: Azure Virtual Machines | D110: Virtual Machines | E110: 20.8 | F110: [Legacy] Ensure that VHDs are Encrypted | G110: Level 2 | H110: Manual | I110: CIS Microsoft Azure Compute Services Benchmark v2.0.0 | J110: None
A111: 110 | B111: Compute | C111: Azure Virtual Machines | D111: Virtual Machines | E111: 20.9 | F111: Ensure only MFA enabled identities can access privileged Virtual Machine | G111: Level 2 | H111: Manual | I111: CIS Microsoft Azure Compute Services Benchmark v2.0.0 | J111: Duplicate | K111: Foundations v6.0.0 3.1.1
A112: 111 | B112: Compute | C112: Azure Virtual Machines | D112: Virtual Machines | E112: 20.10 | F112: Ensure Trusted Launch is enabled on Virtual Machines | G112: Level 1 | H112: Automated | I112: CIS Microsoft Azure Compute Services Benchmark v2.0.0 | J112: None
A113: 112 | B113: Compute | C113: Azure Virtual Machines | D113: Virtual Machines | E113: 20.11 | F113: Ensure that encryption at host is enabled | G113: Level 1 | H113: Automated | I113: CIS Microsoft Azure Compute Services Benchmark v2.0.0 | J113: None
A114: 113 | B114: Database | C114: Azure Cache for Redis | D114: Azure Cache for Redis (Retiring) | E114: 2.1 | F114: Ensure 'Microsoft Entra Authentication' is 'Enabled' | G114: Level 1 | H114: Manual | I114: CIS Microsoft Azure Database Services Benchmark v2.0.0 | J114: None
A115: 114 | B115: Database | C115: Azure Cache for Redis | D115: Azure Cache for Redis (Retiring) | E115: 2.2 | F115: Ensure that 'Allow access only via SSL' is set to 'Yes' | G115: Level 1 | H115: Automated | I115: CIS Microsoft Azure Database Services Benchmark v2.0.0 | J115: None
A116: 115 | B116: Database | C116: Azure Cache for Redis | D116: Azure Cache for Redis (Retiring) | E116: 2.3 | F116: Ensure that 'Minimum TLS version' is set to TLS v1.2 (or higher) | G116: Level 1 | H116: Manual | I116: CIS Microsoft Azure Database Services Benchmark v2.0.0 | J116: None
A117: 116 | B117: Database | C117: Azure Cache for Redis | D117: Azure Cache for Redis (Retiring) | E117: 2.4 | F117: Ensure that 'Access Policies' are Implemented and Reviewed Periodically | G117: Level 2 | H117: Manual | I117: CIS Microsoft Azure Database Services Benchmark v2.0.0 | J117: None
A118: 117 | B118: Database | C118: Azure Cache for Redis | D118: Azure Cache for Redis (Retiring) | E118: 2.5 | F118: Ensure that 'System Assigned Managed Identity' is set to 'On' | G118: Level 1 | H118: Manual | I118: CIS Microsoft Azure Database Services Benchmark v2.0.0 | J118: None
A119: 118 | B119: Database | C119: Azure Cache for Redis | D119: Azure Cache for Redis (Retiring) | E119: 2.6 | F119: Ensure that 'Public Network Access' is 'Disabled' | G119: Level 2 | H119: Manual | I119: CIS Microsoft Azure Database Services Benchmark v2.0.0 | J119: None
A120: 119 | B120: Database | C120: Azure Cache for Redis | D120: Azure Cache for Redis (Retiring) | E120: 2.7 | F120: Ensure Azure Cache for Redis is Using a Private Link | G120: Level 2 | H120: Manual | I120: CIS Microsoft Azure Database Services Benchmark v2.0.0 | J120: None
A121: 120 | B121: Database | C121: Azure Cache for Redis | D121: Azure Cache for Redis (Retiring) | E121: 2.8 | F121: Ensure that Azure Cache for Redis is Using Customer-Managed Keys | G121: Level 2 | H121: Manual | I121: CIS Microsoft Azure Database Services Benchmark v2.0.0 | J121: None
A122: 121 | B122: Database | C122: Azure Cache for Redis | D122: Azure Cache for Redis (Retiring) | E122: 2.9 | F122: Ensure 'Access Keys Authentication' is set to 'Disabled' | G122: Level 1 | H122: Automated | I122: CIS Microsoft Azure Database Services Benchmark v2.0.0 | J122: None
A123: 122 | B123: Database | C123: Azure Cache for Redis | D123: Azure Cache for Redis (Retiring) | E123: 2.10 | F123: Ensure 'Update Channel' is set to 'Stable' | G123: Level 1 | H123: Automated | I123: CIS Microsoft Azure Database Services Benchmark v2.0.0 | J123: None
... A179: 178 | B179: Management & Governance | C179: Azure Monitor (Logging & Alerting) | D179: Management and Governance Services > Logging and Monitoring > Configuring Diagnostic Settings | E179: 6.1.1.2 | F179: Ensure Diagnostic Setting Captures Appropriate Categories | G179: Level 1 | H179: Automated | I179: CIS Microsoft Azure Foundations Benchmark v6.0.0 | J179: None
A180: 179 | B180: Management & Governance | C180: Azure Monitor (Logging & Alerting) | D180: Management and Governance Services > Logging and Monitoring > Configuring Diagnostic Settings | E180: 6.1.1.3 | F180: Ensure the Storage Account Containing the Container with Activity Logs is Encrypted with Customer-managed Key (CMK) | G180: Level 2 | H180: Manual | I180: CIS Microsoft Azure Foundations Benchmark v6.0.0 | J180: Related | K180: Storage v2.0.0 16.1.8
A181: 180 | B181: Management & Governance | C181: Azure Monitor (Logging & Alerting) | D181: Management and Governance Services > Logging and Monitoring > Configuring Diagnostic Settings | E181: 6.1.1.4 | F181: Ensure that Logging for Azure Key Vault is 'Enabled' | G181: Level 1 | H181: Automated | I181: CIS Microsoft Azure Foundations Benchmark v6.0.0 | J181: None
A182: 181 | B182: Management & Governance | C182: Azure Monitor (Logging & Alerting) | D182: Management and Governance Services > Logging and Monitoring > Configuring Diagnostic Settings | E182: 6.1.1.5 | F182: Ensure that Network Security Group Flow Logs are Captured and Sent to Log Analytics | G182: Level 2 | H182: Manual | I182: CIS Microsoft Azure Foundations Benchmark v6.0.0 | J182: None
...

Sheet Service Summary
A1: Service Category | B1: Azure Service | C1: Total Controls | D1: Level 1 | E1: Level 2 | F1: Automated | G1: Manual | H1: Flagged Overlaps (Dup/Near-dup) | I1: Source Benchmark(s)
A2: Analytics | B2: Azure Databricks | C2: =COUNTIFS('All Controls'!$C$2:$C$340,B2) -> 12 | D2: =COUNTIFS('All Controls'!$C$2:$C$340,B2,'All Controls'!$G$2:$G$340,"Level 1") -> 9 | E2: =COUNTIFS('All Controls'!$C$2:$C$340,B2,'All Controls'!$G$2:$G$340,"Level 2") -> 3 | F2: =COUNTIFS('All Controls'!$C$2:$C$340,B2,'All Controls'!$H$2:$H$340,"Automated") -> 6 | G2: =COUNTIFS('All Controls'!$C$2:$C$340,B2,'All Controls'!$H$2:$H$340,"Manual") -> 6 | H2: =COUNTIFS('All Controls'!$C$2:$C$340,B2,'All Controls'!$J$2:$J$340,"Duplicate")+COUNTIFS('All Controls'!$C$2:$C$340,B2,'All Controls'!$J$2:$J$340,"Near-duplicate") -> 0 | I2: Foundations v6.0.0
A3: Compute | B3: Azure App Service | C3: =COUNTIFS('All Controls'!$C$2:$C$340,B3) -> 44 | D3: =COUNTIFS('All Controls'!$C$2:$C$340,B3,'All Controls'!$G$2:$G$340,"Level 1") -> 31 | E3: =COUNTIFS('All Controls'!$C$2:$C$340,B3,'All Controls'!$G$2:$G$340,"Level 2") -> 13 | F3: =COUNTIFS('All Controls'!$C$2:$C$340,B3,'All Controls'!$H$2:$H$340,"Automated") -> 36 | G3: =COUNTIFS('All Controls'!$C$2:$C$340,B3,'All Controls'!$H$2:$H$340,"Manual") -> 8 | H3: =COUNTIFS('All Controls'!$C$2:$C$340,B3,'All Controls'!$J$2:$J$340,"Duplicate")+COUNTIFS('All Controls'!$C$2:$C$340,B3,'All Controls'!$J$2:$J$340,"Near-duplicate") -> 0 | I3: Compute Services v2.0.0
A4: Compute | B4: Azure Batch | C4: =COUNTIFS('All Controls'!$C$2:$C$340,B4) -> 7 | D4: =COUNTIFS('All Controls'!$C$2:$C$340,B4,'All Controls'!$G$2:$G$340,"Level 1") -> 4 | E4: =COUNTIFS('All Controls'!$C$2:$C$340,B4,'All Controls'!$G$2:$G$340,"Level 2") -> 3 | F4: =COUNTIFS('All Controls'!$C$2:$C$340,B4,'All Controls'!$H$2:$H$340,"Automated") -> 5 | G4: =COUNTIFS('All Controls'!$C$2:$C$340,B4,'All Controls'!$H$2:$H$340,"Manual") -> 2 | H4: =COUNTIFS('All Controls'!$C$2:$C$340,B4,'All Controls'!$J$2:$J$340,"Duplicate")+COUNTIFS('All Controls'!$C$2:$C$340,B4,'All Controls'!$J$2:$J$340,"Near-duplicate") -> 0 | I4: Compute Services v2.0.0
A5: Compute | B5: Azure Container Instances | C5: =COUNTIFS('All Controls'!$C$2:$C$340,B5) -> 3 | D5: =COUNTIFS('All Controls'!$C$2:$C$340,B5,'All Controls'!$G$2:$G$340,"Level 1") -> 3 | E5: =COUNTIFS('All Controls'!$C$2:$C$340,B5,'All Controls'!$G$2:$G$340,"Level 2") -> 0 | F5: =COUNTIFS('All Controls'!$C$2:$C$340,B5,'All Controls'!$H$2:$H$340,"Automated") -> 0 | G5: =COUNTIFS('All Controls'!$C$2:$C$340,B5,'All Controls'!$H$2:$H$340,"Manual") -> 3 | H5: =COUNTIFS('All Controls'!$C$2:$C$340,B5,'All Controls'!$J$2:$J$340,"Duplicate")+COUNTIFS('All Controls'!$C$2:$C$340,B5,'All Controls'!$J$2:$J$340,"Near-duplicate") -> 0 | I5: Compute Services v2.0.0
A6: Compute | B6: Azure CycleCloud | C6: =COUNTIFS('All Controls'!$C$2:$C$340,B6) -> 1 | D6: =COUNTIFS('All Controls'!$C$2:$C$340,B6,'All Controls'!$G$2:$G$340,"Level 1") -> 1 | E6: =COUNTIFS('All Controls'!$C$2:$C$340,B6,'All Controls'!$G$2:$G$340,"Level 2") -> 0 | F6: =COUNTIFS('All Controls'!$C$2:$C$340,B6,'All Controls'!$H$2:$H$340,"Automated") -> 0 | G6: =COUNTIFS('All Controls'!$C$2:$C$340,B6,'All Controls'!$H$2:$H$340,"Manual") -> 1 | H6: =COUNTIFS('All Controls'!$C$2:$C$340,B6,'All Controls'!$J$2:$J$340,"Duplicate")+COUNTIFS('All Controls'!$C$2:$C$340,B6,'All Controls'!$J$2:$J$340,"Near-duplicate") -> 0 | I6: Compute Services v2.0.0
A7: Compute | B7: Azure Functions | C7: =COUNTIFS('All Controls'!$C$2:$C$340,B7) -> 33 | D7: =COUNTIFS('All Controls'!$C$2:$C$340,B7,'All Controls'!$G$2:$G$340,"Level 1") -> 26 | E7: =COUNTIFS('All Controls'!$C$2:$C$340,B7,'All Controls'!$G$2:$G$340,"Level 2") -> 7 | F7: =COUNTIFS('All Controls'!$C$2:$C$340,B7,'All Controls'!$H$2:$H$340,"Automated") -> 29 | G7: =COUNTIFS('All Controls'!$C$2:$C$340,B7,'All Controls'!$H$2:$H$340,"Manual") -> 4 | H7: =COUNTIFS('All Controls'!$C$2:$C$340,B7,'All Controls'!$J$2:$J$340,"Duplicate")+COUNTIFS('All Controls'!$C$2:$C$340,B7,'All Controls'!$J$2:$J$340,"Near-duplicate") -> 0 | I7: Compute Services v2.0.0
A8: Compute | B8: Azure Virtual Machines | C8: =COUNTIFS('All Controls'!$C$2:$C$340,B8) -> 12 | D8: =COUNTIFS('All Controls'!$C$2:$C$340,B8,'All Controls'!$G$2:$G$340,"Level 1") -> 6 | E8: =COUNTIFS('All Controls'!$C$2:$C$340,B8,'All Controls'!$G$2:$G$340,"Level 2") -> 6 | F8: =COUNTIFS('All Controls'!$C$2:$C$340,B8,'All Controls'!$H$2:$H$340,"Automated") -> 7 | G8: =COUNTIFS('All Controls'!$C$2:$C$340,B8,'All Controls'!$H$2:$H$340,"Manual") -> 5 | H8: =COUNTIFS('All Controls'!$C$2:$C$340,B8,'All Controls'!$J$2:$J$340,"Duplicate")+COUNTIFS('All Controls'!$C$2:$C$340,B8,'All Controls'!$J$2:$J$340,"Near-duplicate") -> 2 | I8: Compute Services v2.0.0, Foundations v6.0.0
A9: Database | B9: Azure Cache for Redis | C9: =COUNTIFS('All Controls'!$C$2:$C$340,B9) -> 10 | D9: =COUNTIFS('All Controls'!$C$2:$C$340,B9,'All Controls'!$G$2:$G$340,"Level 1") -> 6 | E9: =COUNTIFS('All Controls'!$C$2:$C$340,B9,'All Controls'!$G$2:$G$340,"Level 2") -> 4 | F9: =COUNTIFS('All Controls'!$C$2:$C$340,B9,'All Controls'!$H$2:$H$340,"Automated") -> 3 | G9: =COUNTIFS('All Controls'!$C$2:$C$340,B9,'All Controls'!$H$2:$H$340,"Manual") -> 7 | H9: =COUNTIFS('All Controls'!$C$2:$C$340,B9,'All Controls'!$J$2:$J$340,"Duplicate")+COUNTIFS('All Controls'!$C$2:$C$340,B9,'All Controls'!$J$2:$J$340,"Near-duplicate") -> 0 | I9: Database Services v2.0.0
A10: Database | B10: Azure Cosmos DB | C10: =COUNTIFS('All Controls'!$C$2:$C$340,B10) -> 7 | D10: =COUNTIFS('All Controls'!$C$2:$C$340,B10,'All Controls'!$G$2:$G$340,"Level 1") -> 3 | E10: =COUNTIFS('All Controls'!$C$2:$C$340,B10,'All Controls'!$G$2:$G$340,"Level 2") -> 4 | F10: =COUNTIFS('All Controls'!$C$2:$C$340,B10,'All Controls'!$H$2:$H$340,"Automated") -> 4 | G10: =COUNTIFS('All Controls'!$C$2:$C$340,B10,'All Controls'!$H$2:$H$340,"Manual") -> 3 | H10: =COUNTIFS('All Controls'!$C$2:$C$340,B10,'All Controls'!$J$2:$J$340,"Duplicate")+COUNTIFS('All Controls'!$C$2:$C$340,B10,'All Controls'!$J$2:$J$340,"Near-duplicate") -> 0 | I10: Database Services v2.0.0
A11: Database | B11: Azure Data Factory | C11: =COUNTIFS('All Controls'!$C$2:$C$340,B11) -> 4 | D11: =COUNTIFS('All Controls'!$C$2:$C$340,B11,'All Controls'!$G$2:$G$340,"Level 1") -> 1 | E11: =COUNTIFS('All Controls'!$C$2:$C$340,B11,'All Controls'!$G$2:$G$340,"Level 2") -> 3 | F11: =COUNTIFS('All Controls'!$C$2:$C$340,B11,'All Controls'!$H$2:$H$340,"Automated") -> 1 | G11: =COUNTIFS('All Controls'!$C$2:$C$340,B11,'All Controls'!$H$2:$H$340,"Manual") -> 3 | H11: =COUNTIFS('All Controls'!$C$2:$C$340,B11,'All Controls'!$J$2:$J$340,"Duplicate")+COUNTIFS('All Controls'!$C$2:$C$340,B11,'All Controls'!$J$2:$J$340,"Near-duplicate") -> 0 | I11: Database Services v2.0.0
A12: Database | B12: Azure Database for MySQL | C12: =COUNTIFS('All Controls'!$C$2:$C$340,B12) -> 9 | D12: =COUNTIFS('All Controls'!$C$2:$C$340,B12,'All Controls'!$G$2:$G$340,"Level 1") -> 3 | E12: =COUNTIFS('All Controls'!$C$2:$C$340,B12,'All Controls'!$G$2:$G$340,"Level 2") -> 6 | F12: =COUNTIFS('All Controls'!$C$2:$C$340,B12,'All Controls'!$H$2:$H$340,"Automated") -> 7 | G12: =COUNTIFS('All Controls'!$C$2:$C$340,B12,'All Controls'!$H$2:$H$340,"Manual") -> 2 | H12: =COUNTIFS('All Controls'!$C$2:$C$340,B12,'All Controls'!$J$2:$J$340,"Duplicate")+COUNTIFS('All Controls'!$C$2:$C$340,B12,'All Controls'!$J$2:$J$340,"Near-duplicate") -> 0 | I12: Database Services v2.0.0
A13: Database | B13: Azure Database for PostgreSQL | C13: =COUNTIFS('All Controls'!$C$2:$C$340,B13) -> 11 | D13: =COUNTIFS('All Controls'!$C$2:$C$340,B13,'All Controls'!$G$2:$G$340,"Level 1") -> 8 | E13: =COUNTIFS('All Controls'!$C$2:$C$340,B13,'All Controls'!$G$2:$G$340,"Level 2") -> 3 | F13: =COUNTIFS('All Controls'!$C$2:$C$340,B13,'All Controls'!$H$2:$H$340,"Automated") -> 9 | G13: =COUNTIFS('All Controls'!$C$2:$C$340,B13,'All Controls'!$H$2:$H$340,"Manual") -> 2 | H13: =COUNTIFS('All Controls'!$C$2:$C$340,B13,'All Controls'!$J$2:$J$340,"Duplicate")+COUNTIFS('All Controls'!$C$2:$C$340,B13,'All Controls'!$J$2:$J$340,"Near-duplicate") -> 0 | I13: Database Services v2.0.0
... A38: Storage | B38: Azure Storage Explorer | C38: =COUNTIFS('All Controls'!$C$2:$C$340,B38) -> 3 | D38: =COUNTIFS('All Controls'!$C$2:$C$340,B38,'All Controls'!$G$2:$G$340,"Level 1") -> 2 | E38: =COUNTIFS('All Controls'!$C$2:$C$340,B38,'All Controls'!$G$2:$G$340,"Level 2") -> 1 | F38: =COUNTIFS('All Controls'!$C$2:$C$340,B38,'All Controls'!$H$2:$H$340,"Automated") -> 0 | G38: =COUNTIFS('All Controls'!$C$2:$C$340,B38,'All Controls'!$H$2:$H$340,"Manual") -> 3 | H38: =COUNTIFS('All Controls'!$C$2:$C$340,B38,'All Controls'!$J$2:$J$340,"Duplicate")+COUNTIFS('All Controls'!$C$2:$C$340,B38,'All Controls'!$J$2:$J$340,"Near-duplicate") -> 0 | I38: Storage Services v2.0.0
A39: Total | C39: =SUM(C2:C38) -> 339 | D39: =SUM(D2:D38) -> 205 | E39: =SUM(E2:E38) -> 134 | F39: =SUM(F2:F38) -> 245 | G39: =SUM(G2:G38) -> 94 | H39: =SUM(H2:H38) -> 42

Sheet Foundations v6.0.0
A1: # | B1: Service Category | C1: Azure Service | D1: Section / Sub-service | E1: CIS ID | F1: Control (CIS Recommendation) | G1: Profile | H1: Assessment | I1: CIS Benchmark (Version) | J1: Overlap Flag | K1: Overlap Reference
A2: 1 | B2: Analytics | C2: Azure Databricks | D2: Analytics Services > Azure Databricks | E2: 2.1.1 | F2: Ensure that Azure Databricks is deployed in a customer-managed virtual network (VNet) | G2: Level 1 | H2: Automated | I2: CIS Microsoft Azure Foundations Benchmark v6.0.0 | J2: None
A3: 2 | B3: Analytics | C3: Azure Databricks | D3: Analytics Services > Azure Databricks | E3: 2.1.2 | F3: Ensure that Network Security Groups are Configured for Databricks Subnets | G3: Level 1 | H3: Automated | I3: CIS Microsoft Azure Foundations Benchmark v6.0.0 | J3: None
A4: 3 | B4: Analytics | C4: Azure Databricks | D4: Analytics Services > Azure Databricks | E4: 2.1.3 | F4: Ensure that Traffic is Encrypted Between Cluster Worker Nodes | G4: Level 2 | H4: Manual | I4: CIS Microsoft Azure Foundations Benchmark v6.0.0 | J4: None
A5: 4 | B5: Analytics | C5: Azure Databricks | D5: Analytics Services > Azure Databricks | E5: 2.1.4 | F5: Ensure that Users and Groups are Synced from Microsoft Entra ID to Azure Databricks | G5: Level 1 | H5: Manual | I5: CIS Microsoft Azure Foundations Benchmark v6.0.0 | J5: None
A6: 5 | B6: Analytics | C6: Azure Databricks | D6: Analytics Services > Azure Databricks | E6: 2.1.5 | F6: Ensure that Unity Catalog is Configured for Azure Databricks | G6: Level 1 | H6: Manual | I6: CIS Microsoft Azure Foundations Benchmark v6.0.0 | J6: None
A7: 6 | B7: Analytics | C7: Azure Databricks | D7: Analytics Services > Azure Databricks | E7: 2.1.6 | F7: Ensure that Usage is Restricted and Expiry is Enforced for Databricks Personal Access Tokens | G7: Level 1 | H7: Manual | I7: CIS Microsoft Azure Foundations Benchmark v6.0.0 | J7: None
A8: 7 | B8: Analytics | C8: Azure Databricks | D8: Analytics Services > Azure Databricks | E8: 2.1.7 | F8: Ensure that Diagnostic Log Delivery is Configured for Azure Databricks | G8: Level 1 | H8: Automated | I8: CIS Microsoft Azure Foundations Benchmark v6.0.0 | J8: None
A9: 8 | B9: Analytics | C9: Azure Databricks | D9: Analytics Services > Azure Databricks | E9: 2.1.8 | F9: Ensure Critical Data in Azure Databricks is Encrypted with Customer-managed Keys (CMK) | G9: Level 2 | H9: Manual | I9: CIS Microsoft Azure Foundations Benchmark v6.0.0 | J9: None
A10: 9 | B10: Analytics | C10: Azure Databricks | D10: Analytics Services > Azure Databricks | E10: 2.1.9 | F10: Ensure 'No Public IP' is Set to 'Enabled' | G10: Level 1 | H10: Automated | I10: CIS Microsoft Azure Foundations Benchmark v6.0.0 | J10: None
A11: 10 | B11: Analytics | C11: Azure Databricks | D11: Analytics Services > Azure Databricks | E11: 2.1.10 | F11: Ensure 'Allow Public Network Access' is set to 'Disabled' | G11: Level 1 | H11: Automated | I11: CIS Microsoft Azure Foundations Benchmark v6.0.0 | J11: None
A12: 11 | B12: Analytics | C12: Azure Databricks | D12: Analytics Services > Azure Databricks | E12: 2.1.11 | F12: Ensure Private Endpoints are used to access Azure Databricks workspaces | G12: Level 2 | H12: Automated | I12: CIS Microsoft Azure Foundations Benchmark v6.0.0 | J12: None
A13: 12 | B13: Analytics | C13: Azure Databricks | D13: Analytics Services > Azure Databricks | E13: 2.1.12 | F13: Ensure Azure Databricks groups are reviewed periodically | G13: Level 1 | H13: Manual | I13: CIS Microsoft Azure Foundations Benchmark v6.0.0 | J13: None
A14: 13 | B14: Compute | C14: Azure Virtual Machines | D14: Compute Services > Virtual Machines | E14: 3.1.1 | F14: Ensure only MFA Enabled Identities can Access Privileged Virtual Machine | G14: Level 2 | H14: Manual | I14: CIS Microsoft Azure Foundations Benchmark v6.0.0 | J14: Duplicate | K14: Compute v2.0.0 20.9
A15: 14 | B15: Identity | C15: Microsoft Entra ID / Azure RBAC | D15: Identity Services > Security Defaults (Per-User MFA) | E15: 5.1.1 | F15: Ensure that 'security defaults' is Enabled in Microsoft Entra ID | G15: Level 1 | H15: Automated | I15: CIS Microsoft Azure Foundations Benchmark v6.0.0 | J15: None
A16: 15 | B16: Identity | C16: Microsoft Entra ID / Azure RBAC | D16: Identity Services > Security Defaults (Per-User MFA) | E16: 5.1.2 | F16: Ensure that 'Require Multifactor Authentication to register or join devices with Microsoft Entra' is set to 'Yes' | G16: Level 1 | H16: Manual | I16: CIS Microsoft Azure Foundations Benchmark v6.0.0 | J16: None
A17: 16 | B17: Identity | C17: Microsoft Entra ID / Azure RBAC | D17: Identity Services > Security Defaults (Per-User MFA) | E17: 5.1.3 | F17: Ensure that 'multifactor authentication' is 'enabled' For All Users | G17: Level 1 | H17: Automated | I17: CIS Microsoft Azure Foundations Benchmark v6.0.0 | J17: None
A18: 17 | B18: Identity | C18: Microsoft Entra ID / Azure RBAC | D18: Identity Services > Security Defaults (Per-User MFA) | E18: 5.1.4 | F18: Ensure that 'Allow users to remember multifactor authentication on devices they trust' is Disabled | G18: Level 1 | H18: Manual | I18: CIS Microsoft Azure Foundations Benchmark v6.0.0 | J18: None
A19: 18 | B19: Identity | C19: Microsoft Entra ID / Azure RBAC | D19: Identity Services > Periodic Identity Reviews | E19: 5.3.1 | F19: Ensure that Azure Admin Accounts Are Not Used for Daily Operations | G19: Level 1 | H19: Manual | I19: CIS Microsoft Azure Foundations Benchmark v6.0.0 | J19: None
A20: 19 | B20: Identity | C20: Microsoft Entra ID / Azure RBAC | D20: Identity Services > Periodic Identity Reviews | E20: 5.3.2 | F20: Ensure that Guest Users are Reviewed on a Regular Basis | G20: Level 1 | H20: Manual | I20: CIS Microsoft Azure Foundations Benchmark v6.0.0 | J20: None
A21: 20 | B21: Identity | C21: Microsoft Entra ID / Azure RBAC | D21: Identity Services > Periodic Identity Reviews | E21: 5.3.3 | F21: Ensure That Use of the 'User Access Administrator' Role is Restricted | G21: Level 1 | H21: Automated | I21: CIS Microsoft Azure Foundations Benchmark v6.0.0 | J21: None
A22: 21 | B22: Identity | C22: Microsoft Entra ID / Azure RBAC | D22: Identity Services > Periodic Identity Reviews | E22: 5.3.4 | F22: Ensure that All 'Privileged' Role Assignments are Periodically Reviewed | G22: Level 1 | H22: Manual | I22: CIS Microsoft Azure Foundations Benchmark v6.0.0 | J22: None
A23: 22 | B23: Identity | C23: Microsoft Entra ID / Azure RBAC | D23: Identity Services > Periodic Identity Reviews | E23: 5.3.5 | F23: Ensure Disabled User Accounts do not Have Read, Write, or Owner Permissions | G23: Level 1 | H23: Manual | I23: CIS Microsoft Azure Foundations Benchmark v6.0.0 | J23: None
A24: 23 | B24: Identity | C24: Microsoft Entra ID / Azure RBAC | D24: Identity Services > Periodic Identity Reviews | E24: 5.3.6 | F24: Ensure 'Tenant Creator' Role Assignments are Periodically Reviewed | G24: Level 1 | H24: Manual | I24: CIS Microsoft Azure Foundations Benchmark v6.0.0 | J24: None
A25: 24 | B25: Identity | C25: Microsoft Entra ID / Azure RBAC | D25: Identity Services > Periodic Identity Reviews | E25: 5.3.7 | F25: Ensure All Non-privileged Role Assignments are Periodically Reviewed | G25: Level 1 | H25: Manual | I25: CIS Microsoft Azure Foundations Benchmark v6.0.0 | J25: None
A26: 25 | B26: Identity | C26: Microsoft Entra ID / Azure RBAC | D26: Identity Services | E26: 5.4 | F26: Ensure that No Custom Subscription Administrator Roles Exist | G26: Level 1 | H26: Automated | I26: CIS Microsoft Azure Foundations Benchmark v6.0.0 | J26: None
... A31: 30 | B31: Management & Governance | C31: Azure Monitor (Logging & Alerting) | D31: Management and Governance Services > Logging and Monitoring > Configuring Diagnostic Settings | E31: 6.1.1.2 | F31: Ensure Diagnostic Setting Captures Appropriate Categories | G31: Level 1 | H31: Automated | I31: CIS Microsoft Azure Foundations Benchmark v6.0.0 | J31: None
A32: 31 | B32: Management & Governance | C32: Azure Monitor (Logging & Alerting) | D32: Management and Governance Services > Logging and Monitoring > Configuring Diagnostic Settings | E32: 6.1.1.3 | F32: Ensure the Storage Account Containing the Container with Activity Logs is Encrypted with Customer-managed Key (CMK) | G32: Level 2 | H32: Manual | I32: CIS Microsoft Azure Foundations Benchmark v6.0.0 | J32: Related | K32: Storage v2.0.0 16.1.8
A33: 32 | B33: Management & Governance | C33: Azure Monitor (Logging & Alerting) | D33: Management and Governance Services > Logging and Monitoring > Configuring Diagnostic Settings | E33: 6.1.1.4 | F33: Ensure that Logging for Azure Key Vault is 'Enabled' | G33: Level 1 | H33: Automated | I33: CIS Microsoft Azure Foundations Benchmark v6.0.0 | J33: None
A34: 33 | B34: Management & Governance | C34: Azure Monitor (Logging & Alerting) | D34: Management and Governance Services > Logging and Monitoring > Configuring Diagnostic Settings | E34: 6.1.1.5 | F34: Ensure that Network Security Group Flow Logs are Captured and Sent to Log Analytics | G34: Level 2 | H34: Manual | I34: CIS Microsoft Azure Foundations Benchmark v6.0.0 | J34: None
A35: 34 | B35: Management & Governance | C35: Azure Monitor (Logging & Alerting) | D35: Management and Governance Services > Logging and Monitoring > Configuring Diagnostic Settings | E35: 6.1.1.6 | F35: Ensure that Virtual Network Flow Logs are Captured and Sent to Log Analytics | G35: Level 2 | H35: Manual | I35: CIS Microsoft Azure Foundations Benchmark v6.0.0 | J35: None
A36: 35 | B36: Management & Governance | C36: Azure Monitor (Logging & Alerting) | D36: Management and Governance Services > Logging and Monitoring > Configuring Diagnostic Settings | E36: 6.1.1.7 | F36: Ensure that a Microsoft Entra Diagnostic Setting Exists to Send Microsoft Graph Activity Logs to an Appropriate Destination | G36: Level 2 | H36: Manual | I36: CIS Microsoft Azure Foundations Benchmark v6.0.0 | J36: None
A37: 36 | B37: Management & Governance | C37: Azure Monitor (Logging & Alerting) | D37: Management and Governance Services > Logging and Monitoring > Configuring Diagnostic Settings | E37: 6.1.1.8 | F37: Ensure that a Microsoft Entra Diagnostic Setting Exists to Send Microsoft Entra Activity Logs to an Appropriate Destination | G37: Level 2 | H37: Manual | I37: CIS Microsoft Azure Foundations Benchmark v6.0.0 | J37: None
A38: 37 | B38: Management & Governance | C38: Azure Monitor (Logging & Alerting) | D38: Management and Governance Services > Logging and Monitoring > Configuring Diagnostic Settings | E38: 6.1.1.9 | F38: Ensure that Intune Logs are Captured and Sent to Log Analytics | G38: Level 2 | H38: Manual | I38: CIS Microsoft Azure Foundations Benchmark v6.0.0 | J38: None
A39: 38 | B39: Management & Governance | C39: Azure Monitor (Logging & Alerting) | D39: Management and Governance Services > Logging and Monitoring > Monitoring Using Activity Log Alerts | E39: 6.1.2.1 | F39: Ensure that Activity Log Alert Exists for Create Policy Assignment | G39: Level 1 | H39: Automated | I39: CIS Microsoft Azure Foundations Benchmark v6.0.0 | J39: None
A40: 39 | B40: Management & Governance | C40: Azure Monitor (Logging & Alerting) | D40: Management and Governance Services > Logging and Monitoring > Monitoring Using Activity Log Alerts | E40: 6.1.2.2 | F40: Ensure that Activity Log Alert exists for Delete Policy Assignment | G40: Level 1 | H40: Automated | I40: CIS Microsoft Azure Foundations Benchmark v6.0.0 | J40: None
A41: 40 | B41: Management & Governance | C41: Azure Monitor (Logging & Alerting) | D41: Management and Governance Services > Logging and Monitoring > Monitoring Using Activity Log Alerts | E41: 6.1.2.3 | F41: Ensure that Activity Log Alert Exists for Create or Update Network Security Group | G41: Level 1 | H41: Automated | I41: CIS Microsoft Azure Foundations Benchmark v6.0.0 | J41: None
A42: 41 | B42: Management & Governance | C42: Azure Monitor (Logging & Alerting) | D42: Management and Governance Services > Logging and Monitoring > Monitoring Using Activity Log Alerts | E42: 6.1.2.4 | F42: Ensure that Activity Log Alert Exists for Delete Network Security Group | G42: Level 1 | H42: Automated | I42: CIS Microsoft Azure Foundations Benchmark v6.0.0 | J42: None
A43: 42 | B43: Management & Governance | C43: Azure Monitor (Logging & Alerting) | D43: Management and Governance Services > Logging and Monitoring > Monitoring Using Activity Log Alerts | E43: 6.1.2.5 | F43: Ensure that Activity Log Alert Exists for Create or Update Security Solution | G43: Level 1 | H43: Automated | I43: CIS Microsoft Azure Foundations Benchmark v6.0.0 | J43: None
A44: 43 | B44: Management & Governance | C44: Azure Monitor (Logging & Alerting) | D44: Management and Governance Services > Logging and Monitoring > Monitoring Using Activity Log Alerts | E44: 6.1.2.6 | F44: Ensure that Activity Log Alert Exists for Delete Security Solution | G44: Level 1 | H44: Automated | I44: CIS Microsoft Azure Foundations Benchmark v6.0.0 | J44: None
...

Sheet Compute v2.0.0
A1: # | B1: Service Category | C1: Azure Service | D1: Section / Sub-service | E1: CIS ID | F1: Control (CIS Recommendation) | G1: Profile | H1: Assessment | I1: CIS Benchmark (Version) | J1: Overlap Flag | K1: Overlap Reference
A2: 1 | B2: Compute | C2: Azure App Service | D2: App Service > App Service Apps | E2: 2.1.1 | F2: Ensure 'Java version' is currently supported (if in use) | G2: Level 1 | H2: Manual | I2: CIS Microsoft Azure Compute Services Benchmark v2.0.0 | J2: None
A3: 2 | B3: Compute | C3: Azure App Service | D3: App Service > App Service Apps | E3: 2.1.2 | F3: Ensure 'Python version' is currently supported (if in use) | G3: Level 1 | H3: Manual | I3: CIS Microsoft Azure Compute Services Benchmark v2.0.0 | J3: None
A4: 3 | B4: Compute | C4: Azure App Service | D4: App Service > App Service Apps | E4: 2.1.3 | F4: Ensure 'PHP version' is currently supported (if in use) | G4: Level 1 | H4: Manual | I4: CIS Microsoft Azure Compute Services Benchmark v2.0.0 | J4: None
A5: 4 | B5: Compute | C5: Azure App Service | D5: App Service > App Service Apps | E5: 2.1.4 | F5: Ensure 'Basic Authentication Publishing Credentials' are 'Disabled' | G5: Level 1 | H5: Automated | I5: CIS Microsoft Azure Compute Services Benchmark v2.0.0 | J5: None
A6: 5 | B6: Compute | C6: Azure App Service | D6: App Service > App Service Apps | E6: 2.1.5 | F6: Ensure 'FTP State' is set to 'FTPS only' or 'Disabled' | G6: Level 1 | H6: Automated | I6: CIS Microsoft Azure Compute Services Benchmark v2.0.0 | J6: None
A7: 6 | B7: Compute | C7: Azure App Service | D7: App Service > App Service Apps | E7: 2.1.6 | F7: Ensure 'HTTP version' is set to '2.0' (if in use) | G7: Level 1 | H7: Automated | I7: CIS Microsoft Azure Compute Services Benchmark v2.0.0 | J7: None
A8: 7 | B8: Compute | C8: Azure App Service | D8: App Service > App Service Apps | E8: 2.1.7 | F8: Ensure 'HTTPS Only' is set to 'On' | G8: Level 1 | H8: Automated | I8: CIS Microsoft Azure Compute Services Benchmark v2.0.0 | J8: None
A9: 8 | B9: Compute | C9: Azure App Service | D9: App Service > App Service Apps | E9: 2.1.8 | F9: Ensure 'Minimum Inbound TLS Version' is set to '1.2' or higher | G9: Level 1 | H9: Automated | I9: CIS Microsoft Azure Compute Services Benchmark v2.0.0 | J9: None
A10: 9 | B10: Compute | C10: Azure App Service | D10: App Service > App Service Apps | E10: 2.1.9 | F10: Ensure end-to-end TLS encryption is enabled | G10: Level 1 | H10: Automated | I10: CIS Microsoft Azure Compute Services Benchmark v2.0.0 | J10: None
A11: 10 | B11: Compute | C11: Azure App Service | D11: App Service > App Service Apps | E11: 2.1.10 | F11: Ensure 'Remote debugging' is set to 'Off' | G11: Level 1 | H11: Automated | I11: CIS Microsoft Azure Compute Services Benchmark v2.0.0 | J11: None
A12: 11 | B12: Compute | C12: Azure App Service | D12: App Service > App Service Apps | E12: 2.1.11 | F12: Ensure incoming client certificates are enabled and required (if in use) | G12: Level 2 | H12: Automated | I12: CIS Microsoft Azure Compute Services Benchmark v2.0.0 | J12: None
A13: 12 | B13: Compute | C13: Azure App Service | D13: App Service > App Service Apps | E13: 2.1.12 | F13: Ensure 'App Service authentication' is set to 'Enabled' | G13: Level 2 | H13: Automated | I13: CIS Microsoft Azure Compute Services Benchmark v2.0.0 | J13: None
... A95: 94 | B95: Compute | C95: Azure Virtual Machines | D95: Virtual Machines | E95: 20.6 | F95: Ensure that Only Approved Extensions Are Installed | G95: Level 1 | H95: Manual | I95: CIS Microsoft Azure Compute Services Benchmark v2.0.0 | J95: None
A96: 95 | B96: Compute | C96: Azure Virtual Machines | D96: Virtual Machines | E96: 20.7 | F96: Ensure that Endpoint Protection for all Virtual Machines is installed | G96: Level 2 | H96: Manual | I96: CIS Microsoft Azure Compute Services Benchmark v2.0.0 | J96: Related | K96: Foundations v6.0.0 8.1.3.3
A97: 96 | B97: Compute | C97: Azure Virtual Machines | D97: Virtual Machines | E97: 20.8 | F97: [Legacy] Ensure that VHDs are Encrypted | G97: Level 2 | H97: Manual | I97: CIS Microsoft Azure Compute Services Benchmark v2.0.0 | J97: None
A98: 97 | B98: Compute | C98: Azure Virtual Machines | D98: Virtual Machines | E98: 20.9 | F98: Ensure only MFA enabled identities can access privileged Virtual Machine | G98: Level 2 | H98: Manual | I98: CIS Microsoft Azure Compute Services Benchmark v2.0.0 | J98: Duplicate | K98: Foundations v6.0.0 3.1.1
A99: 98 | B99: Compute | C99: Azure Virtual Machines | D99: Virtual Machines | E99: 20.10 | F99: Ensure Trusted Launch is enabled on Virtual Machines | G99: Level 1 | H99: Automated | I99: CIS Microsoft Azure Compute Services Benchmark v2.0.0 | J99: None
A100: 99 | B100: Compute | C100: Azure Virtual Machines | D100: Virtual Machines | E100: 20.11 | F100: Ensure that encryption at host is enabled | G100: Level 1 | H100: Automated | I100: CIS Microsoft Azure Compute Services Benchmark v2.0.0 | J100: None

Sheet Database v2.0.0
A1: # | B1: Service Category | C1: Azure Service | D1: Section / Sub-service | E1: CIS ID | F1: Control (CIS Recommendation) | G1: Profile | H1: Assessment | I1: CIS Benchmark (Version) | J1: Overlap Flag | K1: Overlap Reference
A2: 1 | B2: Database | C2: Azure Cache for Redis | D2: Azure Cache for Redis (Retiring) | E2: 2.1 | F2: Ensure 'Microsoft Entra Authentication' is 'Enabled' | G2: Level 1 | H2: Manual | I2: CIS Microsoft Azure Database Services Benchmark v2.0.0 | J2: None
A3: 2 | B3: Database | C3: Azure Cache for Redis | D3: Azure Cache for Redis (Retiring) | E3: 2.2 | F3: Ensure that 'Allow access only via SSL' is set to 'Yes' | G3: Level 1 | H3: Automated | I3: CIS Microsoft Azure Database Services Benchmark v2.0.0 | J3: None
A4: 3 | B4: Database | C4: Azure Cache for Redis | D4: Azure Cache for Redis (Retiring) | E4: 2.3 | F4: Ensure that 'Minimum TLS version' is set to TLS v1.2 (or higher) | G4: Level 1 | H4: Manual | I4: CIS Microsoft Azure Database Services Benchmark v2.0.0 | J4: None
A5: 4 | B5: Database | C5: Azure Cache for Redis | D5: Azure Cache for Redis (Retiring) | E5: 2.4 | F5: Ensure that 'Access Policies' are Implemented and Reviewed Periodically | G5: Level 2 | H5: Manual | I5: CIS Microsoft Azure Database Services Benchmark v2.0.0 | J5: None
A6: 5 | B6: Database | C6: Azure Cache for Redis | D6: Azure Cache for Redis (Retiring) | E6: 2.5 | F6: Ensure that 'System Assigned Managed Identity' is set to 'On' | G6: Level 1 | H6: Manual | I6: CIS Microsoft Azure Database Services Benchmark v2.0.0 | J6: None
A7: 6 | B7: Database | C7: Azure Cache for Redis | D7: Azure Cache for Redis (Retiring) | E7: 2.6 | F7: Ensure that 'Public Network Access' is 'Disabled' | G7: Level 2 | H7: Manual | I7: CIS Microsoft Azure Database Services Benchmark v2.0.0 | J7: None
A8: 7 | B8: Database | C8: Azure Cache for Redis | D8: Azure Cache for Redis (Retiring) | E8: 2.7 | F8: Ensure Azure Cache for Redis is Using a Private Link | G8: Level 2 | H8: Manual | I8: CIS Microsoft Azure Database Services Benchmark v2.0.0 | J8: None
A9: 8 | B9: Database | C9: Azure Cache for Redis | D9: Azure Cache for Redis (Retiring) | E9: 2.8 | F9: Ensure that Azure Cache for Redis is Using Customer-Managed Keys | G9: Level 2 | H9: Manual | I9: CIS Microsoft Azure Database Services Benchmark v2.0.0 | J9: None
A10: 9 | B10: Database | C10: Azure Cache for Redis | D10: Azure Cache for Redis (Retiring) | E10: 2.9 | F10: Ensure 'Access Keys Authentication' is set to 'Disabled' | G10: Level 1 | H10: Automated | I10: CIS Microsoft Azure Database Services Benchmark v2.0.0 | J10: None
A11: 10 | B11: Database | C11: Azure Cache for Redis | D11: Azure Cache for Redis (Retiring) | E11: 2.10 | F11: Ensure 'Update Channel' is set to 'Stable' | G11: Level 1 | H11: Automated | I11: CIS Microsoft Azure Database Services Benchmark v2.0.0 | J11: None
A12: 11 | B12: Database | C12: Azure Cosmos DB | D12: Azure Cosmos DB | E12: 3.1 | F12: Ensure That 'Firewalls & Networks' Is Limited to Use Selected Networks Instead of All Networks | G12: Level 2 | H12: Automated | I12: CIS Microsoft Azure Database Services Benchmark v2.0.0 | J12: None
A13: 12 | B13: Database | C13: Azure Cosmos DB | D13: Azure Cosmos DB | E13: 3.2 | F13: Ensure that Cosmos DB uses Private Endpoints where possible | G13: Level 2 | H13: Automated | I13: CIS Microsoft Azure Database Services Benchmark v2.0.0 | J13: None
... A50: 49 | B50: Database | C50: Azure SQL Database | D50: Azure SQL Database | E50: 9.8 | F50: Ensure 'Minimum TLS Version' is set to 'TLS 1.2' or higher | G50: Level 1 | H50: Automated | I50: CIS Microsoft Azure Database Services Benchmark v2.0.0 | J50: None

Sheet Storage v2.0.0
A1: # | B1: Service Category | C1: Azure Service | D1: Section / Sub-service | E1: CIS ID | F1: Control (CIS Recommendation) | G1: Profile | H1: Assessment | I1: CIS Benchmark (Version) | J1: Overlap Flag | K1: Overlap Reference
A2: 1 | B2: Storage | C2: Azure Backup | D2: Azure Backup > Backup Vaults | E2: 3.1.1 | F2: Ensure soft delete on Backup vaults is Enabled | G2: Level 1 | H2: Automated | I2: CIS Microsoft Azure Storage Services Benchmark v2.0.0 | J2: None
A3: 2 | B3: Storage | C3: Azure Backup | D3: Azure Backup > Backup Vaults | E3: 3.1.2 | F3: Ensure immutability for Backup vaults is Enabled | G3: Level 1 | H3: Automated | I3: CIS Microsoft Azure Storage Services Benchmark v2.0.0 | J3: None
A4: 3 | B4: Storage | C4: Azure Backup | D4: Azure Backup > Backup Vaults | E4: 3.1.3 | F4: Ensure backup data in Backup vaults is encrypted using customer-managed keys (CMK) | G4: Level 2 | H4: Automated | I4: CIS Microsoft Azure Storage Services Benchmark v2.0.0 | J4: None
A5: 4 | B5: Storage | C5: Azure Backup | D5: Azure Backup > Backup Vaults | E5: 3.1.4 | F5: Ensure 'Use infrastructure encryption for this vault' is enabled on Backup vaults | G5: Level 2 | H5: Automated | I5: CIS Microsoft Azure Storage Services Benchmark v2.0.0 | J5: None
A6: 5 | B6: Storage | C6: Azure Backup | D6: Azure Backup > Backup Vaults | E6: 3.1.5 | F6: Ensure 'Cross Region Restore' is set to 'Enabled' on Backup vaults | G6: Level 2 | H6: Automated | I6: CIS Microsoft Azure Storage Services Benchmark v2.0.0 | J6: None
A7: 6 | B7: Storage | C7: Azure Backup | D7: Azure Backup > Backup Vaults | E7: 3.1.6 | F7: Ensure 'Cross Subscription Restore' is set to 'Disabled' or 'Permanently Disabled' on Backup vaults | G7: Level 1 | H7: Automated | I7: CIS Microsoft Azure Storage Services Benchmark v2.0.0 | J7: None
A8: 7 | B8: Storage | C8: Azure Backup | D8: Azure Backup > Recovery Services Vaults | E8: 3.2.1 | F8: Ensure soft delete on Recovery Services vaults is Enabled | G8: Level 1 | H8: Automated | I8: CIS Microsoft Azure Storage Services Benchmark v2.0.0 | J8: None
A9: 8 | B9: Storage | C9: Azure Backup | D9: Azure Backup > Recovery Services Vaults | E9: 3.2.2 | F9: Ensure immutability for Recovery Services vaults is Enabled | G9: Level 1 | H9: Automated | I9: CIS Microsoft Azure Storage Services Benchmark v2.0.0 | J9: None
A10: 9 | B10: Storage | C10: Azure Backup | D10: Azure Backup > Recovery Services Vaults | E10: 3.2.3 | F10: Ensure backup data in Recovery Services vaults is encrypted using customer-managed keys (CMK) | G10: Level 2 | H10: Automated | I10: CIS Microsoft Azure Storage Services Benchmark v2.0.0 | J10: None
A11: 10 | B11: Storage | C11: Azure Backup | D11: Azure Backup > Recovery Services Vaults | E11: 3.2.4 | F11: Ensure 'Use infrastructure encryption for this vault' is enabled on Recovery Services vaults | G11: Level 2 | H11: Automated | I11: CIS Microsoft Azure Storage Services Benchmark v2.0.0 | J11: None
A12: 11 | B12: Storage | C12: Azure Backup | D12: Azure Backup > Recovery Services Vaults | E12: 3.2.5 | F12: Ensure public network access on Recovery Services vaults is Disabled | G12: Level 1 | H12: Automated | I12: CIS Microsoft Azure Storage Services Benchmark v2.0.0 | J12: None
A13: 12 | B13: Storage | C13: Azure Backup | D13: Azure Backup > Recovery Services Vaults | E13: 3.2.6 | F13: Ensure 'Cross Region Restore' is set to 'Enabled' on Recovery Services vaults | G13: Level 2 | H13: Automated | I13: CIS Microsoft Azure Storage Services Benchmark v2.0.0 | J13: None
... A21: 20 | B21: Storage | C21: Azure Files | D21: Azure Files > File Shares (Microsoft.FileShares) | E21: 7.1.5 | F21: Ensure private endpoints are configured for File Shares (Microsoft.FileShares) | G21: Level 2 | H21: Automated | I21: CIS Microsoft Azure Storage Services Benchmark v2.0.0 | J21: None
A22: 21 | B22: Storage | C22: Azure Files | D22: Azure Files > Classic File Shares (Microsoft.Storage) | E22: 7.2.1 | F22: Ensure soft delete for Azure File Shares is Enabled (Classic File Shares) | G22: Level 1 | H22: Automated | I22: CIS Microsoft Azure Storage Services Benchmark v2.0.0 | J22: Duplicate | K22: Foundations v6.0.0 9.1.1
A23: 22 | B23: Storage | C23: Azure Files | D23: Azure Files > Classic File Shares (Microsoft.Storage) | E23: 7.2.2 | F23: Ensure 'SMB channel encryption' is set to 'AES-256-GCM' or higher for SMB file shares (Classic File Shares) | G23: Level 1 | H23: Automated | I23: CIS Microsoft Azure Storage Services Benchmark v2.0.0 | J23: Duplicate | K23: Foundations v6.0.0 9.1.3
A24: 23 | B24: Storage | C24: Azure Files | D24: Azure Files > Classic File Shares (Microsoft.Storage) | E24: 7.2.3 | F24: Ensure 'SMB protocol version' is set to 'SMB 3.1.1' or higher for SMB file shares (Classic File Shares) | G24: Level 1 | H24: Automated | I24: CIS Microsoft Azure Storage Services Benchmark v2.0.0 | J24: Duplicate | K24: Foundations v6.0.0 9.1.2
A25: 24 | B25: Storage | C25: Azure Files | D25: Azure Files > Classic File Shares (Microsoft.Storage) | E25: 7.2.4 | F25: Ensure root squash for NFS file shares is configured (Classic File Shares) | G25: Level 1 | H25: Automated | I25: CIS Microsoft Azure Storage Services Benchmark v2.0.0 | J25: None
A26: 25 | B26: Storage | C26: Azure NetApp Files | D26: Azure NetApp Files | E26: 9.1 | F26: Ensure 'Encryption key source' is set to 'Customer Managed Key' for Azure NetApp Files accounts | G26: Level 2 | H26: Automated | I26: CIS Microsoft Azure Storage Services Benchmark v2.0.0 | J26: None
A27: 26 | B27: Storage | C27: Azure Blob Storage | D27: Azure Blob Storage | E27: 10.1 | F27: Ensure 'Allowed Protocols' for shared access signature (SAS) tokens is set to 'HTTPS Only' | G27: Level 1 | H27: Manual | I27: CIS Microsoft Azure Storage Services Benchmark v2.0.0 | J27: Related (same benchmark, other scope) | K27: SAS tokens HTTPS only: Storage v2.0.0 15.1, Storage v2.0.0 16.1.2
A28: 27 | B28: Storage | C28: Azure Blob Storage | D28: Azure Blob Storage | E28: 10.2 | F28: Ensure that shared access signature (SAS) tokens expire within an hour | G28: Level 2 | H28: Manual | I28: CIS Microsoft Azure Storage Services Benchmark v2.0.0 | J28: Related (same benchmark, other scope) | K28: SAS token expiry <= 1 hour: Storage v2.0.0 15.2, Storage v2.0.0 16.1.6, Storage v2.0.0 17.1
A29: 28 | B29: Storage | C29: Azure Blob Storage | D29: Azure Blob Storage | E29: 10.3 | F29: Ensure that soft delete for blobs on Azure Blob Storage storage accounts is Enabled | G29: Level 1 | H29: Automated | I29: CIS Microsoft Azure Storage Services Benchmark v2.0.0 | J29: Duplicate | K29: Foundations v6.0.0 9.2.1; Blob soft delete: Storage v2.0.0 16.7
A30: 29 | B30: Storage | C30: Azure Blob Storage | D30: Azure Blob Storage | E30: 10.4 | F30: Ensure stored access policies (SAP) are used when generating shared access signature (SAS) tokens | G30: Level 1 | H30: Manual | I30: CIS Microsoft Azure Storage Services Benchmark v2.0.0 | J30: Related (same benchmark, other scope) | K30: Stored access policies for SAS: Storage v2.0.0 15.3, Storage v2.0.0 17.2
A31: 30 | B31: Storage | C31: Azure Blob Storage | D31: Azure Blob Storage | E31: 10.5 | F31: Ensure 'Versioning' is set to 'Enabled' on Azure Blob Storage storage accounts | G31: Level 2 | H31: Automated | I31: CIS Microsoft Azure Storage Services Benchmark v2.0.0 | J31: Duplicate | K31: Foundations v6.0.0 9.2.3
A32: 31 | B32: Storage | C32: Azure Blob Storage | D32: Azure Blob Storage | E32: 10.6 | F32: Ensure locked immutability policies are used for containers storing business-critical blob data | G32: Level 2 | H32: Automated | I32: CIS Microsoft Azure Storage Services Benchmark v2.0.0 | J32: None
A33: 32 | B33: Storage | C33: Azure Data Box | D33: Azure Data Box | E33: 11.1 | F33: Ensure double encryption is used for Azure Data Box in high-security environments | G33: Level 2 | H33: Manual | I33: CIS Microsoft Azure Storage Services Benchmark v2.0.0 | J33: None
A34: 33 | B34: Storage | C34: Azure Elastic SAN | D34: Azure Elastic SAN | E34: 14.1 | F34: Ensure 'Public network access' is set to 'Disabled' on Azure Elastic SAN | G34: Level 2 | H34: Automated | I34: CIS Microsoft Azure Storage Services Benchmark v2.0.0 | J34: None
A35: 34 | B35: Storage | C35: Azure Elastic SAN | D35: Azure Elastic SAN | E35: 14.2 | F35: Ensure customer-managed keys (CMK) are used to encrypt data at rest on Azure Elastic SAN volume groups | G35: Level 2 | H35: Automated | I35: CIS Microsoft Azure Storage Services Benchmark v2.0.0 | J35: None
A36: 35 | B36: Storage | C36: Azure Queue Storage | D36: Queue Storage | E36: 15.1 | F36: Ensure 'Allowed Protocols' for shared access signature (SAS) tokens is set to 'HTTPS Only' | G36: Level 1 | H36: Manual | I36: CIS Microsoft Azure Storage Services Benchmark v2.0.0 | J36: Related (same benchmark, other scope) | K36: SAS tokens HTTPS only: Storage v2.0.0 10.1, Storage v2.0.0 16.1.2
A37: 36 | B37: Storage | C37: Azure Queue Storage | D37: Queue Storage | E37: 15.2 | F37: Ensure that shared access signature (SAS) tokens expire within an hour | G37: Level 2 | H37: Manual | I37: CIS Microsoft Azure Storage Services Benchmark v2.0.0 | J37: Related (same benchmark, other scope) | K37: SAS token expiry <= 1 hour: Storage v2.0.0 10.2, Storage v2.0.0 16.1.6, Storage v2.0.0 17.1
A38: 37 | B38: Storage | C38: Azure Queue Storage | D38: Queue Storage | E38: 15.3 | F38: Ensure stored access policies (SAP) are used when generating shared access signature (SAS) tokens | G38: Level 1 | H38: Manual | I38: CIS Microsoft Azure Storage Services Benchmark v2.0.0 | J38: Related (same benchmark, other scope) | K38: Stored access policies for SAS: Storage v2.0.0 10.4, Storage v2.0.0 17.2
A39: 38 | B39: Storage | C39: Azure Storage Accounts | D39: Storage Accounts > Secrets and Keys | E39: 16.1.1 | F39: Ensure that 'Enable key rotation reminders' is enabled for each Storage Account | G39: Level 1 | H39: Manual | I39: CIS Microsoft Azure Storage Services Benchmark v2.0.0 | J39: Duplicate | K39: Foundations v6.0.0 9.3.1.1
A40: 39 | B40: Storage | C40: Azure Storage Accounts | D40: Storage Accounts > Secrets and Keys | E40: 16.1.2 | F40: Ensure 'Allowed Protocols' for shared access signature (SAS) tokens is set to 'HTTPS Only' | G40: Level 1 | H40: Manual | I40: CIS Microsoft Azure Storage Services Benchmark v2.0.0 | J40: Related (same benchmark, other scope) | K40: SAS tokens HTTPS only: Storage v2.0.0 10.1, Storage v2.0.0 15.1
A41: 40 | B41: Storage | C41: Azure Storage Accounts | D41: Storage Accounts > Secrets and Keys | E41: 16.1.3 | F41: Ensure that Storage Account Access Keys are Periodically Regenerated | G41: Level 1 | H41: Manual | I41: CIS Microsoft Azure Storage Services Benchmark v2.0.0 | J41: Duplicate | K41: Foundations v6.0.0 9.3.1.2
A42: 41 | B42: Storage | C42: Azure Storage Accounts | D42: Storage Accounts > Secrets and Keys | E42: 16.1.4 | F42: Ensure that a shared access signature (SAS) expiration policy is configured | G42: Level 1 | H42: Automated | I42: CIS Microsoft Azure Storage Services Benchmark v2.0.0 | J42: None
A43: 42 | B43: Storage | C43: Azure Storage Accounts | D43: Storage Accounts > Secrets and Keys | E43: 16.1.5 | F43: Ensure the shared access signature (SAS) expiration policy action is set to 'Block' | G43: Level 2 | H43: Automated | I43: CIS Microsoft Azure Storage Services Benchmark v2.0.0 | J43: None
A44: 43 | B44: Storage | C44: Azure Storage Accounts | D44: Storage Accounts > Secrets and Keys | E44: 16.1.6 | F44: Ensure that shared access signature (SAS) tokens expire within an hour | G44: Level 2 | H44: Manual | I44: CIS Microsoft Azure Storage Services Benchmark v2.0.0 | J44: Related (same benchmark, other scope) | K44: SAS token expiry <= 1 hour: Storage v2.0.0 10.2, Storage v2.0.0 15.2, Storage v2.0.0 17.1
A45: 44 | B45: Storage | C45: Azure Storage Accounts | D45: Storage Accounts > Secrets and Keys | E45: 16.1.7 | F45: Ensure 'Allow storage account key access' for Azure Storage Accounts is 'Disabled' | G45: Level 1 | H45: Automated | I45: CIS Microsoft Azure Storage Services Benchmark v2.0.0 | J45: Duplicate | K45: Foundations v6.0.0 9.3.1.3
A46: 45 | B46: Storage | C46: Azure Storage Accounts | D46: Storage Accounts > Secrets and Keys | E46: 16.1.8 | F46: Ensure Storage for Critical Data are Encrypted with Customer Managed Keys (CMK) | G46: Level 2 | H46: Manual | I46: CIS Microsoft Azure Storage Services Benchmark v2.0.0 | J46: Related | K46: Foundations v6.0.0 6.1.1.3
A47: 46 | B47: Storage | C47: Azure Storage Accounts | D47: Storage Accounts > Networking | E47: 16.2.1 | F47: Ensure Private Endpoints are used to access Storage Accounts | G47: Level 2 | H47: Automated | I47: CIS Microsoft Azure Storage Services Benchmark v2.0.0 | J47: Duplicate | K47: Foundations v6.0.0 9.3.2.1
...

Sheet Overlaps
A1: Overlap Type | B1: Foundations v6.0.0 ID | C1: Foundations Control | D1: Service Benchmark | E1: Service Benchmark ID | F1: Service Benchmark Control | G1: Recommendation
A2: Duplicate | B2: 3.1.1 | C2: Ensure only MFA Enabled Identities can Access Privileged Virtual Machine | D2: Compute v2.0.0 | E2: 20.9 | F2: Ensure only MFA enabled identities can access privileged Virtual Machine | G2: Implement once; map evidence to both IDs
A3: Duplicate | B3: 9.1.1 | C3: Ensure Soft Delete for Azure File Shares is Enabled | D3: Storage v2.0.0 | E3: 7.2.1 | F3: Ensure soft delete for Azure File Shares is Enabled (Classic File Shares) | G3: Implement once; map evidence to both IDs
A4: Duplicate | B4: 9.1.2 | C4: Ensure 'SMB protocol version' is Set to 'SMB 3.1.1' or Higher for SMB file shares | D4: Storage v2.0.0 | E4: 7.2.3 | F4: Ensure 'SMB protocol version' is set to 'SMB 3.1.1' or higher for SMB file shares (Classic File Shares) | G4: Implement once; map evidence to both IDs
A5: Duplicate | B5: 9.1.3 | C5: Ensure 'SMB channel encryption' is Set to 'AES-256-GCM' or Higher for SMB file shares | D5: Storage v2.0.0 | E5: 7.2.2 | F5: Ensure 'SMB channel encryption' is set to 'AES-256-GCM' or higher for SMB file shares (Classic File Shares) | G5: Implement once; map evidence to both IDs
A6: Duplicate | B6: 9.2.1 | C6: Ensure That Soft Delete for Blobs on Azure Blob Storage Storage Accounts is Enabled | D6: Storage v2.0.0 | E6: 10.3 | F6: Ensure that soft delete for blobs on Azure Blob Storage storage accounts is Enabled | G6: Implement once; map evidence to both IDs
A7: Near-duplicate | B7: 9.2.2 | C7: Ensure that Soft Delete for Containers on Azure Blob Storage Storage Accounts is Enabled | D7: Storage v2.0.0 | E7: 16.7 | F7: Ensure Soft Delete is Enabled for Azure Containers and Blob Storage | G7: Implement the stricter wording; map to both
A8: Duplicate | B8: 9.2.3 | C8: Ensure 'Versioning' is Set to 'Enabled' on Azure Blob Storage Storage Accounts | D8: Storage v2.0.0 | E8: 10.5 | F8: Ensure 'Versioning' is set to 'Enabled' on Azure Blob Storage storage accounts | G8: Implement once; map evidence to both IDs
A9: Duplicate | B9: 9.3.1.1 | C9: Ensure That 'Enable key rotation reminders' is Enabled for Each Storage Account | D9: Storage v2.0.0 | E9: 16.1.1 | F9: Ensure that 'Enable key rotation reminders' is enabled for each Storage Account | G9: Implement once; map evidence to both IDs
A10: Duplicate | B10: 9.3.1.2 | C10: Ensure That Storage Account Access keys are Periodically Regenerated | D10: Storage v2.0.0 | E10: 16.1.3 | F10: Ensure that Storage Account Access Keys are Periodically Regenerated | G10: Implement once; map evidence to both IDs
A11: Duplicate | B11: 9.3.1.3 | C11: Ensure 'Allow storage account key access' for Azure Storage Accounts is 'Disabled' | D11: Storage v2.0.0 | E11: 16.1.7 | F11: Ensure 'Allow storage account key access' for Azure Storage Accounts is 'Disabled' | G11: Implement once; map evidence to both IDs
A12: Duplicate | B12: 9.3.2.1 | C12: Ensure Private Endpoints are Used to Access Storage Accounts | D12: Storage v2.0.0 | E12: 16.2.1 | F12: Ensure Private Endpoints are used to access Storage Accounts | G12: Implement once; map evidence to both IDs
... A28: Related (same benchmark, other scope) | B28: - | C28: - | D28: Storage v2.0.0 | E28: 10.3, 16.7 | F28: Blob soft delete | G28: Same requirement at different scopes (Blob / Queue / Account / Storage Explorer); one policy can cover them all
