Workbook

Sheet Overview
A1: Security Hardening & Evergreen Governance Program - Plan v2
A2: Prepared 19 Oct 2026. Yellow cells are inputs. All dated/versioned facts are sourced on the Sources tab.
A4: Program Week 1 start (input) | B4: 46321
A5: Program Week 26 end | B5: =B4+7*26-1 -> 46502
A6: Week 0 (Immediate) start | B6: =B4-7 -> 46314
A8: Goal | B8: Deliver a decision-ready, staffed 26-week security program that (1) hardens OS and containers, (2) hardens security monitoring and response, and (3) installs an evergreen governance model, for an AWS-hosted Ethereum/Solana dApp business pursuing SOC 2.
A9: Timeline | B9: Week 0 = 19-25 Oct 2026 (Immediate actions). Week 1 starts Mon 26 Oct 2026; Week 26 ends Sun 25 Apr 2027. Weeks 9-10 (21 Dec 2026 - 3 Jan 2027) are reduced-capacity with a production change freeze (emergency changes only).
A10: In scope | B10: AWS multi-account org (Control Tower, Organizations, EC2 Linux, EKS, ECS/EC2 containers, data services, network, logging, backup); Microsoft Entra ID (workforce), Azure AD B2C (customers), IAM Identity Center; Splunk SIEM/SOAR, CrowdStrike EDR, MDR; Ethereum Solidity contracts and Solana Rust/Anchor programs, admin multisigs (Safe/Squads), MPC custody vendor oversight, staking-provider oversight; SOC 2 readiness and Type I; policies, TPRM, HR controls, training.
A11: Out of scope | B11: MiCA/DORA/PCI DSS build-out (go/no-go only, D-01); AML/money-transmission programme (contingent on D-01); running own validators; executing the B2C -> External ID migration (roadmap only); ISO 27001 certification (alignment only); Windows workloads; physical security; budget costing (envelope requested at Gate 1).
A13: Headline numbers (live)
A14: Total tasks | B14: =COUNTA('Project Plan'!$A$7:$A$156) -> 150
A15: Immediate actions (with owner + deadline) | B15: =COUNTIF('Project Plan'!$U$7:$U$156,"?*") -> 16
A16: Workstreams | B16: =6 -> 6
A17: Steering gates | B17: =COUNTA(A55:A58) -> 4
A18: Internal program FTE | B18: ='Roles & Skills'!E27 -> 5
A19: Contractor FTE (peak concurrent) | B19: ='Roles & Skills'!E28 -> 6.5
A20: Contractor FTE-weeks | B20: ='Roles & Skills'!H27 -> 133
A21: Partner/firm engagements | B21: ='Roles & Skills'!E29 -> 7
A22: KPIs | B22: =COUNTA(KPIs!A5:A29) -> 25
A23: Decisions in log | B23: =COUNTA('Risks and Decisions'!A30:A46) -> 17
A24: Risks in register | B24: =COUNTA('Risks and Decisions'!A5:A26) -> 22
A25: Review findings logged | B25: =COUNTA('Review Log'!A5:A66) -> 62
A26: Dependency violations (must be 0) | B26: =COUNTIF('Project Plan'!$K$7:$K$156,"VIOLATION") -> 0
A27: Tasks ending after W26 (must be 0) | B27: =COUNTIF('Project Plan'!$L$7:$L$156,"LATE") -> 0
A28: Decision misalignments (must be 0) | B28: =COUNTIF('Risks and Decisions'!J30:J46,"MISALIGNED") -> 0
A29: Role overloads (must be 0) | B29: =COUNTIF('Roles & Skills'!P5:P26,"OVER") -> 0
A31: Assumptions
A32: • Non-EU firm; no EU solicitation of customers; SOC 2 is the primary compliance driver (user-confirmed). Confirmed or overturned by D-01 in W4.
A33: • No cardholder data in scope (user-confirmed); any future card acceptance via hosted iframe/redirect would fall under PCI DSS v4.0.1 SAQ A.
A34: • Amazon Linux 2 workloads remain in the fleet alongside AL2023 (user-confirmed); exact count from HD-01.
A35: • Staking is delegated to a third-party staking provider (no self-run validators); treasury/hot wallets on a third-party MPC custody platform; admin keys in Safe (EVM) and Squads v4 (Solana) multisigs.
A36: • Splunk remains the SIEM (Enterprise Security 8.x, SOAR available); CrowdStrike Falcon covers EC2. Microsoft Sentinel is not adopted, so its Azure-portal retirement (31 Mar 2027) is noted but not actioned.
A37: • Security program team = 5.0 internal FTE plus contractors/partners; platform and application engineering teams implement changes (supporting role, outside program FTE).
A38: • Assumed US-headquartered entity for OFAC/state-law purposes (to be confirmed in D-01).
A39: • Whether the business is custodial for customer funds (withdrawal flows exist) is UNVERIFIED; D-01 answers custodial / FinCEN MSB / state licensing / FTC Safeguards Rule. Any 'yes' triggers a re-plan at Gate 1.
A40: • Weeks 9-10 (21 Dec 2026 - 3 Jan 2027) are a production change freeze; design and non-prod work continues at reduced capacity.
A41: • Capacity rule: each role leads at most round(3 x FTE) concurrent tasks and carries a weighted load (lead 1.0 + support 0.25 per task) of at most 4 x FTE in any week.
A42: • Budget is not costed in this plan; licence uplifts (Entra P2/ID Governance, Security Hub per-resource pricing, EKS extended support, Splunk ingest) are flagged as decisions/risks.
A44: Phases
A45: Phase | B45: Name | C45: Start wk | D45: End wk | E45: Start date | F45: Purpose
...

Sheet Project Plan
A1: Project Plan - 150 tasks; End wk, dates and checks are formulas; Gantt W0-W26 via conditional formatting
A2: Status column has a dropdown. Dependency check = every dependency ends before this task starts. Weeks 9-10 shaded = production change freeze.
A4: Legend: | B4: HD OS & Container Hardening | C4: ID Identity Hardening | D4: MR Security Monitoring, Response & Resilience | E4: BC Blockchain Security | F4: GC Governance & Compliance | G4: PM Program Management & Sustainment
W5: =Overview!$B$4+7*(W6-1) -> 46314 | X5: =Overview!$B$4+7*(X6-1) -> 46321 | Y5: =Overview!$B$4+7*(Y6-1) -> 46328 | Z5: =Overview!$B$4+7*(Z6-1) -> 46335 | AA5: =Overview!$B$4+7*(AA6-1) -> 46342 | AB5: =Overview!$B$4+7*(AB6-1) -> 46349 | AC5: =Overview!$B$4+7*(AC6-1) -> 46356 | AD5: =Overview!$B$4+7*(AD6-1) -> 46363 | ... AW5: =Overview!$B$4+7*(AW6-1) -> 46496
A6: ID | B6: Phase | C6: Workstream | D6: Task | E6: Key activities | F6: Start wk | G6: Duration (wks) | H6: End wk | I6: Dependencies (IDs) | J6: Latest dependency end | K6: Dependency check | L6: End-week check | M6: Start date | N6: End date | O6: Lead role | P6: Supporting roles | Q6: Skill set required | R6: Deliverable | S6: Benchmark / standard reference | T6: Status | U6: Immediate action (owner / deadline) | V6: Support (delimited) | W6: 0 | X6: 1 | Y6: 2 | Z6: 3 | AA6: 4 | AB6: 5 | AC6: 6 | AD6: 7 | AE6: 8 | AF6: 9 | AG6: 10 | AH6: 11 | AI6: 12 | AJ6: 13 | AK6: 14 | AL6: 15 | AM6: 16 | AN6: 17 | AO6: 18 | AP6: 19 | AQ6: 20 | AR6: 21 | AS6: 22 | AT6: 23 | AU6: 24 | AV6: 25 | AW6: 26
A7: PM-01 | B7: P0 Immediate (pre-program) | C7: PM | D7: Stand up Immediate-actions cell and name owners | E7: Daily 15-min stand-up for Immediate actions; owners/deadlines confirmed by exec sponsor | F7: 0 | G7: 1 | H7: =F7+G7-1 -> 0 | J7: =IF(I7="","",SUMPRODUCT(MAX(ISNUMBER(SEARCH(","&$A$7:$A$156&",",","&SUBSTITUTE(I7," ","")&","))*$H$7:$H$156))) | K7: =IF(I7="","OK",IF(F7>J7,"OK","VIOLATION")) -> OK | L7: =IF(H7<=26,"OK","LATE") -> OK | M7: =Overview!$B$4+7*(F7-1) -> 46314 | N7: =Overview!$B$4+7*(H7-1)+4 -> 46318 | O7: PL | P7: CSE; ISE; BSE; GRC | Q7: Program management | R7: Immediate-actions tracker with owners | S7: NIST CSF 2.0 GV.RR | T7: Not started | U7: Owner PL - Fri 23 Oct 2026 | V7: =";"&SUBSTITUTE(P7," ","")&";" -> ;CSE;ISE;BSE;GRC;
A8: ID-00 | B8: P0 Immediate (pre-program) | C8: ID | D8: Order FIDO2 security keys and signer hardware wallets | E8: Device-bound FIDO2 keys (approved models/AAGUIDs) for break-glass, admins, spares; clear-signing hardware wallets for on-chain signers | F8: 0 | G8: 1 | H8: =F8+G8-1 -> 0 | J8: =IF(I8="","",SUMPRODUCT(MAX(ISNUMBER(SEARCH(","&$A$7:$A$156&",",","&SUBSTITUTE(I8," ","")&","))*$H$7:$H$156))) | K8: =IF(I8="","OK",IF(F8>J8,"OK","VIOLATION")) -> OK | L8: =IF(H8<=26,"OK","LATE") -> OK | M8: =Overview!$B$4+7*(F8-1) -> 46314 | N8: =Overview!$B$4+7*(H8-1)+4 -> 46318 | O8: PL | P8: ISE; BSE | Q8: Procurement | R8: Purchase orders; delivery tracked to W3 | S8: Entra passkey (FIDO2) docs; SEAL Wallet Security | T8: Not started | U8: Owner PL - order by Fri 23 Oct 2026 | V8: =";"&SUBSTITUTE(P8," ","")&";" -> ;ISE;BSE;
A9: GC-01 | B9: P0 Immediate (pre-program) | C9: GC | D9: Regulatory scope go/no-go (D-01) with counsel engaged in W0 | E9: Counsel opinion: MiCA Art 61 reverse solicitation/ESMA guidelines; DORA (only via MiCA authorisation); PCI DSS (no CHD); US: custodial vs non-custodial, FinCEN MSB status, state money-transmission, OFAC, FTC Safeguards Rule, NYDFS; any 'yes' triggers re-plan at Gate 1 | F9: 0 | G9: 5 | H9: =F9+G9-1 -> 4 | J9: =IF(I9="","",SUMPRODUCT(MAX(ISNUMBER(SEARCH(","&$A$7:$A$156&",",","&SUBSTITUTE(I9," ","")&","))*$H$7:$H$156))) | K9: =IF(I9="","OK",IF(F9>J9,"OK","VIOLATION")) -> OK | L9: =IF(H9<=26,"OK","LATE") -> OK | M9: =Overview!$B$4+7*(F9-1) -> 46314 | N9: =Overview!$B$4+7*(H9-1)+4 -> 46346 | O9: GRC | P9: LEG; PL | Q9: Regulatory analysis | R9: Signed regulatory scope memo (D-01) | S9: MiCA Art 61/143; ESMA35-1872330276-2030; DORA Art 2(1)(f); PCI DSS v4.0.1; FinCEN FIN-2019-G001; OFAC VC guidance | T9: Not started | U9: Owner GRC - signed by Steering Fri 20 Nov 2026 (W4) | V9: =";"&SUBSTITUTE(P9," ","")&";" -> ;LEG;PL;
A10: BC-01 | B10: P0 Immediate (pre-program) | C10: BC | D10: Alpenglow readiness confirmation from staking provider (activates 21 Oct 2026) | E10: By Tue 20 Oct: written confirmation of BLS pubkey registration, VAT funding (0.8 SOL burned PER EPOCH above rent-exempt, auto top-up), Agave-4.3.0-based client (Firedancer/Frankendancer unsupported during migration), VAT pass-through in commission; pre-approved re-delegation fallback; verify rewards for epochs 1065-1066 | F10: 0 | G10: 2 | H10: =F10+G10-1 -> 1 | J10: =IF(I10="","",SUMPRODUCT(MAX(ISNUMBER(SEARCH(","&$A$7:$A$156&",",","&SUBSTITUTE(I10," ","")&","))*$H$7:$H$156))) | K10: =IF(I10="","OK",IF(F10>J10,"OK","VIOLATION")) -> OK | L10: =IF(H10<=26,"OK","LATE") -> OK | M10: =Overview!$B$4+7*(F10-1) -> 46314 | N10: =Overview!$B$4+7*(H10-1)+4 -> 46325 | O10: BSE | Q10: Solana staking, vendor management | R10: Provider confirmation + reward-delta check note | S10: solana.com/upgrades/alpenglow; BSSC NOS v2 | T10: Not started | U10: Owner BSE - confirmation Tue 20 Oct 2026; reward check Fri 30 Oct 2026 | V10: =";"&SUBSTITUTE(P10," ","")&";" -> ;;
A11: BC-02 | B11: P0 Immediate (pre-program) | C11: BC | D11: Staking authority inventory and on-chain verification | E11: Every Ethereum validator: credential type (0x00/0x01/0x02) and that 0x01/0x02 point to our custody address; plan 0x00 change signed by us; provider-owned 0x01 -> exit/re-deposit via BC-19; Solana stake withdraw authority = our MPC vault; interim alerts on EIP-7002 requests and authority changes | F11: 0 | G11: 2 | H11: =F11+G11-1 -> 1 | J11: =IF(I11="","",SUMPRODUCT(MAX(ISNUMBER(SEARCH(","&$A$7:$A$156&",",","&SUBSTITUTE(I11," ","")&","))*$H$7:$H$156))) | K11: =IF(I11="","OK",IF(F11>J11,"OK","VIOLATION")) -> OK | L11: =IF(H11<=26,"OK","LATE") -> OK | M11: =Overview!$B$4+7*(F11-1) -> 46314 | N11: =Overview!$B$4+7*(H11-1)+4 -> 46325 | O11: BSE | P11: CSO | Q11: Ethereum/Solana staking internals | R11: Staking authority register (signed) | S11: EIP-7002; EIP-7251; Anza delegate-stake & vote-account docs; CCSS v9 | T11: Not started | U11: Owner BSE - Fri 30 Oct 2026 | V11: =";"&SUBSTITUTE(P11," ","")&";" -> ;CSO;
A12: BC-22 | B12: P0 Immediate (pre-program) | C12: BC | D12: Interim multisig hardening (Drift-pattern exposure) | E12: Raise Safe/Squads thresholds to policy minimum; enable Squads time lock on upgrade authorities; ban durable-nonce/pre-signed admin txs; confirm signer set and devices; emergency CUKC path | F12: 0 | G12: 3 | H12: =F12+G12-1 -> 2 | J12: =IF(I12="","",SUMPRODUCT(MAX(ISNUMBER(SEARCH(","&$A$7:$A$156&",",","&SUBSTITUTE(I12," ","")&","))*$H$7:$H$156))) | K12: =IF(I12="","OK",IF(F12>J12,"OK","VIOLATION")) -> OK | L12: =IF(H12<=26,"OK","LATE") -> OK | M12: =Overview!$B$4+7*(F12-1) -> 46314 | N12: =Overview!$B$4+7*(H12-1)+4 -> 46332 | O12: BSE | P12: CSO | Q12: Safe/Squads operations | R12: Interim multisig hardening record | S12: SEAL Multisig framework; Squads v4 docs | T12: Not started | U12: Owner BSE - Fri 6 Nov 2026 | V12: =";"&SUBSTITUTE(P12," ","")&";" -> ;CSO;
A13: HD-01 | B13: P0 Immediate (pre-program) | C13: HD | D13: EOL inventory: AL2 hosts/AMIs, EKS versions and upgradePolicy (D-10) | E13: Org-wide Config query + SSM inventory + EKS API: AL2 instances/AMIs/launch templates, ECS AMIs, cluster versions (1.31-1.37), node AMI types, per-cluster upgradePolicy (STANDARD auto-upgrades at end of standard support; EXTENDED costs $0.60/cluster-hr); D-10 recommendation | F13: 0 | G13: 2 | H13: =F13+G13-1 -> 1 | J13: =IF(I13="","",SUMPRODUCT(MAX(ISNUMBER(SEARCH(","&$A$7:$A$156&",",","&SUBSTITUTE(I13," ","")&","))*$H$7:$H$156))) | K13: =IF(I13="","OK",IF(F13>J13,"OK","VIOLATION")) -> OK | L13: =IF(H13<=26,"OK","LATE") -> OK | M13: =Overview!$B$4+7*(F13-1) -> 46314 | N13: =Overview!$B$4+7*(H13-1)+4 -> 46325 | O13: CSE | P13: ENG | Q13: AWS Config, EKS | R13: EOL register + D-10 recommendation | S13: AL2 FAQ (EOS 2026-06-30); EKS kubernetes-versions page; SH EKS.2/EKS.9 | T13: Not started | U13: Owner CSE - Fri 30 Oct 2026 | V13: =";"&SUBSTITUTE(P13," ","")&";" -> ;ENG;
A14: MR-01 | B14: P0 Immediate (pre-program) | C14: MR | D14: Enable agentless AWS detection services org-wide (independent of SIEM) | E14: Delegated admin; GuardDuty all accounts/Regions incl. EKS audit-log monitoring, S3 Protection, Malware Protection for EC2; Security Hub CSPM (FSBP + CIS AWS v5.0.0) and Security Hub; Inspector EC2/ECR/Lambda; Access Analyzer external + internal; Config all Regions; org CloudTrail. Runtime agents follow in MR-01B | F14: 0 | G14: 2 | H14: =F14+G14-1 -> 1 | J14: =IF(I14="","",SUMPRODUCT(MAX(ISNUMBER(SEARCH(","&$A$7:$A$156&",",","&SUBSTITUTE(I14," ","")&","))*$H$7:$H$156))) | K14: =IF(I14="","OK",IF(F14>J14,"OK","VIOLATION")) -> OK | L14: =IF(H14<=26,"OK","LATE") -> OK | M14: =Overview!$B$4+7*(F14-1) -> 46314 | N14: =Overview!$B$4+7*(H14-1)+4 -> 46325 | O14: CSE | P14: ISE | Q14: AWS security services | R14: Detection services coverage report | S14: SH GuardDuty.1/.5/.8/.10, Config.1, CloudTrail.1, Inspector.1-.4; CIS AWS v5.0.0 | T14: Not started | U14: Owner CSE - Fri 30 Oct 2026 | V14: =";"&SUBSTITUTE(P14," ","")&";" -> ;ISE;
A15: MR-21 | B15: P0 Immediate (pre-program) | C15: MR | D15: Archive Entra and B2C logs before they expire | E15: Diagnostic settings for Entra (sign-in incl. non-interactive/SP/MI, audit, risk, Graph activity) and B2C (via Azure Lighthouse) to immutable storage; Entra keeps only 30 days on P1/P2 | F15: 0 | G15: 2 | H15: =F15+G15-1 -> 1 | J15: =IF(I15="","",SUMPRODUCT(MAX(ISNUMBER(SEARCH(","&$A$7:$A$156&",",","&SUBSTITUTE(I15," ","")&","))*$H$7:$H$156))) | K15: =IF(I15="","OK",IF(F15>J15,"OK","VIOLATION")) -> OK | L15: =IF(H15<=26,"OK","LATE") -> OK | M15: =Overview!$B$4+7*(F15-1) -> 46314 | N15: =Overview!$B$4+7*(H15-1)+4 -> 46325 | O15: CSE | P15: ISE | Q15: Azure Monitor | R15: Log archive live (evidence preserved) | S15: Entra data-retention reference; B2C Azure Monitor docs | T15: Not started | U15: Owner CSE - Fri 30 Oct 2026 | V15: =";"&SUBSTITUTE(P15," ","")&";" -> ;ISE;
A16: MR-00 | B16: P0 Immediate (pre-program) | C16: MR | D16: Interim 24/7 coverage until MDR is live | E16: On-call rota incl. holiday weeks; paging tool; GuardDuty/Security Hub/Falcon high-severity alerts via EventBridge/SNS to pager; interim IR runbook (severity, contacts, SEAL 911, counsel) | F16: 0 | G16: 2 | H16: =F16+G16-1 -> 1 | J16: =IF(I16="","",SUMPRODUCT(MAX(ISNUMBER(SEARCH(","&$A$7:$A$156&",",","&SUBSTITUTE(I16," ","")&","))*$H$7:$H$156))) | K16: =IF(I16="","OK",IF(F16>J16,"OK","VIOLATION")) -> OK | L16: =IF(H16<=26,"OK","LATE") -> OK | M16: =Overview!$B$4+7*(F16-1) -> 46314 | N16: =Overview!$B$4+7*(H16-1)+4 -> 46325 | O16: ISE | P16: BSE | Q16: SOC operations | R16: On-call rota + paging + interim runbook | S16: NIST SP 800-61r3; CSF 2.0 DE.CM/RS.MA | T16: Not started | U16: Owner ISE - Fri 30 Oct 2026 | V16: =";"&SUBSTITUTE(P16," ","")&";" -> ;BSE;
A17: ID-01 | B17: P0 Immediate (pre-program) | C17: ID | D17: Break-glass accounts before any Conditional Access change | E17: 2 cloud-only permanent Global Admins with FIDO2/certificate auth distinct from admins; excluded from blocking CA; Sev-0 sign-in alert via Log Analytics to pager until Splunk; AWS break-glass: management-account root (2 FIDO2) + emergency role with alarm; test every 90 days | F17: 0 | G17: 2 | H17: =F17+G17-1 -> 1 | J17: =IF(I17="","",SUMPRODUCT(MAX(ISNUMBER(SEARCH(","&$A$7:$A$156&",",","&SUBSTITUTE(I17," ","")&","))*$H$7:$H$156))) | K17: =IF(I17="","OK",IF(F17>J17,"OK","VIOLATION")) -> OK | L17: =IF(H17<=26,"OK","LATE") -> OK | M17: =Overview!$B$4+7*(F17-1) -> 46314 | N17: =Overview!$B$4+7*(H17-1)+4 -> 46325 | O17: ISE | Q17: Entra ID, AWS IAM | R17: Break-glass runbook + test record | S17: Microsoft emergency-access guidance; mandatory Azure MFA; SH IAM.4/IAM.6 | T17: Not started | U17: Owner ISE - Fri 30 Oct 2026 | V17: =";"&SUBSTITUTE(P17," ","")&";" -> ;;
A18: ID-02 | B18: P0 Immediate (pre-program) | C18: ID | D18: Azure MFA Phase 2 (enforced): move user-run automation to workload identities | E18: Find CLI/PowerShell/IaC/SDK automation running as users (breaking now); migrate to managed identities/service principals with federated credentials (exempt) | F18: 0 | G18: 3 | H18: =F18+G18-1 -> 2 | J18: =IF(I18="","",SUMPRODUCT(MAX(ISNUMBER(SEARCH(","&$A$7:$A$156&",",","&SUBSTITUTE(I18," ","")&","))*$H$7:$H$156))) | K18: =IF(I18="","OK",IF(F18>J18,"OK","VIOLATION")) -> OK | L18: =IF(H18<=26,"OK","LATE") -> OK | M18: =Overview!$B$4+7*(F18-1) -> 46314 | N18: =Overview!$B$4+7*(H18-1)+4 -> 46332 | O18: ISE | P18: ENG | Q18: Entra workload identities | R18: Automation identity register; remediated pipelines | S18: Microsoft mandatory MFA (Phase 2) | T18: Not started | U18: Owner ISE - Fri 6 Nov 2026 | V18: =";"&SUBSTITUTE(P18," ","")&";" -> ;ENG;
A19: PM-02 | B19: P1 Mobilize | C19: PM | D19: Program charter, scope, success criteria and Steering ToR | E19: Charter; scope/out-of-scope; Steering membership and decision rights | F19: 1 | G19: 1 | H19: =F19+G19-1 -> 1 | I19: PM-01 | J19: =IF(I19="","",SUMPRODUCT(MAX(ISNUMBER(SEARCH(","&$A$7:$A$156&",",","&SUBSTITUTE(I19," ","")&","))*$H$7:$H$156))) -> 0 | K19: =IF(I19="","OK",IF(F19>J19,"OK","VIOLATION")) -> OK | L19: =IF(H19<=26,"OK","LATE") -> OK | M19: =Overview!$B$4+7*(F19-1) -> 46321 | N19: =Overview!$B$4+7*(H19-1)+4 -> 46325 | O19: PL | P19: GRC; PMC | Q19: Program management | R19: Signed charter | S19: NIST CSF 2.0 GV.OC/GV.RR | T19: Not started | V19: =";"&SUBSTITUTE(P19," ","")&";" -> ;GRC;PMC;
A20: PM-02A | B20: P0 Immediate (pre-program) | C20: PM | D20: Interim budget approval for long-lead commitments (D-17) | E20: CFO approves envelope for partners, 8 contractors (6.5 FTE peak) and licences booked in W1-2 (D-17); full budget at Gate 1 | F20: 0 | G20: 1 | H20: =F20+G20-1 -> 0 | J20: =IF(I20="","",SUMPRODUCT(MAX(ISNUMBER(SEARCH(","&$A$7:$A$156&",",","&SUBSTITUTE(I20," ","")&","))*$H$7:$H$156))) | K20: =IF(I20="","OK",IF(F20>J20,"OK","VIOLATION")) -> OK | L20: =IF(H20<=26,"OK","LATE") -> OK | M20: =Overview!$B$4+7*(F20-1) -> 46314 | N20: =Overview!$B$4+7*(H20-1)+4 -> 46318 | O20: PL | P20: PMC | Q20: Finance | R20: Approved interim budget | S20: NIST CSF 2.0 GV.RR-03 | T20: Not started | V20: =";"&SUBSTITUTE(P20," ","")&";" -> ;PMC;
A21: PM-03 | B21: P1 Mobilize | C21: PM | D21: Book long-lead partners and contractors (weeks 1-2) | E21: Sign: smart-contract auditor (slot W16-W19, sized by nSLOC; >4k nSLOC -> parallel teams), SOC 2 CPA, independent readiness assessor, MDR, pentest (W18), GRC platform trial, contractors (KHE/CPE/DET/IDC/CSO/BSC/GRCC/PMC) | F21: 1 | G21: 2 | H21: =F21+G21-1 -> 2 | I21: PM-01, PM-02A | J21: =IF(I21="","",SUMPRODUCT(MAX(ISNUMBER(SEARCH(","&$A$7:$A$156&",",","&SUBSTITUTE(I21," ","")&","))*$H$7:$H$156))) -> 0 | K21: =IF(I21="","OK",IF(F21>J21,"OK","VIOLATION")) -> OK | L21: =IF(H21<=26,"OK","LATE") -> OK | M21: =Overview!$B$4+7*(F21-1) -> 46321 | N21: =Overview!$B$4+7*(H21-1)+4 -> 46332 | O21: PL | P21: GRC; BSE; ISE; PMC | Q21: Procurement | R21: Signed SOWs / booked slots | S21: NIST CSF 2.0 GV.SC | T21: Not started | V21: =";"&SUBSTITUTE(P21," ","")&";" -> ;GRC;BSE;ISE;PMC;
A22: PM-04 | B22: P1 Mobilize | C22: PM | D22: Risk appetite statement and tolerances (D-14) | E22: On-chain loss tolerance, hot-wallet caps, velocity limits, max time-to-pause, patch SLAs, exception limits (max 90 days, one renewal) | F22: 2 | G22: 2 | H22: =F22+G22-1 -> 3 | I22: PM-02 | J22: =IF(I22="","",SUMPRODUCT(MAX(ISNUMBER(SEARCH(","&$A$7:$A$156&",",","&SUBSTITUTE(I22," ","")&","))*$H$7:$H$156))) -> 1 | K22: =IF(I22="","OK",IF(F22>J22,"OK","VIOLATION")) -> OK | L22: =IF(H22<=26,"OK","LATE") -> OK | M22: =Overview!$B$4+7*(F22-1) -> 46328 | N22: =Overview!$B$4+7*(H22-1)+4 -> 46339 | O22: PL | P22: GRC; BSE | Q22: Risk management | R22: Approved risk appetite statement | S22: NIST CSF 2.0 GV.RM; ISO 27001 6.1 | T22: Not started | V22: =";"&SUBSTITUTE(P22," ","")&";" -> ;GRC;BSE;
A23: PM-07 | B23: P1 Mobilize | C23: PM | D23: RACI, RAID log, interim exception log and operating rhythm | E23: RACI; weekly status; RAID log; interim exception log; change calendar incl. W9-W10 freeze | F23: 2 | G23: 1 | H23: =F23+G23-1 -> 2 | I23: PM-02 | J23: =IF(I23="","",SUMPRODUCT(MAX(ISNUMBER(SEARCH(","&$A$7:$A$156&",",","&SUBSTITUTE(I23," ","")&","))*$H$7:$H$156))) -> 1 | K23: =IF(I23="","OK",IF(F23>J23,"OK","VIOLATION")) -> OK | L23: =IF(H23<=26,"OK","LATE") -> OK | M23: =Overview!$B$4+7*(F23-1) -> 46328 | N23: =Overview!$B$4+7*(H23-1)+4 -> 46332 | O23: PMC | P23: PL | Q23: PMO | R23: RACI + RAID + interim exception log | S23: ISO 27001 5.3 | T23: Not started | V23: =";"&SUBSTITUTE(P23," ","")&";" -> ;PL;
A24: PM-05 | B24: P1 Mobilize | C24: PM | D24: Threat model (cloud, identity, on-chain, supply chain, insider) | E24: Signer-UI compromise (Bybit), durable-nonce pre-signing (Drift), EIP-7702 delegation phishing, DPRK IT workers, domain/front-end hijack, CI/CD poisoning, ransomware, B2C account takeover, helpdesk reset fraud | F24: 3 | G24: 3 | H24: =F24+G24-1 -> 5 | I24: PM-02 | J24: =IF(I24="","",SUMPRODUCT(MAX(ISNUMBER(SEARCH(","&$A$7:$A$156&",",","&SUBSTITUTE(I24," ","")&","))*$H$7:$H$156))) -> 1 | K24: =IF(I24="","OK",IF(F24>J24,"OK","VIOLATION")) -> OK | L24: =IF(H24<=26,"OK","LATE") -> OK | M24: =Overview!$B$4+7*(F24-1) -> 46335 | N24: =Overview!$B$4+7*(H24-1)+4 -> 46353 | O24: PL | P24: CSE; ISE; BSE | Q24: Threat modelling | R24: Threat model + prioritised scenarios | S24: MITRE ATT&CK; OWASP SC Top 10 2026; SEAL Frameworks | T24: Not started | V24: =";"&SUBSTITUTE(P24," ","")&";" -> ;CSE;ISE;BSE;
A25: PM-06 | B25: P1 Mobilize | C25: PM | D25: Baseline gap assessment (CSF 2.0 current/target profile) | E25: CSF 2.0 profiles; CIS Controls v8.1 IG1/IG2; Security Hub CSPM baseline; Inspector; identity and on-chain gaps | F25: 3 | G25: 3 | H25: =F25+G25-1 -> 5 | I25: PM-02, MR-01 | J25: =IF(I25="","",SUMPRODUCT(MAX(ISNUMBER(SEARCH(","&$A$7:$A$156&",",","&SUBSTITUTE(I25," ","")&","))*$H$7:$H$156))) -> 1 | K25: =IF(I25="","OK",IF(F25>J25,"OK","VIOLATION")) -> OK | L25: =IF(H25<=26,"OK","LATE") -> OK | M25: =Overview!$B$4+7*(F25-1) -> 46335 | N25: =Overview!$B$4+7*(H25-1)+4 -> 46353 | O25: GRC | Q25: Assessment | R25: Gap assessment + baseline KPIs | S25: NIST CSF 2.0; CIS Controls v8.1 | T25: Not started | V25: =";"&SUBSTITUTE(P25," ","")&";" -> ;;
A26: GC-02 | B26: P1 Mobilize | C26: GC | D26: Governance operating model and forum ToRs | E26: Steering, ARB (fortnightly), CUKC (fortnightly + ad hoc, internal chair), CAB (weekly), IR forum, independent assurance; three lines; decision rights | F26: 3 | G26: 2 | H26: =F26+G26-1 -> 4 | I26: PM-02, PM-07 | J26: =IF(I26="","",SUMPRODUCT(MAX(ISNUMBER(SEARCH(","&$A$7:$A$156&",",","&SUBSTITUTE(I26," ","")&","))*$H$7:$H$156))) -> 2 | K26: =IF(I26="","OK",IF(F26>J26,"OK","VIOLATION")) -> OK | L26: =IF(H26<=26,"OK","LATE") -> OK | M26: =Overview!$B$4+7*(F26-1) -> 46335 | N26: =Overview!$B$4+7*(H26-1)+4 -> 46346 | O26: PL | P26: GRC | Q26: Governance design | R26: Governance model + ToRs | S26: NIST CSF 2.0 GV.RR; ISO 27001 5.1-5.3; IIA Three Lines | T26: Not started | V26: =";"&SUBSTITUTE(P26," ","")&";" -> ;GRC;
A27: MR-02 | B27: P1 Mobilize | C27: MR | D27: MDR selection and contract (D-03) | E27: Falcon Complete Next-Gen MDR vs Splunk-integrated MDR; named 24/7 owner per alert source (incl. Splunk notables); acknowledge/contain SLAs; authority to disable accounts/isolate hosts; escalation to CUKC | F27: 3 | G27: 2 | H27: =F27+G27-1 -> 4 | I27: PM-03 | J27: =IF(I27="","",SUMPRODUCT(MAX(ISNUMBER(SEARCH(","&$A$7:$A$156&",",","&SUBSTITUTE(I27," ","")&","))*$H$7:$H$156))) -> 2 | K27: =IF(I27="","OK",IF(F27>J27,"OK","VIOLATION")) -> OK | L27: =IF(H27<=26,"OK","LATE") -> OK | M27: =Overview!$B$4+7*(F27-1) -> 46335 | N27: =Overview!$B$4+7*(H27-1)+4 -> 46346 | O27: ISE | P27: PL | Q27: SOC operations, vendor evaluation | R27: Signed MDR contract (D-03) | S27: NIST SP 800-61r3; CSF 2.0 DE/RS | T27: Not started | V27: =";"&SUBSTITUTE(P27," ","")&";" -> ;PL;
A28: MR-23 | B28: P1 Mobilize | C28: MR | D28: Security services cost review before trials end (D-15) | E28: Security Hub per-resource pricing, GuardDuty/Inspector, EKS extended support, Splunk ingest sizing; plan selection | F28: 3 | G28: 2 | H28: =F28+G28-1 -> 4 | I28: MR-01 | J28: =IF(I28="","",SUMPRODUCT(MAX(ISNUMBER(SEARCH(","&$A$7:$A$156&",",","&SUBSTITUTE(I28," ","")&","))*$H$7:$H$156))) -> 1 | K28: =IF(I28="","OK",IF(F28>J28,"OK","VIOLATION")) -> OK | L28: =IF(H28<=26,"OK","LATE") -> OK | M28: =Overview!$B$4+7*(F28-1) -> 46335 | N28: =Overview!$B$4+7*(H28-1)+4 -> 46346 | O28: PMC | Q28: Cost analysis | R28: D-15 cost decision | S28: Security Hub pricing; EKS pricing | T28: Not started | V28: =";"&SUBSTITUTE(P28," ","")&";" -> ;;
A29: GC-03 | B29: P1 Mobilize | C29: GC | D29: GRC platform selection (D-04) | E29: Vanta/Drata/Secureframe: AWS, Entra (licence/role needs), GitHub, HRIS integrations; pricing | F29: 3 | G29: 2 | H29: =F29+G29-1 -> 4 | I29: PM-03 | J29: =IF(I29="","",SUMPRODUCT(MAX(ISNUMBER(SEARCH(","&$A$7:$A$156&",",","&SUBSTITUTE(I29," ","")&","))*$H$7:$H$156))) -> 2 | K29: =IF(I29="","OK",IF(F29>J29,"OK","VIOLATION")) -> OK | L29: =IF(H29<=26,"OK","LATE") -> OK | M29: =Overview!$B$4+7*(F29-1) -> 46335 | N29: =Overview!$B$4+7*(H29-1)+4 -> 46346 | O29: GRCC | P29: GRC | Q29: GRC tooling | R29: GRC platform decision (D-04) | S29: AICPA TSC 2017 (2022 PoF) | T29: Not started | V29: =";"&SUBSTITUTE(P29," ","")&";" -> ;GRC;
A30: GC-18 | B30: P1 Mobilize | C30: GC | D30: Business impact analysis (BIA) | E30: Critical services, dependencies (custody, staking, RPC, Splunk), RTO/RPO, tolerable on-chain downtime | F30: 4 | G30: 2 | H30: =F30+G30-1 -> 5 | I30: PM-02 | J30: =IF(I30="","",SUMPRODUCT(MAX(ISNUMBER(SEARCH(","&$A$7:$A$156&",",","&SUBSTITUTE(I30," ","")&","))*$H$7:$H$156))) -> 1 | K30: =IF(I30="","OK",IF(F30>J30,"OK","VIOLATION")) -> OK | L30: =IF(H30<=26,"OK","LATE") -> OK | M30: =Overview!$B$4+7*(F30-1) -> 46342 | N30: =Overview!$B$4+7*(H30-1)+4 -> 46353 | O30: GRC | P30: PL; CSE; BSE | Q30: BC planning | R30: Approved BIA | S30: NIST CSF 2.0 ID.AM/RC; ISO 27001 A.5.30 | T30: Not started | V30: =";"&SUBSTITUTE(P30," ","")&";" -> ;PL;CSE;BSE;
A31: GC-20 | B31: P1 Mobilize | C31: GC | D31: Board oversight of cyber risk | E31: Board/Audit Committee terms; quarterly cyber report format; first briefing | F31: 5 | G31: 2 | H31: =F31+G31-1 -> 6 | I31: PM-02 | J31: =IF(I31="","",SUMPRODUCT(MAX(ISNUMBER(SEARCH(","&$A$7:$A$156&",",","&SUBSTITUTE(I31," ","")&","))*$H$7:$H$156))) -> 1 | K31: =IF(I31="","OK",IF(F31>J31,"OK","VIOLATION")) -> OK | L31: =IF(H31<=26,"OK","LATE") -> OK | M31: =Overview!$B$4+7*(F31-1) -> 46349 | N31: =Overview!$B$4+7*(H31-1)+4 -> 46360 | O31: PL | P31: GRC | Q31: Board reporting | R31: Board reporting cadence + first pack | S31: SOC 2 CC1.2; NIST CSF 2.0 GV.OV | T31: Not started | V31: =";"&SUBSTITUTE(P31," ","")&";" -> ;GRC;
A32: GC-08 | B32: P1 Mobilize | C32: GC | D32: Change management / CAB live | E32: CAB ToR; change types; emergency CAB; freeze rules; link to CUKC for on-chain changes | F32: 5 | G32: 2 | H32: =F32+G32-1 -> 6 | I32: GC-02 | J32: =IF(I32="","",SUMPRODUCT(MAX(ISNUMBER(SEARCH(","&$A$7:$A$156&",",","&SUBSTITUTE(I32," ","")&","))*$H$7:$H$156))) -> 4 | K32: =IF(I32="","OK",IF(F32>J32,"OK","VIOLATION")) -> OK | L32: =IF(H32<=26,"OK","LATE") -> OK | M32: =Overview!$B$4+7*(F32-1) -> 46349 | N32: =Overview!$B$4+7*(H32-1)+4 -> 46360 | O32: PMC | P32: PL | Q32: ITSM | R32: CAB procedure live | S32: SOC 2 CC8.1; ISO 27001 A.8.32 | T32: Not started | V32: =";"&SUBSTITUTE(P32," ","")&";" -> ;PL;
A33: PM-08 | B33: P1 Mobilize | C33: PM | D33: Gate 1 - Mobilize exit (Steering, W6) | E33: Criteria in Overview: charter + budget; partners booked; D-01 signed; risk appetite; threat model + gap baseline; 1.31 clusters gone; agentless detection 100% accounts; interim 24/7 live; break-glass tested; interim multisig hardening done | F33: 6 | G33: 1 | H33: =F33+G33-1 -> 6 | I33: PM-02A, PM-03, PM-04, PM-05, PM-06, GC-01, GC-02, HD-02, MR-01, MR-00, ID-01, BC-22 | J33: =IF(I33="","",SUMPRODUCT(MAX(ISNUMBER(SEARCH(","&$A$7:$A$156&",",","&SUBSTITUTE(I33," ","")&","))*$H$7:$H$156))) -> 5 | K33: =IF(I33="","OK",IF(F33>J33,"OK","VIOLATION")) -> OK | L33: =IF(H33<=26,"OK","LATE") -> OK | M33: =Overview!$B$4+7*(F33-1) -> 46356 | N33: =Overview!$B$4+7*(H33-1)+4 -> 46360 | O33: PL | P33: PMC | Q33: Governance | R33: Signed Gate 1 minute | S33: Program governance | T33: Not started | V33: =";"&SUBSTITUTE(P33," ","")&";" -> ;PMC;
A34: HD-04 | B34: P2 Assess & Design | C34: HD | D34: Org guardrail design: SCPs, RCPs, declarative policies, Control Tower controls | E34: SCP: protect CloudTrail/GuardDuty/Config, allow guardduty:SendSecurityTelemetry, region allowlist, block Identity Store writes; RCP data perimeter; declarative: IMDSv2 (hop limit set per launch template: EKS 1, ECS bridge 2), snapshot/AMI BPA, VPC BPA with exclusions, serial console, allowed images (audit mode first); EBS default encryption via Control Tower/Config + automation (not a declarative attribute) | F34: 3 | G34: 3 | H34: =F34+G34-1 -> 5 | I34: HD-01, PM-02 | J34: =IF(I34="","",SUMPRODUCT(MAX(ISNUMBER(SEARCH(","&$A$7:$A$156&",",","&SUBSTITUTE(I34," ","")&","))*$H$7:$H$156))) -> 1 | K34: =IF(I34="","OK",IF(F34>J34,"OK","VIOLATION")) -> OK | L34: =IF(H34<=26,"OK","LATE") -> OK | M34: =Overview!$B$4+7*(F34-1) -> 46335 | N34: =Overview!$B$4+7*(H34-1)+4 -> 46353 | O34: CSE | P34: KHE | Q34: AWS Organizations policy design | R34: Guardrail design (ARB pack) | S34: SH EC2.7/EC2.8/EC2.170/S3.1; CIS AWS v5.0.0; declarative policy docs | T34: Not started | V34: =";"&SUBSTITUTE(P34," ","")&";" -> ;KHE;
A35: HD-05 | B35: P2 Assess & Design | C35: HD | D35: Hardened image standard and EKS node OS decision (D-05) | E35: CIS AL2023 v1.0.0 L1; AL2023 vs Bottlerocket vs EKS Auto Mode for nodes; CIS EKS v2.0.0 / Auto Mode v1.0.0; Inspector CIS is x86_64-oriented and excludes Bottlerocket -> alternate evidence; CrowdStrike AL2023/Bottlerocket support in writing | F35: 2 | G35: 3 | H35: =F35+G35-1 -> 4 | I35: HD-01 | J35: =IF(I35="","",SUMPRODUCT(MAX(ISNUMBER(SEARCH(","&$A$7:$A$156&",",","&SUBSTITUTE(I35," ","")&","))*$H$7:$H$156))) -> 1 | K35: =IF(I35="","OK",IF(F35>J35,"OK","VIOLATION")) -> OK | L35: =IF(H35<=26,"OK","LATE") -> OK | M35: =Overview!$B$4+7*(F35-1) -> 46328 | N35: =Overview!$B$4+7*(H35-1)+4 -> 46346 | O35: KHE | P35: CSE | Q35: CIS benchmarks | R35: Image standard + D-05 | S35: CIS AL2023 v1.0.0; CIS Bottlerocket v1.0.0; CIS EKS v2.0.0 | T35: Not started | V35: =";"&SUBSTITUTE(P35," ","")&";" -> ;CSE;
A36: HD-24 | B36: P2 Assess & Design | C36: HD | D36: EKS upgrade-readiness matrix per version hop | E36: Per hop 1.32->1.36: add-ons, Karpenter/CA, deprecated APIs, cgroup v2, containerd 2.x, ingress controller replacement; rollback limits | F36: 2 | G36: 3 | H36: =F36+G36-1 -> 4 | I36: HD-01 | J36: =IF(I36="","",SUMPRODUCT(MAX(ISNUMBER(SEARCH(","&$A$7:$A$156&",",","&SUBSTITUTE(I36," ","")&","))*$H$7:$H$156))) -> 1 | K36: =IF(I36="","OK",IF(F36>J36,"OK","VIOLATION")) -> OK | L36: =IF(H36<=26,"OK","LATE") -> OK | M36: =Overview!$B$4+7*(F36-1) -> 46328 | N36: =Overview!$B$4+7*(H36-1)+4 -> 46346 | O36: KHE | P36: ENG | Q36: EKS | R36: Upgrade-readiness matrix | S36: EKS kubernetes-versions & upgrade docs | T36: Not started | V36: =";"&SUBSTITUTE(P36," ","")&";" -> ;ENG;
A37: HD-06 | B37: P2 Assess & Design | C37: HD | D37: SSM enrolment fleet-wide (prerequisite for runtime agents, Patch Manager, Inspector CIS) | E37: Instance profiles with AmazonSSMManagedInstanceCore + AmazonInspector2ManagedCisPolicy as primary path; DHMC where no profile (needs IMDSv2); per-instance IMDSv2 conversion where compatible; VPC endpoints | F37: 2 | G37: 5 | H37: =F37+G37-1 -> 6 | I37: HD-01 | J37: =IF(I37="","",SUMPRODUCT(MAX(ISNUMBER(SEARCH(","&$A$7:$A$156&",",","&SUBSTITUTE(I37," ","")&","))*$H$7:$H$156))) -> 1 | K37: =IF(I37="","OK",IF(F37>J37,"OK","VIOLATION")) -> OK | L37: =IF(H37<=26,"OK","LATE") -> OK | M37: =Overview!$B$4+7*(F37-1) -> 46328 | N37: =Overview!$B$4+7*(H37-1)+4 -> 46360 | O37: KHE | P37: ENG | Q37: Systems Manager | R37: >=95% EC2 managed by SSM | S37: SH SSM.1; Inspector CIS prerequisites | T37: Not started | V37: =";"&SUBSTITUTE(P37," ","")&";" -> ;ENG;
A38: HD-22 | B38: P2 Assess & Design | C38: HD | D38: Immutable log archive | E38: Log Archive account; S3 Object Lock; CloudTrail data events (critical S3/KMS/Secrets); log-file validation; KMS encryption; retention by log class | F38: 3 | G38: 3 | H38: =F38+G38-1 -> 5 | I38: MR-01 | J38: =IF(I38="","",SUMPRODUCT(MAX(ISNUMBER(SEARCH(","&$A$7:$A$156&",",","&SUBSTITUTE(I38," ","")&","))*$H$7:$H$156))) -> 1 | K38: =IF(I38="","OK",IF(F38>J38,"OK","VIOLATION")) -> OK | L38: =IF(H38<=26,"OK","LATE") -> OK | M38: =Overview!$B$4+7*(F38-1) -> 46335 | N38: =Overview!$B$4+7*(H38-1)+4 -> 46353 | O38: CPE | Q38: AWS logging | R38: Immutable log archive | S38: SH CloudTrail.2/.4, S3.5; CIS AWS v5.0.0 | T38: Not started | V38: =";"&SUBSTITUTE(P38," ","")&";" -> ;;
A39: HD-02 | B39: P1 Mobilize | C39: HD | D39: EKS end-of-support remediation (1.31 before 26 Nov; 1.34 per D-10 before 2 Dec) | E39: Controlled 1.31->1.32 upgrade (last AL2-AMI version); add-on compatibility; 1.34 clusters upgraded to 1.35 or upgradePolicy set to EXTENDED per D-10; rollback plan | F39: 2 | G39: 4 | H39: =F39+G39-1 -> 5 | I39: HD-01 | J39: =IF(I39="","",SUMPRODUCT(MAX(ISNUMBER(SEARCH(","&$A$7:$A$156&",",","&SUBSTITUTE(I39," ","")&","))*$H$7:$H$156))) -> 1 | K39: =IF(I39="","OK",IF(F39>J39,"OK","VIOLATION")) -> OK | L39: =IF(H39<=26,"OK","LATE") -> OK | M39: =Overview!$B$4+7*(F39-1) -> 46328 | N39: =Overview!$B$4+7*(H39-1)+4 -> 46353 | O39: CSE | P39: KHE; ENG | Q39: EKS upgrades | R39: No 1.31 clusters; 1.34 handled per D-10 | S39: EKS kubernetes-versions page; SH EKS.2/EKS.9 | T39: Not started | U39: Owner CSE - 1.31 upgraded by Fri 20 Nov 2026; 1.34 by Fri 27 Nov 2026 | V39: =";"&SUBSTITUTE(P39," ","")&";" -> ;KHE;ENG;
A40: HD-03 | B40: P1 Mobilize | C40: HD | D40: AL2 containment and migration backlog | E40: Tag/isolate remaining AL2; CrowdStrike prevention policy; restrict SGs; owners/dates per workload; time-boxed exceptions | F40: 2 | G40: 2 | H40: =F40+G40-1 -> 3 | I40: HD-01 | J40: =IF(I40="","",SUMPRODUCT(MAX(ISNUMBER(SEARCH(","&$A$7:$A$156&",",","&SUBSTITUTE(I40," ","")&","))*$H$7:$H$156))) -> 1 | K40: =IF(I40="","OK",IF(F40>J40,"OK","VIOLATION")) -> OK | L40: =IF(H40<=26,"OK","LATE") -> OK | M40: =Overview!$B$4+7*(F40-1) -> 46328 | N40: =Overview!$B$4+7*(H40-1)+4 -> 46339 | O40: CSE | P40: ENG | Q40: Linux ops, CrowdStrike | R40: AL2 backlog + exceptions | S40: AL2 FAQ; CIS Controls v8.1 2.2/7 | T40: Not started | U40: Owner CSE - Fri 6 Nov 2026 | V40: =";"&SUBSTITUTE(P40," ","")&";" -> ;ENG;
A41: HD-07 | B41: P2 Assess & Design | C41: HD | D41: Network baseline design | E41: VPC segmentation, TGW route domains, Network Firewall egress allowlist, NAT, VPC endpoints, WAF managed rules, SG standards, flow logs, Route 53 Resolver DNS Firewall | F41: 6 | G41: 2 | H41: =F41+G41-1 -> 7 | I41: PM-05 | J41: =IF(I41="","",SUMPRODUCT(MAX(ISNUMBER(SEARCH(","&$A$7:$A$156&",",","&SUBSTITUTE(I41," ","")&","))*$H$7:$H$156))) -> 5 | K41: =IF(I41="","OK",IF(F41>J41,"OK","VIOLATION")) -> OK | L41: =IF(H41<=26,"OK","LATE") -> OK | M41: =Overview!$B$4+7*(F41-1) -> 46356 | N41: =Overview!$B$4+7*(H41-1)+4 -> 46367 | O41: KHE | P41: CSE | Q41: AWS networking | R41: Network design (ARB pack) | S41: SH EC2.2/EC2.6/EC2.9/ELB.16/WAF.10/WAF.11/NetworkFirewall.2/.4/.5; CIS Controls 12/13 | T41: Not started | V41: =";"&SUBSTITUTE(P41," ","")&";" -> ;CSE;
...

Sheet Roles & Skills
A1: Roles & Skills - live counts from Project Plan; capacity rule: leads <= cap and weighted load (lead 1 + support 0.25) <= 4 x FTE
A2: Partners and business contributors carry 0 program FTE. ENG supports only. Weekly load matrix below.
A4: Role ID | B4: Role | C4: Type | D4: Sourcing | E4: Avg FTE (in window) | F4: Window first wk | G4: Window last wk | H4: Core skills | I4: Certifications / evidence | J4: Lead cap (concurrent) | K4: Tasks led | L4: Tasks supported | M4: First wk led | N4: Last wk led | O4: Peak concurrent leads | P4: Load status | Q4: Peak weighted load | R4: FTE-weeks
A5: PL | B5: Security Program Lead | C5: Internal | D5: Internal (existing) | E5: 1 | F5: 0 | G5: 26 | H5: Program/portfolio management, risk, executive and board comms, budget, vendor management | I5: CISSP or CISM; PMP/PRINCE2 or equivalent delivery record | J5: 3 | K5: =COUNTIF('Project Plan'!$O$7:$O$156,A5) -> 18 | L5: =COUNTIF('Project Plan'!$V$7:$V$156,"*;"&A5&";*") -> 13 | M5: =IF(K5=0,"-",_xlfn.MINIFS('Project Plan'!$F$7:$F$156,'Project Plan'!$O$7:$O$156,A5)) -> 0 | N5: =IF(K5=0,"-",_xlfn.MAXIFS('Project Plan'!$H$7:$H$156,'Project Plan'!$O$7:$O$156,A5)) -> 26 | O5: =MAX(C36:AC36) -> 3 | P5: =IF(OR(O5>J5,AND(E5>0,Q5>4*E5+0.0001)),"OVER","OK") -> OK | Q5: =MAX(C61:AC61) -> 3.75 | R5: =E5*(G5-F5+1) -> 27
A6: CSE | B6: Cloud & Platform Security Engineer | C6: Internal | D6: Internal (existing) | E6: 1 | F6: 0 | G6: 26 | H6: AWS Organizations/Control Tower, SCP/RCP, EKS upgrades, VPC/TGW/Network Firewall, IaC | I6: AWS Certified Security - Specialty; CKS | J6: 3 | K6: =COUNTIF('Project Plan'!$O$7:$O$156,A6) -> 16 | L6: =COUNTIF('Project Plan'!$V$7:$V$156,"*;"&A6&";*") -> 21 | M6: =IF(K6=0,"-",_xlfn.MINIFS('Project Plan'!$F$7:$F$156,'Project Plan'!$O$7:$O$156,A6)) -> 0 | N6: =IF(K6=0,"-",_xlfn.MAXIFS('Project Plan'!$H$7:$H$156,'Project Plan'!$O$7:$O$156,A6)) -> 22 | O6: =MAX(C37:AC37) -> 3 | P6: =IF(OR(O6>J6,AND(E6>0,Q6>4*E6+0.0001)),"OVER","OK") -> OK | Q6: =MAX(C62:AC62) -> 4 | R6: =E6*(G6-F6+1) -> 27
A7: ISE | B7: Identity & Security Operations Engineer (IR Lead) | C7: Internal | D7: Internal (existing) | E7: 1 | F7: 0 | G7: 26 | H7: Entra ID CA/PIM, IAM Identity Center, Splunk ES, incident handling | I7: SC-300; SC-200 or Splunk ES Certified Admin; GCIH | J7: 3 | K7: =COUNTIF('Project Plan'!$O$7:$O$156,A7) -> 15 | L7: =COUNTIF('Project Plan'!$V$7:$V$156,"*;"&A7&";*") -> 34 | M7: =IF(K7=0,"-",_xlfn.MINIFS('Project Plan'!$F$7:$F$156,'Project Plan'!$O$7:$O$156,A7)) -> 0 | N7: =IF(K7=0,"-",_xlfn.MAXIFS('Project Plan'!$H$7:$H$156,'Project Plan'!$O$7:$O$156,A7)) -> 20 | O7: =MAX(C38:AC38) -> 3 | P7: =IF(OR(O7>J7,AND(E7>0,Q7>4*E7+0.0001)),"OVER","OK") -> OK | Q7: =MAX(C63:AC63) -> 4 | R7: =E7*(G7-F7+1) -> 27
A8: GRC | B8: GRC & Risk Lead (2nd line) | C8: Internal | D8: Internal (existing) | E8: 1 | F8: 0 | G8: 26 | H8: SOC 2, NIST CSF 2.0, ISO 27001, TPRM, risk, audit liaison | I8: CISA and/or CRISC; ISO 27001 Lead Implementer | J8: 3 | K8: =COUNTIF('Project Plan'!$O$7:$O$156,A8) -> 13 | L8: =COUNTIF('Project Plan'!$V$7:$V$156,"*;"&A8&";*") -> 21 | M8: =IF(K8=0,"-",_xlfn.MINIFS('Project Plan'!$F$7:$F$156,'Project Plan'!$O$7:$O$156,A8)) -> 0 | N8: =IF(K8=0,"-",_xlfn.MAXIFS('Project Plan'!$H$7:$H$156,'Project Plan'!$O$7:$O$156,A8)) -> 21 | O8: =MAX(C39:AC39) -> 3 | P8: =IF(OR(O8>J8,AND(E8>0,Q8>4*E8+0.0001)),"OVER","OK") -> OK | Q8: =MAX(C64:AC64) -> 4 | R8: =E8*(G8-F8+1) -> 27
A9: BSE | B9: Blockchain Security Engineer | C9: Internal | D9: Internal (existing) | E9: 1 | F9: 0 | G9: 26 | H9: Solidity and Rust/Anchor review, Safe/Squads operations, MPC custody, staking mechanics, on-chain IR | I9: Public audit/contest track record (audit reports, contest placings) | J9: 3 | K9: =COUNTIF('Project Plan'!$O$7:$O$156,A9) -> 20 | L9: =COUNTIF('Project Plan'!$V$7:$V$156,"*;"&A9&";*") -> 25 | M9: =IF(K9=0,"-",_xlfn.MINIFS('Project Plan'!$F$7:$F$156,'Project Plan'!$O$7:$O$156,A9)) -> 0 | N9: =IF(K9=0,"-",_xlfn.MAXIFS('Project Plan'!$H$7:$H$156,'Project Plan'!$O$7:$O$156,A9)) -> 24 | O9: =MAX(C40:AC40) -> 3 | P9: =IF(OR(O9>J9,AND(E9>0,Q9>4*E9+0.0001)),"OVER","OK") -> OK | Q9: =MAX(C65:AC65) -> 4 | R9: =E9*(G9-F9+1) -> 27
A10: KHE | B10: Contract Cloud/K8s Hardening Engineer | C10: Contractor | D10: Contractor (T&M) | E10: 1 | F10: 2 | G10: 22 | H10: CIS benchmarks, SSM, Image Builder, AL2023/Bottlerocket, EKS upgrades, Kubernetes admission policy | I10: CKS; AWS Security Specialty; CIS-CAT experience | J10: 3 | K10: =COUNTIF('Project Plan'!$O$7:$O$156,A10) -> 13 | L10: =COUNTIF('Project Plan'!$V$7:$V$156,"*;"&A10&";*") -> 9 | M10: =IF(K10=0,"-",_xlfn.MINIFS('Project Plan'!$F$7:$F$156,'Project Plan'!$O$7:$O$156,A10)) -> 2 | N10: =IF(K10=0,"-",_xlfn.MAXIFS('Project Plan'!$H$7:$H$156,'Project Plan'!$O$7:$O$156,A10)) -> 19 | O10: =MAX(C41:AC41) -> 3 | P10: =IF(OR(O10>J10,AND(E10>0,Q10>4*E10+0.0001)),"OVER","OK") -> OK | Q10: =MAX(C66:AC66) -> 3.75 | R10: =E10*(G10-F10+1) -> 21
A11: CPE | B11: Contract Cloud Platform Security Engineer | C11: Contractor | D11: Contractor (T&M) | E11: 1 | F11: 3 | G11: 20 | H11: S3 Object Lock/log archive, AWS Backup/Aurora, KMS/Secrets Manager, EKS node groups, CloudFront/DNS | I11: AWS Security Specialty or SA Professional | J11: 3 | K11: =COUNTIF('Project Plan'!$O$7:$O$156,A11) -> 9 | L11: =COUNTIF('Project Plan'!$V$7:$V$156,"*;"&A11&";*") -> 0 | M11: =IF(K11=0,"-",_xlfn.MINIFS('Project Plan'!$F$7:$F$156,'Project Plan'!$O$7:$O$156,A11)) -> 3 | N11: =IF(K11=0,"-",_xlfn.MAXIFS('Project Plan'!$H$7:$H$156,'Project Plan'!$O$7:$O$156,A11)) -> 17 | O11: =MAX(C42:AC42) -> 3 | P11: =IF(OR(O11>J11,AND(E11>0,Q11>4*E11+0.0001)),"OVER","OK") -> OK | Q11: =MAX(C67:AC67) -> 3 | R11: =E11*(G11-F11+1) -> 18
A12: DET | B12: Contract Detection Engineer (Splunk) | C12: Contractor | D12: Contractor (T&M) | E12: 1 | F12: 3 | G12: 24 | H12: SPL, Splunk ES 8 detections, contentctl detection-as-code, Splunk SOAR (Python 3.13) | I12: Splunk Certified Cybersecurity Defense Engineer or ES Admin; GCDA/GCIA | J12: 3 | K12: =COUNTIF('Project Plan'!$O$7:$O$156,A12) -> 9 | L12: =COUNTIF('Project Plan'!$V$7:$V$156,"*;"&A12&";*") -> 4 | M12: =IF(K12=0,"-",_xlfn.MINIFS('Project Plan'!$F$7:$F$156,'Project Plan'!$O$7:$O$156,A12)) -> 6 | N12: =IF(K12=0,"-",_xlfn.MAXIFS('Project Plan'!$H$7:$H$156,'Project Plan'!$O$7:$O$156,A12)) -> 18 | O12: =MAX(C43:AC43) -> 3 | P12: =IF(OR(O12>J12,AND(E12>0,Q12>4*E12+0.0001)),"OVER","OK") -> OK | Q12: =MAX(C68:AC68) -> 3 | R12: =E12*(G12-F12+1) -> 22
A13: IDC | B13: Contract Identity Specialist (Entra/B2C) | C13: Contractor | D13: Contractor (T&M) | E13: 0.5 | F13: 3 | G13: 18 | H13: Entra CA/PIM/auth strengths/ID Protection, Azure AD B2C custom policies (IEF), External ID | I13: SC-300; delivered B2C custom-policy projects | J13: 2 | K13: =COUNTIF('Project Plan'!$O$7:$O$156,A13) -> 9 | L13: =COUNTIF('Project Plan'!$V$7:$V$156,"*;"&A13&";*") -> 0 | M13: =IF(K13=0,"-",_xlfn.MINIFS('Project Plan'!$F$7:$F$156,'Project Plan'!$O$7:$O$156,A13)) -> 3 | N13: =IF(K13=0,"-",_xlfn.MAXIFS('Project Plan'!$H$7:$H$156,'Project Plan'!$O$7:$O$156,A13)) -> 18 | O13: =MAX(C44:AC44) -> 2 | P13: =IF(OR(O13>J13,AND(E13>0,Q13>4*E13+0.0001)),"OVER","OK") -> OK | Q13: =MAX(C69:AC69) -> 2 | R13: =E13*(G13-F13+1) -> 8
A14: CSO | B14: Contract Custody, Staking & Sanctions Specialist | C14: Contractor | D14: Contractor (T&M) | E14: 1 | F14: 3 | G14: 22 | H14: MPC custody policy engines, CCSS v9, Ethereum/Solana staking, OFAC wallet screening | I14: CCSS auditor (CCSSA) or equivalent custody assessment record | J14: 3 | K14: =COUNTIF('Project Plan'!$O$7:$O$156,A14) -> 6 | L14: =COUNTIF('Project Plan'!$V$7:$V$156,"*;"&A14&";*") -> 6 | M14: =IF(K14=0,"-",_xlfn.MINIFS('Project Plan'!$F$7:$F$156,'Project Plan'!$O$7:$O$156,A14)) -> 5 | N14: =IF(K14=0,"-",_xlfn.MAXIFS('Project Plan'!$H$7:$H$156,'Project Plan'!$O$7:$O$156,A14)) -> 19 | O14: =MAX(C45:AC45) -> 3 | P14: =IF(OR(O14>J14,AND(E14>0,Q14>4*E14+0.0001)),"OVER","OK") -> OK | Q14: =MAX(C70:AC70) -> 3.25 | R14: =E14*(G14-F14+1) -> 20
A15: BSC | B15: Contract Smart-Contract Security Engineer | C15: Contractor | D15: Contractor (T&M) | E15: 0.5 | F15: 5 | G15: 22 | H15: Foundry/Slither/Aderyn/Echidna, Anchor 1.x/Trident/solana-verify, SIWE/SIWS | I15: Public audit or contest record on EVM and Solana | J15: 2 | K15: =COUNTIF('Project Plan'!$O$7:$O$156,A15) -> 6 | L15: =COUNTIF('Project Plan'!$V$7:$V$156,"*;"&A15&";*") -> 3 | M15: =IF(K15=0,"-",_xlfn.MINIFS('Project Plan'!$F$7:$F$156,'Project Plan'!$O$7:$O$156,A15)) -> 5 | N15: =IF(K15=0,"-",_xlfn.MAXIFS('Project Plan'!$H$7:$H$156,'Project Plan'!$O$7:$O$156,A15)) -> 18 | O15: =MAX(C46:AC46) -> 2 | P15: =IF(OR(O15>J15,AND(E15>0,Q15>4*E15+0.0001)),"OVER","OK") -> OK | Q15: =MAX(C71:AC71) -> 2 | R15: =E15*(G15-F15+1) -> 9
A16: GRCC | B16: Contract SOC 2 Implementation Consultant | C16: Contractor | D16: Contractor (fixed fee) | E16: 1 | F16: 3 | G16: 24 | H16: Control matrices, policy drafting, GRC platform build, evidence design | I16: CISA; >=3 SOC 2 implementations | J16: 3 | K16: =COUNTIF('Project Plan'!$O$7:$O$156,A16) -> 5 | L16: =COUNTIF('Project Plan'!$V$7:$V$156,"*;"&A16&";*") -> 5 | M16: =IF(K16=0,"-",_xlfn.MINIFS('Project Plan'!$F$7:$F$156,'Project Plan'!$O$7:$O$156,A16)) -> 3 | N16: =IF(K16=0,"-",_xlfn.MAXIFS('Project Plan'!$H$7:$H$156,'Project Plan'!$O$7:$O$156,A16)) -> 11 | O16: =MAX(C47:AC47) -> 3 | P16: =IF(OR(O16>J16,AND(E16>0,Q16>4*E16+0.0001)),"OVER","OK") -> OK | Q16: =MAX(C72:AC72) -> 3.5 | R16: =E16*(G16-F16+1) -> 22
... A26: ENG | B26: Platform & App Engineering teams (change implementers) | C26: Internal-BAU | D26: Internal (outside program FTE) | E26: 0 | F26: 0 | G26: 26 | H26: Workload migration, CI/CD, application changes | I26: n/a - supporting only, never lead | J26: 0 | K26: =COUNTIF('Project Plan'!$O$7:$O$156,A26) -> 0 | L26: =COUNTIF('Project Plan'!$V$7:$V$156,"*;"&A26&";*") -> 34 | M26: =IF(K26=0,"-",_xlfn.MINIFS('Project Plan'!$F$7:$F$156,'Project Plan'!$O$7:$O$156,A26)) -> - | N26: =IF(K26=0,"-",_xlfn.MAXIFS('Project Plan'!$H$7:$H$156,'Project Plan'!$O$7:$O$156,A26)) -> - | O26: =MAX(C57:AC57) -> 0 | P26: =IF(OR(O26>J26,AND(E26>0,Q26>4*E26+0.0001)),"OVER","OK") -> OK | Q26: =MAX(C82:AC82) -> 2.75 | R26: =E26*(G26-F26+1) -> 0
A27: Internal program FTE (total) | E27: =SUMIFS(E5:E26,C5:C26,"Internal") -> 5 | G27: Contractor FTE-weeks | H27: =SUMIFS(R5:R26,C5:C26,"Contractor") -> 133
A28: Contractor FTE (peak concurrent week) | E28: =MAX(C32:AC32) -> 6.5 | G28: Internal FTE-weeks | H28: =SUMIFS(R5:R26,C5:C26,"Internal") -> 135
A29: Partner / firm engagements (count) | E29: =COUNTIF(C5:C26,"Partner") -> 7
A30: Internal within 3-5 FTE range? | E30: =IF(AND(E27>=3,E27<=5),"YES","NO") -> YES
C31: 0 | D31: 1 | E31: 2 | F31: 3 | G31: 4 | H31: 5 | I31: 6 | J31: 7 | K31: 8 | L31: 9 | M31: 10 | N31: 11 | O31: 12 | P31: 13 | Q31: 14 | R31: 15 | S31: 16 | T31: 17 | U31: 18 | V31: 19 | W31: 20 | X31: 21 | Y31: 22 | Z31: 23 | AA31: 24 | AB31: 25 | AC31: 26
A32: Contractor FTE by week | B32: wk -> | C32: =SUMPRODUCT((C5:C26="Contractor")*(F5:F26<=C31)*(G5:G26>=C31)*E5:E26) -> 0 | D32: =SUMPRODUCT((C5:C26="Contractor")*(F5:F26<=D31)*(G5:G26>=D31)*E5:E26) -> 0.5 | E32: =SUMPRODUCT((C5:C26="Contractor")*(F5:F26<=E31)*(G5:G26>=E31)*E5:E26) -> 1.5 | F32: =SUMPRODUCT((C5:C26="Contractor")*(F5:F26<=F31)*(G5:G26>=F31)*E5:E26) -> 6 | G32: =SUMPRODUCT((C5:C26="Contractor")*(F5:F26<=G31)*(G5:G26>=G31)*E5:E26) -> 6 | H32: =SUMPRODUCT((C5:C26="Contractor")*(F5:F26<=H31)*(G5:G26>=H31)*E5:E26) -> 6.5 | I32: =SUMPRODUCT((C5:C26="Contractor")*(F5:F26<=I31)*(G5:G26>=I31)*E5:E26) -> 6.5 | J32: =SUMPRODUCT((C5:C26="Contractor")*(F5:F26<=J31)*(G5:G26>=J31)*E5:E26) -> 6.5 | K32: =SUMPRODUCT((C5:C26="Contractor")*(F5:F26<=K31)*(G5:G26>=K31)*E5:E26) -> 6.5 | L32: =SUMPRODUCT((C5:C26="Contractor")*(F5:F26<=L31)*(G5:G26>=L31)*E5:E26) -> 6.5 | M32: =SUMPRODUCT((C5:C26="Contractor")*(F5:F26<=M31)*(G5:G26>=M31)*E5:E26) -> 6.5 | N32: =SUMPRODUCT((C5:C26="Contractor")*(F5:F26<=N31)*(G5:G26>=N31)*E5:E26) -> 6.5 | O32: =SUMPRODUCT((C5:C26="Contractor")*(F5:F26<=O31)*(G5:G26>=O31)*E5:E26) -> 6.5 | P32: =SUMPRODUCT((C5:C26="Contractor")*(F5:F26<=P31)*(G5:G26>=P31)*E5:E26) -> 6.5 | Q32: =SUMPRODUCT((C5:C26="Contractor")*(F5:F26<=Q31)*(G5:G26>=Q31)*E5:E26) -> 6.5 | R32: =SUMPRODUCT((C5:C26="Contractor")*(F5:F26<=R31)*(G5:G26>=R31)*E5:E26) -> 6.5 | S32: =SUMPRODUCT((C5:C26="Contractor")*(F5:F26<=S31)*(G5:G26>=S31)*E5:E26) -> 6.5 | T32: =SUMPRODUCT((C5:C26="Contractor")*(F5:F26<=T31)*(G5:G26>=T31)*E5:E26) -> 6.5 | U32: =SUMPRODUCT((C5:C26="Contractor")*(F5:F26<=U31)*(G5:G26>=U31)*E5:E26) -> 6.5 | V32: =SUMPRODUCT((C5:C26="Contractor")*(F5:F26<=V31)*(G5:G26>=V31)*E5:E26) -> 6 | W32: =SUMPRODUCT((C5:C26="Contractor")*(F5:F26<=W31)*(G5:G26>=W31)*E5:E26) -> 6 | X32: =SUMPRODUCT((C5:C26="Contractor")*(F5:F26<=X31)*(G5:G26>=X31)*E5:E26) -> 5 | Y32: =SUMPRODUCT((C5:C26="Contractor")*(F5:F26<=Y31)*(G5:G26>=Y31)*E5:E26) -> 5 | Z32: =SUMPRODUCT((C5:C26="Contractor")*(F5:F26<=Z31)*(G5:G26>=Z31)*E5:E26) -> 2.5 | AA32: =SUMPRODUCT((C5:C26="Contractor")*(F5:F26<=AA31)*(G5:G26>=AA31)*E5:E26) -> 2.5 | AB32: =SUMPRODUCT((C5:C26="Contractor")*(F5:F26<=AB31)*(G5:G26>=AB31)*E5:E26) -> 0.5 | AC32: =SUMPRODUCT((C5:C26="Contractor")*(F5:F26<=AC31)*(G5:G26>=AC31)*E5:E26) -> 0.5
A34: Concurrent LEAD tasks per role per week
A35: Role | B35: Cap | C35: 0 | D35: 1 | E35: 2 | F35: 3 | G35: 4 | H35: 5 | I35: 6 | J35: 7 | K35: 8 | L35: 9 | M35: 10 | N35: 11 | O35: 12 | P35: 13 | Q35: 14 | R35: 15 | S35: 16 | T35: 17 | U35: 18 | V35: 19 | W35: 20 | X35: 21 | Y35: 22 | Z35: 23 | AA35: 24 | AB35: 25 | AC35: 26
A36: =A5 -> PL | B36: =J5 -> 3 | C36: =COUNTIFS('Project Plan'!$O$7:$O$156,$A36,'Project Plan'!$F$7:$F$156,"<="&C$35,'Project Plan'!$H$7:$H$156,">="&C$35) -> 3 | D36: =COUNTIFS('Project Plan'!$O$7:$O$156,$A36,'Project Plan'!$F$7:$F$156,"<="&D$35,'Project Plan'!$H$7:$H$156,">="&D$35) -> 2 | E36: =COUNTIFS('Project Plan'!$O$7:$O$156,$A36,'Project Plan'!$F$7:$F$156,"<="&E$35,'Project Plan'!$H$7:$H$156,">="&E$35) -> 2 | F36: =COUNTIFS('Project Plan'!$O$7:$O$156,$A36,'Project Plan'!$F$7:$F$156,"<="&F$35,'Project Plan'!$H$7:$H$156,">="&F$35) -> 3 | G36: =COUNTIFS('Project Plan'!$O$7:$O$156,$A36,'Project Plan'!$F$7:$F$156,"<="&G$35,'Project Plan'!$H$7:$H$156,">="&G$35) -> 2 | H36: =COUNTIFS('Project Plan'!$O$7:$O$156,$A36,'Project Plan'!$F$7:$F$156,"<="&H$35,'Project Plan'!$H$7:$H$156,">="&H$35) -> 2 | I36: =COUNTIFS('Project Plan'!$O$7:$O$156,$A36,'Project Plan'!$F$7:$F$156,"<="&I$35,'Project Plan'!$H$7:$H$156,">="&I$35) -> 3 | J36: =COUNTIFS('Project Plan'!$O$7:$O$156,$A36,'Project Plan'!$F$7:$F$156,"<="&J$35,'Project Plan'!$H$7:$H$156,">="&J$35) -> 1 | ... AC36: =COUNTIFS('Project Plan'!$O$7:$O$156,$A36,'Project Plan'!$F$7:$F$156,"<="&AC$35,'Project Plan'!$H$7:$H$156,">="&AC$35) -> 1
A37: =A6 -> CSE | B37: =J6 -> 3 | C37: =COUNTIFS('Project Plan'!$O$7:$O$156,$A37,'Project Plan'!$F$7:$F$156,"<="&C$35,'Project Plan'!$H$7:$H$156,">="&C$35) -> 3 | D37: =COUNTIFS('Project Plan'!$O$7:$O$156,$A37,'Project Plan'!$F$7:$F$156,"<="&D$35,'Project Plan'!$H$7:$H$156,">="&D$35) -> 3 | E37: =COUNTIFS('Project Plan'!$O$7:$O$156,$A37,'Project Plan'!$F$7:$F$156,"<="&E$35,'Project Plan'!$H$7:$H$156,">="&E$35) -> 2 | F37: =COUNTIFS('Project Plan'!$O$7:$O$156,$A37,'Project Plan'!$F$7:$F$156,"<="&F$35,'Project Plan'!$H$7:$H$156,">="&F$35) -> 3 | G37: =COUNTIFS('Project Plan'!$O$7:$O$156,$A37,'Project Plan'!$F$7:$F$156,"<="&G$35,'Project Plan'!$H$7:$H$156,">="&G$35) -> 2 | H37: =COUNTIFS('Project Plan'!$O$7:$O$156,$A37,'Project Plan'!$F$7:$F$156,"<="&H$35,'Project Plan'!$H$7:$H$156,">="&H$35) -> 3 | I37: =COUNTIFS('Project Plan'!$O$7:$O$156,$A37,'Project Plan'!$F$7:$F$156,"<="&I$35,'Project Plan'!$H$7:$H$156,">="&I$35) -> 3 | J37: =COUNTIFS('Project Plan'!$O$7:$O$156,$A37,'Project Plan'!$F$7:$F$156,"<="&J$35,'Project Plan'!$H$7:$H$156,">="&J$35) -> 3 | ... AC37: =COUNTIFS('Project Plan'!$O$7:$O$156,$A37,'Project Plan'!$F$7:$F$156,"<="&AC$35,'Project Plan'!$H$7:$H$156,">="&AC$35) -> 0
A38: =A7 -> ISE | B38: =J7 -> 3 | C38: =COUNTIFS('Project Plan'!$O$7:$O$156,$A38,'Project Plan'!$F$7:$F$156,"<="&C$35,'Project Plan'!$H$7:$H$156,">="&C$35) -> 3 | D38: =COUNTIFS('Project Plan'!$O$7:$O$156,$A38,'Project Plan'!$F$7:$F$156,"<="&D$35,'Project Plan'!$H$7:$H$156,">="&D$35) -> 3 | E38: =COUNTIFS('Project Plan'!$O$7:$O$156,$A38,'Project Plan'!$F$7:$F$156,"<="&E$35,'Project Plan'!$H$7:$H$156,">="&E$35) -> 1 | F38: =COUNTIFS('Project Plan'!$O$7:$O$156,$A38,'Project Plan'!$F$7:$F$156,"<="&F$35,'Project Plan'!$H$7:$H$156,">="&F$35) -> 3 | G38: =COUNTIFS('Project Plan'!$O$7:$O$156,$A38,'Project Plan'!$F$7:$F$156,"<="&G$35,'Project Plan'!$H$7:$H$156,">="&G$35) -> 3 | H38: =COUNTIFS('Project Plan'!$O$7:$O$156,$A38,'Project Plan'!$F$7:$F$156,"<="&H$35,'Project Plan'!$H$7:$H$156,">="&H$35) -> 2 | I38: =COUNTIFS('Project Plan'!$O$7:$O$156,$A38,'Project Plan'!$F$7:$F$156,"<="&I$35,'Project Plan'!$H$7:$H$156,">="&I$35) -> 3 | J38: =COUNTIFS('Project Plan'!$O$7:$O$156,$A38,'Project Plan'!$F$7:$F$156,"<="&J$35,'Project Plan'!$H$7:$H$156,">="&J$35) -> 3 | ... AC38: =COUNTIFS('Project Plan'!$O$7:$O$156,$A38,'Project Plan'!$F$7:$F$156,"<="&AC$35,'Project Plan'!$H$7:$H$156,">="&AC$35) -> 0
A39: =A8 -> GRC | B39: =J8 -> 3 | C39: =COUNTIFS('Project Plan'!$O$7:$O$156,$A39,'Project Plan'!$F$7:$F$156,"<="&C$35,'Project Plan'!$H$7:$H$156,">="&C$35) -> 1 | D39: =COUNTIFS('Project Plan'!$O$7:$O$156,$A39,'Project Plan'!$F$7:$F$156,"<="&D$35,'Project Plan'!$H$7:$H$156,">="&D$35) -> 1 | E39: =COUNTIFS('Project Plan'!$O$7:$O$156,$A39,'Project Plan'!$F$7:$F$156,"<="&E$35,'Project Plan'!$H$7:$H$156,">="&E$35) -> 1 | F39: =COUNTIFS('Project Plan'!$O$7:$O$156,$A39,'Project Plan'!$F$7:$F$156,"<="&F$35,'Project Plan'!$H$7:$H$156,">="&F$35) -> 2 | G39: =COUNTIFS('Project Plan'!$O$7:$O$156,$A39,'Project Plan'!$F$7:$F$156,"<="&G$35,'Project Plan'!$H$7:$H$156,">="&G$35) -> 3 | H39: =COUNTIFS('Project Plan'!$O$7:$O$156,$A39,'Project Plan'!$F$7:$F$156,"<="&H$35,'Project Plan'!$H$7:$H$156,">="&H$35) -> 3 | I39: =COUNTIFS('Project Plan'!$O$7:$O$156,$A39,'Project Plan'!$F$7:$F$156,"<="&I$35,'Project Plan'!$H$7:$H$156,">="&I$35) -> 3 | J39: =COUNTIFS('Project Plan'!$O$7:$O$156,$A39,'Project Plan'!$F$7:$F$156,"<="&J$35,'Project Plan'!$H$7:$H$156,">="&J$35) -> 3 | ... AC39: =COUNTIFS('Project Plan'!$O$7:$O$156,$A39,'Project Plan'!$F$7:$F$156,"<="&AC$35,'Project Plan'!$H$7:$H$156,">="&AC$35) -> 0
A40: =A9 -> BSE | B40: =J9 -> 3 | C40: =COUNTIFS('Project Plan'!$O$7:$O$156,$A40,'Project Plan'!$F$7:$F$156,"<="&C$35,'Project Plan'!$H$7:$H$156,">="&C$35) -> 3 | D40: =COUNTIFS('Project Plan'!$O$7:$O$156,$A40,'Project Plan'!$F$7:$F$156,"<="&D$35,'Project Plan'!$H$7:$H$156,">="&D$35) -> 3 | E40: =COUNTIFS('Project Plan'!$O$7:$O$156,$A40,'Project Plan'!$F$7:$F$156,"<="&E$35,'Project Plan'!$H$7:$H$156,">="&E$35) -> 3 | F40: =COUNTIFS('Project Plan'!$O$7:$O$156,$A40,'Project Plan'!$F$7:$F$156,"<="&F$35,'Project Plan'!$H$7:$H$156,">="&F$35) -> 3 | G40: =COUNTIFS('Project Plan'!$O$7:$O$156,$A40,'Project Plan'!$F$7:$F$156,"<="&G$35,'Project Plan'!$H$7:$H$156,">="&G$35) -> 3 | H40: =COUNTIFS('Project Plan'!$O$7:$O$156,$A40,'Project Plan'!$F$7:$F$156,"<="&H$35,'Project Plan'!$H$7:$H$156,">="&H$35) -> 3 | I40: =COUNTIFS('Project Plan'!$O$7:$O$156,$A40,'Project Plan'!$F$7:$F$156,"<="&I$35,'Project Plan'!$H$7:$H$156,">="&I$35) -> 2 | J40: =COUNTIFS('Project Plan'!$O$7:$O$156,$A40,'Project Plan'!$F$7:$F$156,"<="&J$35,'Project Plan'!$H$7:$H$156,">="&J$35) -> 2 | ... AC40: =COUNTIFS('Project Plan'!$O$7:$O$156,$A40,'Project Plan'!$F$7:$F$156,"<="&AC$35,'Project Plan'!$H$7:$H$156,">="&AC$35) -> 0
A41: =A10 -> KHE | B41: =J10 -> 3 | C41: =COUNTIFS('Project Plan'!$O$7:$O$156,$A41,'Project Plan'!$F$7:$F$156,"<="&C$35,'Project Plan'!$H$7:$H$156,">="&C$35) -> 0 | D41: =COUNTIFS('Project Plan'!$O$7:$O$156,$A41,'Project Plan'!$F$7:$F$156,"<="&D$35,'Project Plan'!$H$7:$H$156,">="&D$35) -> 0 | E41: =COUNTIFS('Project Plan'!$O$7:$O$156,$A41,'Project Plan'!$F$7:$F$156,"<="&E$35,'Project Plan'!$H$7:$H$156,">="&E$35) -> 3 | F41: =COUNTIFS('Project Plan'!$O$7:$O$156,$A41,'Project Plan'!$F$7:$F$156,"<="&F$35,'Project Plan'!$H$7:$H$156,">="&F$35) -> 3 | G41: =COUNTIFS('Project Plan'!$O$7:$O$156,$A41,'Project Plan'!$F$7:$F$156,"<="&G$35,'Project Plan'!$H$7:$H$156,">="&G$35) -> 3 | H41: =COUNTIFS('Project Plan'!$O$7:$O$156,$A41,'Project Plan'!$F$7:$F$156,"<="&H$35,'Project Plan'!$H$7:$H$156,">="&H$35) -> 1 | I41: =COUNTIFS('Project Plan'!$O$7:$O$156,$A41,'Project Plan'!$F$7:$F$156,"<="&I$35,'Project Plan'!$H$7:$H$156,">="&I$35) -> 3 | J41: =COUNTIFS('Project Plan'!$O$7:$O$156,$A41,'Project Plan'!$F$7:$F$156,"<="&J$35,'Project Plan'!$H$7:$H$156,">="&J$35) -> 3 | ... AC41: =COUNTIFS('Project Plan'!$O$7:$O$156,$A41,'Project Plan'!$F$7:$F$156,"<="&AC$35,'Project Plan'!$H$7:$H$156,">="&AC$35) -> 0
A42: =A11 -> CPE | B42: =J11 -> 3 | C42: =COUNTIFS('Project Plan'!$O$7:$O$156,$A42,'Project Plan'!$F$7:$F$156,"<="&C$35,'Project Plan'!$H$7:$H$156,">="&C$35) -> 0 | D42: =COUNTIFS('Project Plan'!$O$7:$O$156,$A42,'Project Plan'!$F$7:$F$156,"<="&D$35,'Project Plan'!$H$7:$H$156,">="&D$35) -> 0 | E42: =COUNTIFS('Project Plan'!$O$7:$O$156,$A42,'Project Plan'!$F$7:$F$156,"<="&E$35,'Project Plan'!$H$7:$H$156,">="&E$35) -> 0 | F42: =COUNTIFS('Project Plan'!$O$7:$O$156,$A42,'Project Plan'!$F$7:$F$156,"<="&F$35,'Project Plan'!$H$7:$H$156,">="&F$35) -> 1 | G42: =COUNTIFS('Project Plan'!$O$7:$O$156,$A42,'Project Plan'!$F$7:$F$156,"<="&G$35,'Project Plan'!$H$7:$H$156,">="&G$35) -> 2 | H42: =COUNTIFS('Project Plan'!$O$7:$O$156,$A42,'Project Plan'!$F$7:$F$156,"<="&H$35,'Project Plan'!$H$7:$H$156,">="&H$35) -> 2 | I42: =COUNTIFS('Project Plan'!$O$7:$O$156,$A42,'Project Plan'!$F$7:$F$156,"<="&I$35,'Project Plan'!$H$7:$H$156,">="&I$35) -> 2 | J42: =COUNTIFS('Project Plan'!$O$7:$O$156,$A42,'Project Plan'!$F$7:$F$156,"<="&J$35,'Project Plan'!$H$7:$H$156,">="&J$35) -> 3 | ... AC42: =COUNTIFS('Project Plan'!$O$7:$O$156,$A42,'Project Plan'!$F$7:$F$156,"<="&AC$35,'Project Plan'!$H$7:$H$156,">="&AC$35) -> 0
A43: =A12 -> DET | B43: =J12 -> 3 | C43: =COUNTIFS('Project Plan'!$O$7:$O$156,$A43,'Project Plan'!$F$7:$F$156,"<="&C$35,'Project Plan'!$H$7:$H$156,">="&C$35) -> 0 | D43: =COUNTIFS('Project Plan'!$O$7:$O$156,$A43,'Project Plan'!$F$7:$F$156,"<="&D$35,'Project Plan'!$H$7:$H$156,">="&D$35) -> 0 | E43: =COUNTIFS('Project Plan'!$O$7:$O$156,$A43,'Project Plan'!$F$7:$F$156,"<="&E$35,'Project Plan'!$H$7:$H$156,">="&E$35) -> 0 | F43: =COUNTIFS('Project Plan'!$O$7:$O$156,$A43,'Project Plan'!$F$7:$F$156,"<="&F$35,'Project Plan'!$H$7:$H$156,">="&F$35) -> 0 | G43: =COUNTIFS('Project Plan'!$O$7:$O$156,$A43,'Project Plan'!$F$7:$F$156,"<="&G$35,'Project Plan'!$H$7:$H$156,">="&G$35) -> 0 | H43: =COUNTIFS('Project Plan'!$O$7:$O$156,$A43,'Project Plan'!$F$7:$F$156,"<="&H$35,'Project Plan'!$H$7:$H$156,">="&H$35) -> 0 | I43: =COUNTIFS('Project Plan'!$O$7:$O$156,$A43,'Project Plan'!$F$7:$F$156,"<="&I$35,'Project Plan'!$H$7:$H$156,">="&I$35) -> 1 | J43: =COUNTIFS('Project Plan'!$O$7:$O$156,$A43,'Project Plan'!$F$7:$F$156,"<="&J$35,'Project Plan'!$H$7:$H$156,">="&J$35) -> 2 | ... AC43: =COUNTIFS('Project Plan'!$O$7:$O$156,$A43,'Project Plan'!$F$7:$F$156,"<="&AC$35,'Project Plan'!$H$7:$H$156,">="&AC$35) -> 0
