Workbook

Sheet README
A1: Unified Blockchain Security Control Register
A2: Prepared 2026-10-20 · Blockchain Security Architecture (drafted with Claude) · Scope: exchanges/custodians, protocol/dApp/token teams, node/validator operators, enterprise baseline.
A4: What this is
A5: One register of 386 controls. The backbone is every normative BSSC requirement (NOS, TIS, KMS, SCS, GSP = 325 controls). 61 supplementary controls close gaps BSSC does not explicitly require, drawn from OWASP SC Top 10:2026, OWASP SCSVS, OWASP Web3 Top 15, SEAL Frameworks, CCSS v9.0, CIS Controls v8.1, DORA, MiCA and FATF.
A6: Every control is cross-referenced to all applicable frameworks (grey-blue header columns M–W). 'Applicable Frameworks' lists them in one cell for filtering.
A8: Columns
A9: Primary Source Framework / Ref ID: the framework the control was derived from. Reference Standard: citation text. Requirement Level: BSSC RFC 2119 keyword, or 'Recommended (supplementary)'.
A10: Overlap Flag / Reference (same convention as the Azure CIS register in this project): Duplicate = two source requirements ask the same party for the same thing – implement once, evidence both. Related = overlapping scope, or mirror requirements for different parties (e.g., TIS integrator check vs SCS issuer obligation). Each reference is tagged [Duplicate] or [Related]; the flag shows the strongest.
A11: Implementation Status, Control Owner, Notes (yellow) are for you to complete; Summary updates automatically.
A12: Example: UCR row for NOS req-limit-consensus-power → Status = Implemented, Owner = Head of Staking, Notes = 'Stake share 18% on Ethereum as of Q3'.
A14: Verification performed
A15: • BSSC requirement anchors re-checked against live specs (NOS 53, SCS 69, GSP 56); TIS/KMS heading-level.
... A23: • Source defects noted in BSSC specs: SCS version link points to gsp/v2.html; SCS references undefined #req-trigger-automated-response; NOS changelog uses #req-use-testnets; GSP anchor typo req-use-seecure-comms; KMS mixes FIPS 140-2/140-3.

Sheet Summary
A1: Unified Blockchain Control Register — Summary
A2: All figures are live formulas over the 'Control Register' tab.
A3: Controls by domain and priority
A4: Domain | B4: Critical | C4: High | D4: Medium | E4: Low | F4: Total | G4: Implemented | H4: % Implemented (excl. N/A & risk accepted)
A5: 01 Governance, Risk & Compliance | B5: =COUNTIFS('Control Register'!$C$2:$C$387,$A5,'Control Register'!$J$2:$J$387,"Critical") -> 2 | C5: =COUNTIFS('Control Register'!$C$2:$C$387,$A5,'Control Register'!$J$2:$J$387,"High") -> 15 | D5: =COUNTIFS('Control Register'!$C$2:$C$387,$A5,'Control Register'!$J$2:$J$387,"Medium") -> 7 | E5: =COUNTIFS('Control Register'!$C$2:$C$387,$A5,'Control Register'!$J$2:$J$387,"Low") -> 2 | F5: =SUM(B5:E5) -> 26 | G5: =COUNTIFS('Control Register'!$C$2:$C$387,$A5,'Control Register'!$AB$2:$AB$387,"Implemented") -> 0 | H5: =IF((F5-(COUNTIFS('Control Register'!$C$2:$C$387,$A5,'Control Register'!$AB$2:$AB$387,"Not applicable")+COUNTIFS('Control Register'!$C$2:$C$387,$A5,'Control Register'!$AB$2:$AB$387,"Risk accepted")))=0,0,G5/(F5-(COUNTIFS('Control Register'!$C$2:$C$387,$A5,'Control Register'!$AB$2:$AB$387,"Not applicable")+COUNTIFS('Control Register'!$C$2:$C$387,$A5,'Control Register'!$AB$2:$AB$387,"Risk accepted")))) -> 0
A6: 02 Key & Wallet Management | B6: =COUNTIFS('Control Register'!$C$2:$C$387,$A6,'Control Register'!$J$2:$J$387,"Critical") -> 32 | C6: =COUNTIFS('Control Register'!$C$2:$C$387,$A6,'Control Register'!$J$2:$J$387,"High") -> 32 | D6: =COUNTIFS('Control Register'!$C$2:$C$387,$A6,'Control Register'!$J$2:$J$387,"Medium") -> 11 | E6: =COUNTIFS('Control Register'!$C$2:$C$387,$A6,'Control Register'!$J$2:$J$387,"Low") -> 3 | F6: =SUM(B6:E6) -> 78 | G6: =COUNTIFS('Control Register'!$C$2:$C$387,$A6,'Control Register'!$AB$2:$AB$387,"Implemented") -> 0 | H6: =IF((F6-(COUNTIFS('Control Register'!$C$2:$C$387,$A6,'Control Register'!$AB$2:$AB$387,"Not applicable")+COUNTIFS('Control Register'!$C$2:$C$387,$A6,'Control Register'!$AB$2:$AB$387,"Risk accepted")))=0,0,G6/(F6-(COUNTIFS('Control Register'!$C$2:$C$387,$A6,'Control Register'!$AB$2:$AB$387,"Not applicable")+COUNTIFS('Control Register'!$C$2:$C$387,$A6,'Control Register'!$AB$2:$AB$387,"Risk accepted")))) -> 0
A7: 03 Smart Contract Development & Assurance | B7: =COUNTIFS('Control Register'!$C$2:$C$387,$A7,'Control Register'!$J$2:$J$387,"Critical") -> 10 | C7: =COUNTIFS('Control Register'!$C$2:$C$387,$A7,'Control Register'!$J$2:$J$387,"High") -> 23 | D7: =COUNTIFS('Control Register'!$C$2:$C$387,$A7,'Control Register'!$J$2:$J$387,"Medium") -> 21 | E7: =COUNTIFS('Control Register'!$C$2:$C$387,$A7,'Control Register'!$J$2:$J$387,"Low") -> 9 | F7: =SUM(B7:E7) -> 63 | G7: =COUNTIFS('Control Register'!$C$2:$C$387,$A7,'Control Register'!$AB$2:$AB$387,"Implemented") -> 0 | H7: =IF((F7-(COUNTIFS('Control Register'!$C$2:$C$387,$A7,'Control Register'!$AB$2:$AB$387,"Not applicable")+COUNTIFS('Control Register'!$C$2:$C$387,$A7,'Control Register'!$AB$2:$AB$387,"Risk accepted")))=0,0,G7/(F7-(COUNTIFS('Control Register'!$C$2:$C$387,$A7,'Control Register'!$AB$2:$AB$387,"Not applicable")+COUNTIFS('Control Register'!$C$2:$C$387,$A7,'Control Register'!$AB$2:$AB$387,"Risk accepted")))) -> 0
A8: 04 Token Integration & Listing | B8: =COUNTIFS('Control Register'!$C$2:$C$387,$A8,'Control Register'!$J$2:$J$387,"Critical") -> 5 | C8: =COUNTIFS('Control Register'!$C$2:$C$387,$A8,'Control Register'!$J$2:$J$387,"High") -> 20 | D8: =COUNTIFS('Control Register'!$C$2:$C$387,$A8,'Control Register'!$J$2:$J$387,"Medium") -> 18 | E8: =COUNTIFS('Control Register'!$C$2:$C$387,$A8,'Control Register'!$J$2:$J$387,"Low") -> 7 | F8: =SUM(B8:E8) -> 50 | G8: =COUNTIFS('Control Register'!$C$2:$C$387,$A8,'Control Register'!$AB$2:$AB$387,"Implemented") -> 0 | H8: =IF((F8-(COUNTIFS('Control Register'!$C$2:$C$387,$A8,'Control Register'!$AB$2:$AB$387,"Not applicable")+COUNTIFS('Control Register'!$C$2:$C$387,$A8,'Control Register'!$AB$2:$AB$387,"Risk accepted")))=0,0,G8/(F8-(COUNTIFS('Control Register'!$C$2:$C$387,$A8,'Control Register'!$AB$2:$AB$387,"Not applicable")+COUNTIFS('Control Register'!$C$2:$C$387,$A8,'Control Register'!$AB$2:$AB$387,"Risk accepted")))) -> 0
A9: 05 Node & Network Operations | B9: =COUNTIFS('Control Register'!$C$2:$C$387,$A9,'Control Register'!$J$2:$J$387,"Critical") -> 2 | C9: =COUNTIFS('Control Register'!$C$2:$C$387,$A9,'Control Register'!$J$2:$J$387,"High") -> 10 | D9: =COUNTIFS('Control Register'!$C$2:$C$387,$A9,'Control Register'!$J$2:$J$387,"Medium") -> 11 | E9: =COUNTIFS('Control Register'!$C$2:$C$387,$A9,'Control Register'!$J$2:$J$387,"Low") -> 2 | F9: =SUM(B9:E9) -> 25 | G9: =COUNTIFS('Control Register'!$C$2:$C$387,$A9,'Control Register'!$AB$2:$AB$387,"Implemented") -> 0 | H9: =IF((F9-(COUNTIFS('Control Register'!$C$2:$C$387,$A9,'Control Register'!$AB$2:$AB$387,"Not applicable")+COUNTIFS('Control Register'!$C$2:$C$387,$A9,'Control Register'!$AB$2:$AB$387,"Risk accepted")))=0,0,G9/(F9-(COUNTIFS('Control Register'!$C$2:$C$387,$A9,'Control Register'!$AB$2:$AB$387,"Not applicable")+COUNTIFS('Control Register'!$C$2:$C$387,$A9,'Control Register'!$AB$2:$AB$387,"Risk accepted")))) -> 0
A10: 06 Identity & Access Management | B10: =COUNTIFS('Control Register'!$C$2:$C$387,$A10,'Control Register'!$J$2:$J$387,"Critical") -> 3 | C10: =COUNTIFS('Control Register'!$C$2:$C$387,$A10,'Control Register'!$J$2:$J$387,"High") -> 8 | D10: =COUNTIFS('Control Register'!$C$2:$C$387,$A10,'Control Register'!$J$2:$J$387,"Medium") -> 1 | E10: =COUNTIFS('Control Register'!$C$2:$C$387,$A10,'Control Register'!$J$2:$J$387,"Low") -> 0 | F10: =SUM(B10:E10) -> 12 | G10: =COUNTIFS('Control Register'!$C$2:$C$387,$A10,'Control Register'!$AB$2:$AB$387,"Implemented") -> 0 | H10: =IF((F10-(COUNTIFS('Control Register'!$C$2:$C$387,$A10,'Control Register'!$AB$2:$AB$387,"Not applicable")+COUNTIFS('Control Register'!$C$2:$C$387,$A10,'Control Register'!$AB$2:$AB$387,"Risk accepted")))=0,0,G10/(F10-(COUNTIFS('Control Register'!$C$2:$C$387,$A10,'Control Register'!$AB$2:$AB$387,"Not applicable")+COUNTIFS('Control Register'!$C$2:$C$387,$A10,'Control Register'!$AB$2:$AB$387,"Risk accepted")))) -> 0
A11: 07 Logging, Monitoring & Detection | B11: =COUNTIFS('Control Register'!$C$2:$C$387,$A11,'Control Register'!$J$2:$J$387,"Critical") -> 4 | C11: =COUNTIFS('Control Register'!$C$2:$C$387,$A11,'Control Register'!$J$2:$J$387,"High") -> 11 | D11: =COUNTIFS('Control Register'!$C$2:$C$387,$A11,'Control Register'!$J$2:$J$387,"Medium") -> 3 | E11: =COUNTIFS('Control Register'!$C$2:$C$387,$A11,'Control Register'!$J$2:$J$387,"Low") -> 0 | F11: =SUM(B11:E11) -> 18 | G11: =COUNTIFS('Control Register'!$C$2:$C$387,$A11,'Control Register'!$AB$2:$AB$387,"Implemented") -> 0 | H11: =IF((F11-(COUNTIFS('Control Register'!$C$2:$C$387,$A11,'Control Register'!$AB$2:$AB$387,"Not applicable")+COUNTIFS('Control Register'!$C$2:$C$387,$A11,'Control Register'!$AB$2:$AB$387,"Risk accepted")))=0,0,G11/(F11-(COUNTIFS('Control Register'!$C$2:$C$387,$A11,'Control Register'!$AB$2:$AB$387,"Not applicable")+COUNTIFS('Control Register'!$C$2:$C$387,$A11,'Control Register'!$AB$2:$AB$387,"Risk accepted")))) -> 0
A12: 08 Incident Response & Resilience | B12: =COUNTIFS('Control Register'!$C$2:$C$387,$A12,'Control Register'!$J$2:$J$387,"Critical") -> 3 | C12: =COUNTIFS('Control Register'!$C$2:$C$387,$A12,'Control Register'!$J$2:$J$387,"High") -> 24 | D12: =COUNTIFS('Control Register'!$C$2:$C$387,$A12,'Control Register'!$J$2:$J$387,"Medium") -> 8 | E12: =COUNTIFS('Control Register'!$C$2:$C$387,$A12,'Control Register'!$J$2:$J$387,"Low") -> 0 | F12: =SUM(B12:E12) -> 35 | G12: =COUNTIFS('Control Register'!$C$2:$C$387,$A12,'Control Register'!$AB$2:$AB$387,"Implemented") -> 0 | H12: =IF((F12-(COUNTIFS('Control Register'!$C$2:$C$387,$A12,'Control Register'!$AB$2:$AB$387,"Not applicable")+COUNTIFS('Control Register'!$C$2:$C$387,$A12,'Control Register'!$AB$2:$AB$387,"Risk accepted")))=0,0,G12/(F12-(COUNTIFS('Control Register'!$C$2:$C$387,$A12,'Control Register'!$AB$2:$AB$387,"Not applicable")+COUNTIFS('Control Register'!$C$2:$C$387,$A12,'Control Register'!$AB$2:$AB$387,"Risk accepted")))) -> 0
A13: 09 Infrastructure & Endpoint Security | B13: =COUNTIFS('Control Register'!$C$2:$C$387,$A13,'Control Register'!$J$2:$J$387,"Critical") -> 2 | C13: =COUNTIFS('Control Register'!$C$2:$C$387,$A13,'Control Register'!$J$2:$J$387,"High") -> 10 | D13: =COUNTIFS('Control Register'!$C$2:$C$387,$A13,'Control Register'!$J$2:$J$387,"Medium") -> 4 | E13: =COUNTIFS('Control Register'!$C$2:$C$387,$A13,'Control Register'!$J$2:$J$387,"Low") -> 0 | F13: =SUM(B13:E13) -> 16 | G13: =COUNTIFS('Control Register'!$C$2:$C$387,$A13,'Control Register'!$AB$2:$AB$387,"Implemented") -> 0 | H13: =IF((F13-(COUNTIFS('Control Register'!$C$2:$C$387,$A13,'Control Register'!$AB$2:$AB$387,"Not applicable")+COUNTIFS('Control Register'!$C$2:$C$387,$A13,'Control Register'!$AB$2:$AB$387,"Risk accepted")))=0,0,G13/(F13-(COUNTIFS('Control Register'!$C$2:$C$387,$A13,'Control Register'!$AB$2:$AB$387,"Not applicable")+COUNTIFS('Control Register'!$C$2:$C$387,$A13,'Control Register'!$AB$2:$AB$387,"Risk accepted")))) -> 0
A14: 10 Supply Chain & Third Parties | B14: =COUNTIFS('Control Register'!$C$2:$C$387,$A14,'Control Register'!$J$2:$J$387,"Critical") -> 3 | C14: =COUNTIFS('Control Register'!$C$2:$C$387,$A14,'Control Register'!$J$2:$J$387,"High") -> 8 | D14: =COUNTIFS('Control Register'!$C$2:$C$387,$A14,'Control Register'!$J$2:$J$387,"Medium") -> 2 | E14: =COUNTIFS('Control Register'!$C$2:$C$387,$A14,'Control Register'!$J$2:$J$387,"Low") -> 0 | F14: =SUM(B14:E14) -> 13 | G14: =COUNTIFS('Control Register'!$C$2:$C$387,$A14,'Control Register'!$AB$2:$AB$387,"Implemented") -> 0 | H14: =IF((F14-(COUNTIFS('Control Register'!$C$2:$C$387,$A14,'Control Register'!$AB$2:$AB$387,"Not applicable")+COUNTIFS('Control Register'!$C$2:$C$387,$A14,'Control Register'!$AB$2:$AB$387,"Risk accepted")))=0,0,G14/(F14-(COUNTIFS('Control Register'!$C$2:$C$387,$A14,'Control Register'!$AB$2:$AB$387,"Not applicable")+COUNTIFS('Control Register'!$C$2:$C$387,$A14,'Control Register'!$AB$2:$AB$387,"Risk accepted")))) -> 0
A15: 11 Data Protection & Privacy | B15: =COUNTIFS('Control Register'!$C$2:$C$387,$A15,'Control Register'!$J$2:$J$387,"Critical") -> 0 | C15: =COUNTIFS('Control Register'!$C$2:$C$387,$A15,'Control Register'!$J$2:$J$387,"High") -> 5 | D15: =COUNTIFS('Control Register'!$C$2:$C$387,$A15,'Control Register'!$J$2:$J$387,"Medium") -> 7 | E15: =COUNTIFS('Control Register'!$C$2:$C$387,$A15,'Control Register'!$J$2:$J$387,"Low") -> 0 | F15: =SUM(B15:E15) -> 12 | G15: =COUNTIFS('Control Register'!$C$2:$C$387,$A15,'Control Register'!$AB$2:$AB$387,"Implemented") -> 0 | H15: =IF((F15-(COUNTIFS('Control Register'!$C$2:$C$387,$A15,'Control Register'!$AB$2:$AB$387,"Not applicable")+COUNTIFS('Control Register'!$C$2:$C$387,$A15,'Control Register'!$AB$2:$AB$387,"Risk accepted")))=0,0,G15/(F15-(COUNTIFS('Control Register'!$C$2:$C$387,$A15,'Control Register'!$AB$2:$AB$387,"Not applicable")+COUNTIFS('Control Register'!$C$2:$C$387,$A15,'Control Register'!$AB$2:$AB$387,"Risk accepted")))) -> 0
A16: 12 People & Physical Security | B16: =COUNTIFS('Control Register'!$C$2:$C$387,$A16,'Control Register'!$J$2:$J$387,"Critical") -> 3 | C16: =COUNTIFS('Control Register'!$C$2:$C$387,$A16,'Control Register'!$J$2:$J$387,"High") -> 4 | D16: =COUNTIFS('Control Register'!$C$2:$C$387,$A16,'Control Register'!$J$2:$J$387,"Medium") -> 2 | E16: =COUNTIFS('Control Register'!$C$2:$C$387,$A16,'Control Register'!$J$2:$J$387,"Low") -> 0 | F16: =SUM(B16:E16) -> 9 | G16: =COUNTIFS('Control Register'!$C$2:$C$387,$A16,'Control Register'!$AB$2:$AB$387,"Implemented") -> 0 | H16: =IF((F16-(COUNTIFS('Control Register'!$C$2:$C$387,$A16,'Control Register'!$AB$2:$AB$387,"Not applicable")+COUNTIFS('Control Register'!$C$2:$C$387,$A16,'Control Register'!$AB$2:$AB$387,"Risk accepted")))=0,0,G16/(F16-(COUNTIFS('Control Register'!$C$2:$C$387,$A16,'Control Register'!$AB$2:$AB$387,"Not applicable")+COUNTIFS('Control Register'!$C$2:$C$387,$A16,'Control Register'!$AB$2:$AB$387,"Risk accepted")))) -> 0
... A18: 14 Protocol Governance & Upgrades | B18: =COUNTIFS('Control Register'!$C$2:$C$387,$A18,'Control Register'!$J$2:$J$387,"Critical") -> 5 | C18: =COUNTIFS('Control Register'!$C$2:$C$387,$A18,'Control Register'!$J$2:$J$387,"High") -> 6 | D18: =COUNTIFS('Control Register'!$C$2:$C$387,$A18,'Control Register'!$J$2:$J$387,"Medium") -> 7 | E18: =COUNTIFS('Control Register'!$C$2:$C$387,$A18,'Control Register'!$J$2:$J$387,"Low") -> 4 | F18: =SUM(B18:E18) -> 22 | G18: =COUNTIFS('Control Register'!$C$2:$C$387,$A18,'Control Register'!$AB$2:$AB$387,"Implemented") -> 0 | H18: =IF((F18-(COUNTIFS('Control Register'!$C$2:$C$387,$A18,'Control Register'!$AB$2:$AB$387,"Not applicable")+COUNTIFS('Control Register'!$C$2:$C$387,$A18,'Control Register'!$AB$2:$AB$387,"Risk accepted")))=0,0,G18/(F18-(COUNTIFS('Control Register'!$C$2:$C$387,$A18,'Control Register'!$AB$2:$AB$387,"Not applicable")+COUNTIFS('Control Register'!$C$2:$C$387,$A18,'Control Register'!$AB$2:$AB$387,"Risk accepted")))) -> 0
A19: Total | B19: =SUM(B5:B18) -> 77 | C19: =SUM(C5:C18) -> 178 | D19: =SUM(D5:D18) -> 104 | E19: =SUM(E5:E18) -> 27 | F19: =SUM(F5:F18) -> 386 | G19: =SUM(G5:G18) -> 0 | H19: =IF((F19-COUNTIF('Control Register'!$AB$2:$AB$387,"Not applicable")-COUNTIF('Control Register'!$AB$2:$AB$387,"Risk accepted"))=0,0,G19/(F19-COUNTIF('Control Register'!$AB$2:$AB$387,"Not applicable")-COUNTIF('Control Register'!$AB$2:$AB$387,"Risk accepted"))) -> 0
A20: Check: total equals register row count | F20: =IF(F19=COUNTA('Control Register'!$B$2:$B$387),"OK","MISMATCH") -> OK
A22: Controls by primary source framework
A23: Primary Source Framework | B23: Controls
A24: BSSC NOS v2 | B24: =COUNTIF('Control Register'!$F$2:$F$387,$A24) -> 54
A25: BSSC TIS v1 | B25: =COUNTIF('Control Register'!$F$2:$F$387,$A25) -> 50
A26: BSSC KMS v1 | B26: =COUNTIF('Control Register'!$F$2:$F$387,$A26) -> 96
A27: BSSC SCS v1 | B27: =COUNTIF('Control Register'!$F$2:$F$387,$A27) -> 69
A28: BSSC GSP v2 | B28: =COUNTIF('Control Register'!$F$2:$F$387,$A28) -> 56
A29: OWASP SC Top 10:2026 | B29: =COUNTIF('Control Register'!$F$2:$F$387,$A29) -> 13
A30: OWASP SCSVS | B30: =COUNTIF('Control Register'!$F$2:$F$387,$A30) -> 8
A31: OWASP Web3 Top 15 | B31: =COUNTIF('Control Register'!$F$2:$F$387,$A31) -> 6
A32: SEAL Frameworks | B32: =COUNTIF('Control Register'!$F$2:$F$387,$A32) -> 22
A33: CCSS v9.0 | B33: =COUNTIF('Control Register'!$F$2:$F$387,$A33) -> 3
A34: CIS Controls v8.1 | B34: =COUNTIF('Control Register'!$F$2:$F$387,$A34) -> 4
A35: DORA (EU 2022/2554) | B35: =COUNTIF('Control Register'!$F$2:$F$387,$A35) -> 3
... A37: FATF Recommendations | B37: =COUNTIF('Control Register'!$F$2:$F$387,$A37) -> 1
A38: Total | B38: =SUM(B24:B37) -> 386
A40: Framework coverage (controls mapped to each item; 0 = gap)
A41: Framework | B41: Item | C41: Mapped controls | D41: Covered?
A42: OWASP SC Top 10:2026 | B42: SC01 | C42: =COUNTIF('Control Register'!$O$2:$O$387,"*SC01*") -> 13 | D42: =IF(C42>0,"Yes","GAP") -> Yes
A43: OWASP SC Top 10:2026 | B43: SC02 | C43: =COUNTIF('Control Register'!$O$2:$O$387,"*SC02*") -> 12 | D43: =IF(C43>0,"Yes","GAP") -> Yes
A44: OWASP SC Top 10:2026 | B44: SC03 | C44: =COUNTIF('Control Register'!$O$2:$O$387,"*SC03*") -> 6 | D44: =IF(C44>0,"Yes","GAP") -> Yes
...

Sheet Control Register
A1: # | B1: Control ID | C1: Domain | D1: Area | E1: Recommended Control | F1: Primary Source Framework | G1: Primary Source Ref ID | H1: Reference Standard | I1: Requirement Level | J1: Priority | K1: Applies To | L1: Applicable Frameworks | M1: BSSC (ID · req) | N1: OWASP SCSVS | O1: OWASP SC Top 10:2026 | P1: OWASP Web3 Top 15 | Q1: EthTrust | R1: SEAL Frameworks | S1: CCSS v9.0 | T1: CIS Controls v8.1 | U1: NIST CSF 2.0 | V1: ISO/IEC 27001:2022 | W1: Regulatory | X1: Overlap Flag | Y1: Overlap Reference | Z1: Verification Method / Evidence | AA1: Source Link | AB1: Implementation Status | AC1: Control Owner | AD1: Notes
A2: 1 | B2: UCR-001 | C2: 01 Governance, Risk & Compliance | D2: Baseline security program | E2: Implement the BSSC General Security & Privacy Guidelines (or ISO 27001 / SOC 2 equivalent) as the baseline security program for node operations. | F2: BSSC NOS v2 | G2: req-implement-basic-security | H2: BSSC NOS v2 — 0. Basic Security | I2: MUST | J2: High | K2: Node/validator operator; Exchange/Custodian running nodes | L2: BSSC NOS; SEAL; CIS v8.1; NIST CSF 2.0; ISO 27001:2022; DORA | M2: NOS-002 · req-implement-basic-security | R2: OpSec | T2: CIS 1–18 (IG1 baseline) | U2: GV.PO-01 | V2: A.5.1 | W2: DORA Art. 5–6 | X2: Related | Y2: UCR-320 [Related] (CIS Controls v8.1 CIS 4.1) | Z2: Review GSP gap assessment or ISO/SOC 2 report scope covering node infrastructure. | AA2: Open source | AB2: Not started
A3: 2 | B3: UCR-002 | C3: 01 Governance, Risk & Compliance | D3: Risk assessment | E3: Run a documented protocol selection and risk analysis (consensus, economics, client maturity, slashing exposure) before onboarding any new network. | F3: BSSC NOS v2 | G3: req-document-protocol-analysis | H3: BSSC NOS v2 — 1. Protocol Onboarding | I3: MUST | J3: High | K3: Node/validator operator; Exchange/Custodian running nodes | L3: BSSC NOS; SEAL; NIST CSF 2.0; ISO 27001:2022; DORA | M3: NOS-003 · req-document-protocol-analysis | R3: OpSec | U3: ID.RA-01; GV.RM-03 | V3: A.5.8 | W3: DORA Art. 6, 8 | X3: None | Z3: Inspect onboarding risk assessments and approval sign-off for each supported protocol. | AA3: Open source | AB3: Not started
A4: 3 | B4: UCR-003 | C4: 01 Governance, Risk & Compliance | D4: Risk assessment | E4: Continuously monitor protocol forks, upgrades and governance changes (release feeds, EIPs/BIPs, dev calls) and refresh the protocol risk assessment on each material change. | F4: BSSC NOS v2 | G4: req-monitor-protocol-changes | H4: BSSC NOS v2 — 1. Protocol Onboarding | I4: MUST | J4: High | K4: Node/validator operator; Exchange/Custodian running nodes | L4: BSSC NOS; SEAL; NIST CSF 2.0; ISO 27001:2022; DORA | M4: NOS-004 · req-monitor-protocol-changes | R4: OpSec | U4: ID.RA-03; ID.RA-07 | V4: A.5.7 | W4: DORA Art. 6, 8 | X4: None | Z4: Show change-tracking log, subscriptions, and risk-assessment revision history. | AA4: Open source | AB4: Not started
A5: 4 | B5: UCR-004 | C5: 01 Governance, Risk & Compliance | D5: Compliance | E5: Screen counterparties and addresses against applicable AML/sanctions blacklists (e.g., OFAC SDN) where required; document jurisdictional obligations. | F5: BSSC NOS v2 | G5: req-follow-relevant-regulation | H5: BSSC NOS v2 — 1. Protocol Onboarding | I5: MUST | J5: Critical | K5: Node/validator operator; Exchange/Custodian running nodes | L5: BSSC NOS; NIST CSF 2.0; ISO 27001:2022; FATF | M5: NOS-011 · req-follow-relevant-regulation | U5: GV.OC-03 | V5: A.5.31 | W5: FATF R.6/R.7 (sanctions), R.15; EU TFR 2023/1113; EU AMLR 2024/1624 | X5: Related | Y5: UCR-018 [Related] (BSSC GSP v2 req-monitor-regulation) | Z5: Test screening tooling against known sanctioned addresses; review compliance register. | AA5: Open source | AB5: Not started
A6: 5 | B6: UCR-005 | C6: 01 Governance, Risk & Compliance | D6: Transparency | E6: Disclose scope and terms of insurance covering slashing, downtime and compromise, or state clearly that none exists. | F6: BSSC NOS v2 | G6: req-document-insurance | H6: BSSC NOS v2 — 5. Transparency | I6: MUST | J6: Medium | K6: Node/validator operator; Exchange/Custodian running nodes | L6: BSSC NOS; NIST CSF 2.0 | M6: NOS-050 · req-document-insurance | U6: GV.OC-02 | X6: None | Z6: Review published insurance disclosure. | AA6: Open source | AB6: Not started
A7: 6 | B7: UCR-006 | C7: 01 Governance, Risk & Compliance | D7: Transparency | E7: Document exit triggers, notification timelines, stored-transaction handling, unbonding/withdrawal penalties and delay conditions. | F7: BSSC NOS v2 | G7: req-document-exit-procedures | H7: BSSC NOS v2 — 5. Transparency | I7: MUST | J7: Medium | K7: Node/validator operator; Exchange/Custodian running nodes | L7: BSSC NOS; NIST CSF 2.0; ISO 27001:2022 | M7: NOS-052 · req-document-exit-procedures | U7: GV.OC-02 | V7: A.5.37 | X7: None | Z7: Review client-facing exit documentation. | AA7: Open source | AB7: Not started
A8: 7 | B8: UCR-007 | C8: 01 Governance, Risk & Compliance | D8: Transparency | E8: Use only industry-standard encrypted communication methods with clients and partners. | F8: BSSC NOS v2 | G8: req-communicate-securely | H8: BSSC NOS v2 — 5. Transparency | I8: MUST | J8: High | K8: Node/validator operator; Exchange/Custodian running nodes | L8: BSSC NOS; SEAL; CIS v8.1; NIST CSF 2.0; ISO 27001:2022 | M8: NOS-053 · req-communicate-securely | R8: OpSec | T8: CIS 3.10 | U8: PR.DS-02 | V8: A.5.14 | X8: Related | Y8: UCR-314 [Related] (BSSC GSP v2 req-use-seecure-comms) | Z8: Review approved communications channels list. | AA8: Open source | AB8: Not started
A9: 8 | B9: UCR-008 | C9: 01 Governance, Risk & Compliance | D9: Threat modelling | E9: Maintain a threat model covering online and offline key components. | F9: BSSC KMS v1 | G9: KMS-GEN-15 | H9: BSSC KMS v1 — §5 General Requirements | I9: SHOULD | J9: High | K9: All key holders (Custodian/Exchange, Node operator, Protocol/admin keys) | L9: BSSC KMS; SEAL; CIS v8.1; NIST CSF 2.0; ISO 27001:2022 | M9: KMS-015 · KMS-GEN-15 | R9: OpSec | T9: CIS 16.14 | U9: ID.RA-03 | V9: A.5.7; A.8.27 | X9: None | Z9: Review threat model currency. | AA9: Open source | AB9: Not started
A10: 9 | B10: UCR-009 | C10: 01 Governance, Risk & Compliance | D10: Threat modelling | E10: Ensure the threat model identifies threats and vulnerabilities. | F10: BSSC KMS v1 | G10: KMS-GEN-16 | H10: BSSC KMS v1 — §5 General Requirements | I10: MUST | J10: High | K10: All key holders (Custodian/Exchange, Node operator, Protocol/admin keys) | L10: BSSC KMS; SEAL; CIS v8.1; NIST CSF 2.0; ISO 27001:2022 | M10: KMS-016 · KMS-GEN-16 | R10: OpSec | T10: CIS 16.14 | U10: ID.RA-03 | V10: A.8.27 | X10: None | Z10: Threat model content review. | AA10: Open source | AB10: Not started
A11: 10 | B11: UCR-010 | C11: 01 Governance, Risk & Compliance | D11: Threat modelling | E11: Ensure the threat model recommends controls and tracks implementation status. | F11: BSSC KMS v1 | G11: KMS-GEN-17 | H11: BSSC KMS v1 — §5 General Requirements | I11: MUST | J11: Medium | K11: All key holders (Custodian/Exchange, Node operator, Protocol/admin keys) | L11: BSSC KMS; SEAL; CIS v8.1; NIST CSF 2.0; ISO 27001:2022 | M11: KMS-017 · KMS-GEN-17 | R11: OpSec | T11: CIS 16.14 | U11: ID.RA-06 | V11: A.8.27 | X11: None | Z11: Trace threats to control status. | AA11: Open source | AB11: Not started
A12: 11 | B12: UCR-011 | C12: 01 Governance, Risk & Compliance | D12: Threat modelling | E12: Periodically test threats and controls via audits and penetration tests. | F12: BSSC KMS v1 | G12: KMS-GEN-18 | H12: BSSC KMS v1 — §5 General Requirements | I12: SHOULD | J12: High | K12: All key holders (Custodian/Exchange, Node operator, Protocol/admin keys) | L12: BSSC KMS; SEAL; CCSS v9.0; CIS v8.1; NIST CSF 2.0; ISO 27001:2022 | M12: KMS-018 · KMS-GEN-18 | R12: Security Testing | S12: 2.01 Security Audits | T12: CIS 18.1 | U12: ID.IM-02 | V12: A.8.8 | X12: Related | Y12: UCR-317 [Related] (BSSC GSP v2 req-test-penetration) | Z12: Review pentest/audit reports. | AA12: Open source | AB12: Not started
A13: 12 | B13: UCR-012 | C13: 01 Governance, Risk & Compliance | D13: Risk assessment & monitoring | E13: Document a risk assessment at least annually. | F13: BSSC SCS v1 | G13: req-assess-risk-regularly | H13: BSSC SCS v1 — 4. Operations | I13: MUST | J13: High | K13: Protocol/dApp/token developer; Exchange/Custodian (own contracts) | L13: BSSC SCS; SEAL; NIST CSF 2.0; ISO 27001:2022; DORA | M13: SCS-048 · req-assess-risk-regularly | R13: OpSec | U13: ID.RA-01 | V13: Cl. 8.2; A.5.7 | W13: DORA Art. 6, 8 | X13: Duplicate | Y13: UCR-020 [Duplicate] (BSSC GSP v2 req-assess-risks) | Z13: Latest annual risk assessment. | AA13: Open source | AB13: Not started
A14: 13 | B14: UCR-013 | C14: 01 Governance, Risk & Compliance | D14: Security knowledge | E14: Document how new security information (exploit post-mortems, advisories) is integrated. | F14: BSSC SCS v1 | G14: req-update-security-process | H14: BSSC SCS v1 — 4. Operations | I14: MUST | J14: Medium | K14: Protocol/dApp/token developer; Exchange/Custodian (own contracts) | L14: BSSC SCS; SEAL; NIST CSF 2.0; ISO 27001:2022 | M14: SCS-052 · req-update-security-process | R14: Awareness | U14: ID.IM-01 | V14: A.5.7 | X14: None | Z14: Process doc and examples. | AA14: Open source | AB14: Not started
A15: 14 | B15: UCR-014 | C15: 01 Governance, Risk & Compliance | D15: Risk management | E15: Include blockchain-specific risks (key loss, smart contract, chain, bridge) in enterprise risk management. | F15: BSSC GSP v2 | G15: req-treat-blockchain-risk | H15: BSSC GSP v2 — 1. Govern | I15: SHOULD | J15: High | K15: All blockchain participants | L15: BSSC GSP; SEAL; NIST CSF 2.0; ISO 27001:2022; DORA | M15: GSP-001 · req-treat-blockchain-risk | R15: OpSec | U15: GV.RM-01; GV.RM-03 | V15: Cl. 6.1; A.5.1 | W15: DORA Art. 5–6 | X15: None | Z15: ERM register shows blockchain risk category. | AA15: Open source | AB15: Not started
A16: 15 | B16: UCR-015 | C16: 01 Governance, Risk & Compliance | D16: Risk management | E16: Maintain a risk governance framework and risk register reviewed with stakeholders. | F16: BSSC GSP v2 | G16: req-risk-register | H16: BSSC GSP v2 — 1. Govern | I16: SHOULD | J16: High | K16: All blockchain participants | L16: BSSC GSP; SEAL; NIST CSF 2.0; ISO 27001:2022; DORA | M16: GSP-002 · req-risk-register | R16: OpSec | U16: GV.RM-01; ID.RA-06 | V16: Cl. 6.1.2; Cl. 8.2 | W16: DORA Art. 5–6 | X16: None | Z16: Register and review minutes. | AA16: Open source | AB16: Not started
A17: 16 | B17: UCR-016 | C17: 01 Governance, Risk & Compliance | D17: Governance resources | E17: Assign dedicated resources and owners for security governance and compliance. | F17: BSSC GSP v2 | G17: req-assign-governance | H17: BSSC GSP v2 — 1. Govern | I17: SHOULD | J17: Medium | K17: All blockchain participants | L17: BSSC GSP; SEAL; NIST CSF 2.0; ISO 27001:2022; DORA | M17: GSP-003 · req-assign-governance | R17: OpSec | U17: GV.RR-03 | V17: Cl. 5.3; A.5.2 | W17: DORA Art. 5 | X17: None | Z17: Org chart / RACI. | AA17: Open source | AB17: Not started
A18: 17 | B18: UCR-017 | C18: 01 Governance, Risk & Compliance | D18: Public compliance | E18: Publish a trust centre with compliance documentation and privacy policy. | F18: BSSC GSP v2 | G18: req-publish-trust-info | H18: BSSC GSP v2 — 1. Govern | I18: SHOULD | J18: Low | K18: All blockchain participants | L18: BSSC GSP; NIST CSF 2.0; ISO 27001:2022 | M18: GSP-005 · req-publish-trust-info | U18: GV.OC-02 | V18: A.5.34 | X18: None | Z18: Trust centre review. | AA18: Open source | AB18: Not started
A19: 18 | B19: UCR-018 | C19: 01 Governance, Risk & Compliance | D19: Regulatory monitoring | E19: Track and adapt to evolving regulation (MiCA, Travel Rule, local VASP rules). | F19: BSSC GSP v2 | G19: req-monitor-regulation | H19: BSSC GSP v2 — 1. Govern | I19: SHOULD | J19: High | K19: All blockchain participants | L19: BSSC GSP; NIST CSF 2.0; ISO 27001:2022; DORA; MiCA; FATF | M19: GSP-006 · req-monitor-regulation | U19: GV.OC-03 | V19: A.5.31 | W19: MiCA; DORA; FATF | X19: Related | Y19: UCR-004 [Related] (BSSC NOS v2 req-follow-relevant-regulation) | Z19: Regulatory watch log. | AA19: Open source | AB19: Not started
A20: 19 | B20: UCR-019 | C20: 01 Governance, Risk & Compliance | D20: Crypto standards | E20: Track cryptographic standards incl. post-quantum guidance in risk management. | F20: BSSC GSP v2 | G20: req-monitor-crypto | H20: BSSC GSP v2 — 1. Govern | I20: SHOULD | J20: Medium | K20: All blockchain participants | L20: BSSC GSP; NIST CSF 2.0; ISO 27001:2022 | M20: GSP-008 · req-monitor-crypto | U20: ID.RA-03 | V20: A.8.24 | X20: Related | Y20: UCR-221 [Related] (BSSC NOS v2 req-evaluate-protocol-pqc-plan); UCR-126 [Related] (BSSC SCS v1 req-assess-cryptography-risk) | Z20: Crypto watch entries in risk register. | AA20: Open source | AB20: Not started
A21: 20 | B21: UCR-020 | C21: 01 Governance, Risk & Compliance | D21: Risk assessment | E21: Conduct regular blockchain-specific risk assessments. | F21: BSSC GSP v2 | G21: req-assess-risks | H21: BSSC GSP v2 — 2. Identify | I21: SHOULD | J21: High | K21: All blockchain participants | L21: BSSC GSP; SEAL; NIST CSF 2.0; ISO 27001:2022; DORA | M21: GSP-009 · req-assess-risks | R21: OpSec | U21: ID.RA-01 | V21: Cl. 8.2 | W21: DORA Art. 6, 8 | X21: Duplicate | Y21: UCR-012 [Duplicate] (BSSC SCS v1 req-assess-risk-regularly) | Z21: Assessment reports. | AA21: Open source | AB21: Not started
A22: 21 | B22: UCR-021 | C22: 01 Governance, Risk & Compliance | D22: Customer funds | E22: Document risks to customer funds and keep accessible. | F22: BSSC GSP v2 | G22: req-document-funds-risks | H22: BSSC GSP v2 — 2. Identify | I22: SHOULD | J22: Critical | K22: Custodian/Exchange; Protocol holding user funds | L22: BSSC GSP; SEAL; CCSS v9.0; NIST CSF 2.0; ISO 27001:2022; MiCA | M22: GSP-010 · req-document-funds-risks | R22: Treasury Operations | S22: 2.03 Proof of Reserve | U22: ID.RA-04 | V22: Cl. 6.1.2 | W22: MiCA Art. 70 | X22: Related | Y22: UCR-025 [Related] (CCSS v9.0 2.03 Proof of Reserve); UCR-104 [Related] (MiCA (EU 2023/1114) Art. 70; 75) | Z22: Customer-funds risk document. | AA22: Open source | AB22: Not started
A23: 22 | B23: UCR-022 | C23: 01 Governance, Risk & Compliance | D23: Ecosystem risk | E23: Assess ecosystem/external risks (bridges, L1 health, counterparties, stablecoin depegs). | F23: BSSC GSP v2 | G23: req-assess-ecosystem-risk | H23: BSSC GSP v2 — 2. Identify | I23: SHOULD | J23: High | K23: All blockchain participants | L23: BSSC GSP; NIST CSF 2.0; ISO 27001:2022 | M23: GSP-011 · req-assess-ecosystem-risk | U23: ID.RA-03; GV.SC-07 | V23: A.5.7 | X23: Related | Y23: UCR-160 [Related] (OWASP SC Top 10:2026 SC03) | Z23: Ecosystem risk assessment. | AA23: Open source | AB23: Not started
A24: 23 | B24: UCR-023 | C24: 01 Governance, Risk & Compliance | D24: Cryptographic security | E24: Maintain a cryptographic inventory and migration plan for timely transitions incl. post-quantum. | F24: BSSC GSP v2 | G24: req-crypto-agility | H24: BSSC GSP v2 — 3. Protect | I24: SHOULD | J24: Medium | K24: All blockchain participants | L24: BSSC GSP; NIST CSF 2.0; ISO 27001:2022 | M24: GSP-037 · req-crypto-agility | U24: ID.AM-08; ID.IM-04 | V24: A.8.24 | X24: Related | Y24: UCR-220 [Related] (BSSC NOS v2 req-document-protocol-crypto); UCR-124 [Related] (BSSC SCS v1 req-document-cryptography) | Z24: Crypto inventory and plan. | AA24: Open source | AB24: Not started
A25: 24 | B25: UCR-024 | C25: 01 Governance, Risk & Compliance | D25: Independent security certification | E25: Pursue an independent certification (e.g., SEAL certification, CCSS audit, SOC 2/ISO 27001) appropriate to the business line. | F25: SEAL Frameworks | G25: SEAL Certifications | H25: SEAL Frameworks — SEAL Certifications | I25: Recommended (supplementary) | J25: Low | K25: All blockchain participants | L25: SEAL; CCSS v9.0; NIST CSF 2.0; ISO 27001:2022 | R25: SEAL Certifications | S25: 2.01 Security Audits | U25: GV.OV-01 | V25: A.5.35 | X25: None | Z25: Certificate/report. | AA25: Open source | AB25: Not started
A26: 25 | B26: UCR-025 | C26: 01 Governance, Risk & Compliance | D26: Proof of reserve | E26: Perform periodic, independently attested proof-of-reserve (assets ≥ liabilities) and publish results. | F26: CCSS v9.0 | G26: 2.03 Proof of Reserve | H26: CCSS v9.0 — 2.03 Proof of Reserve | I26: Recommended (supplementary) | J26: High | K26: Custodian/Exchange | L26: OWASP Web3 Top 15; SEAL; CCSS v9.0; NIST CSF 2.0; ISO 27001:2022; MiCA | P26: WA07 | R26: Treasury Operations | S26: 2.03 Proof of Reserve | U26: GV.OC-02 | V26: A.5.35 | W26: MiCA Art. 70 | X26: Related | Y26: UCR-021 [Related] (BSSC GSP v2 req-document-funds-risks) | Z26: Latest PoR attestation. | AA26: Open source | AB26: Not started
A27: 26 | B27: UCR-026 | C27: 01 Governance, Risk & Compliance | D27: Travel Rule | E27: Collect and transmit originator/beneficiary information for qualifying virtual-asset transfers and screen counterparties (VASP due diligence). | F27: FATF Recommendations | G27: R.15; R.16 | H27: FATF Recommendations — R.15; R.16 | I27: Recommended (supplementary) | J27: High | K27: Custodian/Exchange | L27: NIST CSF 2.0; ISO 27001:2022; FATF | U27: GV.OC-03 | V27: A.5.31 | W27: FATF R.15/R.16; EU TFR 2023/1113 | X27: None | Z27: Travel-rule solution logs; sample transfers. | AA27: Open source | AB27: Not started
A28: 27 | B28: UCR-027 | C28: 02 Key & Wallet Management | D28: Key security | E28: Manage all node, validator, withdrawal and signing keys under the BSSC Key Management Standard (or a documented equivalent); maintain a KMS conformance mapping. | F28: BSSC NOS v2 | G28: req-manage-key-security | H28: BSSC NOS v2 — 0. Basic Security | I28: MUST | J28: Critical | K28: Node/validator operator; Exchange/Custodian running nodes | L28: BSSC NOS; OWASP Web3 Top 15; SEAL; CCSS v9.0; CIS v8.1; NIST CSF 2.0; ISO 27001:2022 | M28: NOS-001 · req-manage-key-security | P28: WA03 | R28: Wallet Security | S28: 1.01–1.06 (Section 1, key lifecycle) | T28: CIS 3.11 | U28: PR.AA-01; PR.DS-01 | V28: A.8.24 | X28: Duplicate | Y28: UCR-094 [Duplicate] (BSSC GSP v2 req-protect-keys) | Z28: Review KMS conformance matrix; sample key lifecycle records; interview key custodians. | AA28: Open source | AB28: Not started
A29: 28 | B29: UCR-028 | C29: 02 Key & Wallet Management | D29: Access control | E29: Use remote signers/HSM-backed signing so key material is not on network-connected nodes; isolate the signer network. | F29: BSSC NOS v2 | G29: req-use-remote-signers | H29: BSSC NOS v2 — 4. Security and Access Control | I29: SHOULD | J29: Critical | K29: Node/validator operator; Exchange/Custodian running nodes | L29: BSSC NOS; OWASP Web3 Top 15; SEAL; CCSS v9.0; CIS v8.1; NIST CSF 2.0; ISO 27001:2022 | M29: NOS-037 · req-use-remote-signers | P29: WA03 | R29: Wallet Security | S29: 1.03 Key Storage; 1.05 Key Usage | T29: CIS 3.11; CIS 12.2 | U29: PR.AA-05; PR.DS-01 | V29: A.8.24; A.8.22 | X29: Related | Y29: UCR-322 [Related] (CIS Controls v8.1 CIS 12.2; 13.4) | Z29: Verify no keystores on beacon/validator hosts; review signer network segmentation. | AA29: Open source | AB29: Not started
A30: 29 | B30: UCR-029 | C30: 02 Key & Wallet Management | D30: Access control | E30: Where remote signers are unsupported, apply compensating key protections (encrypted keystores, TEEs, host hardening, strict access). | F30: BSSC NOS v2 | G30: req-remote-signer-alternatives | H30: BSSC NOS v2 — 4. Security and Access Control | I30: MUST | J30: Critical | K30: Node/validator operator; Exchange/Custodian running nodes | L30: BSSC NOS; OWASP Web3 Top 15; SEAL; CCSS v9.0; CIS v8.1; NIST CSF 2.0; ISO 27001:2022 | M30: NOS-038 · req-remote-signer-alternatives | P30: WA03 | R30: Wallet Security | S30: 1.03 Key Storage | T30: CIS 3.11 | U30: PR.DS-01; PR.PS-01 | V30: A.8.24 | X30: None | Z30: Review compensating controls and risk acceptance for each protocol lacking remote signing. | AA30: Open source | AB30: Not started
A31: 30 | B31: UCR-030 | C31: 02 Key & Wallet Management | D31: Transparency | E31: Deliver pre-signed exit transactions to clients only through cryptographically secure, confidential channels. | F31: BSSC NOS v2 | G31: req-deliver-exit-transactions-securely | H31: BSSC NOS v2 — 5. Transparency | I31: MUST | J31: Critical | K31: Node/validator operator; Exchange/Custodian running nodes | L31: BSSC NOS; SEAL; CCSS v9.0; CIS v8.1; NIST CSF 2.0; ISO 27001:2022 | M31: NOS-051 · req-deliver-exit-transactions-securely | R31: Wallet Security | S31: 1.05 Key Usage | T31: CIS 3.10 | U31: PR.DS-02 | V31: A.5.14 | X31: None | Z31: Inspect delivery mechanism (encrypted, authenticated); sample delivery logs. | AA31: Open source | AB31: Not started
A32: 31 | B32: UCR-031 | C32: 02 Key & Wallet Management | D32: Change management | E32: Enforce a formal change management process for every key management component (HSMs, MPC nodes, policy engines, signing services). | F32: BSSC KMS v1 | G32: KMS-GEN-01 | H32: BSSC KMS v1 — §5 General Requirements | I32: MUST | J32: High | K32: All key holders (Custodian/Exchange, Node operator, Protocol/admin keys) | L32: BSSC KMS; OWASP Web3 Top 15; SEAL; CCSS v9.0; CIS v8.1; NIST CSF 2.0; ISO 27001:2022; DORA | M32: KMS-001 · KMS-GEN-01 | P32: WA12 | R32: DevSecOps | S32: 1.04 Key Material Access | T32: CIS 4.1 | U32: PR.PS-01; ID.RA-07 | V32: A.8.32 | W32: DORA Art. 9(4)(e) | X32: None | Z32: Sample changes: ticket, approval, test evidence. | AA32: Open source | AB32: Not started
A33: 32 | B33: UCR-032 | C33: 02 Key & Wallet Management | D33: Change management | E33: Keep an audit trail of every change naming proposer and approver(s). | F33: BSSC KMS v1 | G33: KMS-GEN-02 | H33: BSSC KMS v1 — §5 General Requirements | I33: MUST | J33: High | K33: All key holders (Custodian/Exchange, Node operator, Protocol/admin keys) | L33: BSSC KMS; OWASP Web3 Top 15; SEAL; CCSS v9.0; CIS v8.1; NIST CSF 2.0; ISO 27001:2022; DORA | M33: KMS-002 · KMS-GEN-02 | P33: WA12 | R33: DevSecOps | S33: 2.04 Audit Logs | T33: CIS 4.1 | U33: PR.PS-04 | V33: A.8.32; A.8.15 | W33: DORA Art. 9(4)(e) | X33: None | Z33: Inspect change records for proposer/approver identity. | AA33: Open source | AB33: Not started
A34: 33 | B34: UCR-033 | C34: 02 Key & Wallet Management | D34: Change management | E34: Require at least one proposer and one distinct approver for every change (four-eyes). | F34: BSSC KMS v1 | G34: KMS-GEN-03 | H34: BSSC KMS v1 — §5 General Requirements | I34: MUST | J34: Critical | K34: All key holders (Custodian/Exchange, Node operator, Protocol/admin keys) | L34: BSSC KMS; OWASP Web3 Top 15; SEAL; CCSS v9.0; CIS v8.1; NIST CSF 2.0; ISO 27001:2022; DORA | M34: KMS-003 · KMS-GEN-03 | P34: WA12 | R34: DevSecOps | S34: 1.04 Key Material Access | T34: CIS 4.1 | U34: PR.AA-05 | V34: A.5.3 | W34: DORA Art. 9(4)(e) | X34: None | Z34: Verify tooling blocks self-approval. | AA34: Open source | AB34: Not started
A35: 34 | B35: UCR-034 | C35: 02 Key & Wallet Management | D35: Separation of duties | E35: Technically enforce that no single individual can cause key misuse or destruction (quorum, MPC thresholds, policy engines). | F35: BSSC KMS v1 | G35: KMS-GEN-04 | H35: BSSC KMS v1 — §5 General Requirements | I35: SHOULD | J35: Critical | K35: All key holders (Custodian/Exchange, Node operator, Protocol/admin keys) | L35: BSSC KMS; OWASP Web3 Top 15; SEAL; CCSS v9.0; CIS v8.1; NIST CSF 2.0; ISO 27001:2022 | M35: KMS-004 · KMS-GEN-04 | P35: WA12 | R35: Multisig for Protocols | S35: 1.05 Key Usage; 1.04 Key Material Access | T35: CIS 6.8 | U35: PR.AA-05 | V35: A.5.3 | X35: None | Z35: Attempt single-actor critical action in test; review threshold configs. | AA35: Open source | AB35: Not started
A36: 35 | B36: UCR-035 | C36: 02 Key & Wallet Management | D36: Change management | E36: Test all changes in a non-production environment before activation. | F36: BSSC KMS v1 | G36: KMS-GEN-05 | H36: BSSC KMS v1 — §5 General Requirements | I36: MUST | J36: High | K36: All key holders (Custodian/Exchange, Node operator, Protocol/admin keys) | L36: BSSC KMS; OWASP Web3 Top 15; SEAL; CIS v8.1; NIST CSF 2.0; ISO 27001:2022; DORA | M36: KMS-005 · KMS-GEN-05 | P36: WA12 | R36: DevSecOps | T36: CIS 4.1 | U36: PR.PS-06 | V36: A.8.31; A.8.32 | W36: DORA Art. 9(4)(e) | X36: None | Z36: Trace changes to test evidence. | AA36: Open source | AB36: Not started
A37: 36 | B37: UCR-036 | C37: 02 Key & Wallet Management | D37: Procedures | E37: Document non-digital (ceremony, physical) processes as transparent, repeatable procedures. | F37: BSSC KMS v1 | G37: KMS-GEN-09 | H37: BSSC KMS v1 — §5 General Requirements | I37: MUST | J37: Medium | K37: All key holders (Custodian/Exchange, Node operator, Protocol/admin keys) | L37: BSSC KMS; SEAL; CCSS v9.0; NIST CSF 2.0; ISO 27001:2022 | M37: KMS-009 · KMS-GEN-09 | R37: Treasury Operations | S37: 1.01 Key Material Generation | U37: GV.PO-01 | V37: A.5.37 | X37: None | Z37: Review ceremony scripts. | AA37: Open source | AB37: Not started
A38: 37 | B38: UCR-037 | C38: 02 Key & Wallet Management | D38: Compromise handling | E38: Immediately remove suspected/known compromised keys from active use. | F38: BSSC KMS v1 | G38: KMS-GEN-24 | H38: BSSC KMS v1 — §5 General Requirements | I38: MUST | J38: Critical | K38: All key holders (Custodian/Exchange, Node operator, Protocol/admin keys) | L38: BSSC KMS; OWASP Web3 Top 15; SEAL; CCSS v9.0; CIS v8.1; NIST CSF 2.0; ISO 27001:2022 | M38: KMS-024 · KMS-GEN-24 | P38: WA03 | R38: Incident Management | S38: 1.06 Key Compromise Protocol | T38: CIS 17.4 | U38: RS.MI-01 | V38: A.5.26 | X38: None | Z38: Review compromise procedure; drill evidence. | AA38: Open source | AB38: Not started
A39: 38 | B39: UCR-038 | C39: 02 Key & Wallet Management | D39: Compromise handling | E39: Promptly retire suspected/known compromised keys (sweep funds, revoke roles). | F39: BSSC KMS v1 | G39: KMS-GEN-25 | H39: BSSC KMS v1 — §5 General Requirements | I39: MUST | J39: Critical | K39: All key holders (Custodian/Exchange, Node operator, Protocol/admin keys) | L39: BSSC KMS; OWASP Web3 Top 15; SEAL; CCSS v9.0; CIS v8.1; NIST CSF 2.0; ISO 27001:2022 | M39: KMS-025 · KMS-GEN-25 | P39: WA03 | R39: Incident Management | S39: 1.06 Key Compromise Protocol | T39: CIS 17.4 | U39: RS.MI-02 | V39: A.5.26 | X39: None | Z39: Review sweep/rotation runbook. | AA39: Open source | AB39: Not started
A40: 39 | B40: UCR-039 | C40: 02 Key & Wallet Management | D40: Compromise handling | E40: Promptly retire keys at increased risk of compromise. | F40: BSSC KMS v1 | G40: KMS-GEN-26 | H40: BSSC KMS v1 — §5 General Requirements | I40: SHOULD | J40: High | K40: All key holders (Custodian/Exchange, Node operator, Protocol/admin keys) | L40: BSSC KMS; OWASP Web3 Top 15; SEAL; CCSS v9.0; CIS v8.1; NIST CSF 2.0; ISO 27001:2022 | M40: KMS-026 · KMS-GEN-26 | P40: WA03 | R40: Incident Management | S40: 1.06 Key Compromise Protocol | T40: CIS 17.4 | U40: RS.MI-02 | V40: A.8.24 | X40: None | Z40: Review risk-triggered retirements. | AA40: Open source | AB40: Not started
...

Sheet Framework Sources
A1: Framework | B1: Version used | C1: Source | D1: How used in register | E1: Verification note
A2: BSSC Node Operation Standard (NOS) | B2: v2, 2026-05-14 | C2: https://specs.blockchainssc.org/nos/ | D2: Backbone (1 control per requirement) | E2: 53 req- anchors verified against live spec
A3: BSSC Token Integration Standard (TIS) | B3: v1, 2025-05-13 | C3: https://specs.blockchainssc.org/tis/ | D3: Backbone | E3: Headings verified; only 1 req- anchor in source
A4: BSSC Key Management Standard (KMS) | B4: v1, 2025-05-13 | C4: https://specs.blockchainssc.org/kms/ | D4: Backbone | E4: No IDs in source; KMS-xx IDs assigned in document order
A5: BSSC Smart Contract Security Standard (SCS) | B5: v1, 2026-05-14 | C5: https://specs.blockchainssc.org/scs/ | D5: Backbone | E5: 69 req- anchors verified
A6: BSSC General Security & Privacy Guidelines (GSP) | B6: v2, 2026-05-14 | C6: https://specs.blockchainssc.org/gsp/ | D6: Backbone | E6: 56 req- anchors verified
A7: OWASP Smart Contract Top 10 | B7: 2026 edition | C7: https://scs.owasp.org/sctop10 | D7: Mapping + supplementary controls | E7: SC01–SC10 names verified
A8: OWASP Smart Contract Security Verification Standard (SCSVS) | B8: Current (2024 refactor; no version label) | C8: https://scs.owasp.org/SCSVS/ | D8: Mapped at area level (SCSVS-ARCH … SCSVS-COMP) | E8: 11 areas / 35 controls verified. Note: area codes do not always match area titles (e.g., SCSVS-ORACLE = 'Arithmetic and Logic Security')
A9: OWASP Alternate Top 15: Web3 Attack Vectors | B9: 2026 | C9: https://scs.owasp.org/sctop10/Web3-Attack-Vectors-Top15/ | D9: Mapping + supplementary controls | E9: WA01–WA15 names verified
A10: EthTrust Security Levels | B10: Latest published spec (EEA; maintained by W3C EthTrust CG since Apr 2026) | C10: https://github.com/w3c-cg/EthTrust | D10: Mapped by level [S]/[M]/[Q] and named requirements cited by BSSC TIS | E10: Version number not stated on CG pages – confirm before certification use
A11: SEAL Frameworks (Security Alliance) | B11: Living document | C11: https://frameworks.securityalliance.org/ | D11: Mapping + supplementary controls | E11: 20 framework names verified
A12: CryptoCurrency Security Standard (CCSS) | B12: v9.0 (Dec 2024) | C12: https://cryptoconsortium.org/ | D12: Mapping (aspect level) + supplementary | E12: 10 aspects verified; prior BSSC workbook used legacy numbering – corrected here
... A18: FATF Recommendations 15 & 16 / EU TFR 2023/1113 | B18: Current | C18: https://www.fatf-gafi.org/ | D18: Supplementary | E18: Travel Rule
